Workbook

Sheet Dados gerais
A1: Autor | B1: Inputs | J1: Output | K1: Modelos normativos - wmax (mm) - utilizando a tensão na armadura medida no ensaio | X1: Sugestão | AA1: fib Model Code 2020 modificado | AD1: Modelos normativos - wmax (mm) | AQ1: Modelos empíricos - wmax (mm) | BI1: Sugestão | BL1: fib Model Code 2020 modificado | BO1: Observação | BS1: Auxiliar 1 | BU1: Auxiliar 2 | BW1: Auxiliar 3
B2: Diâmetro da armadura f (mm) | C2: Número de barras em uma camada | D2: Espaçamento entre as barras (mm) | E2: Resistência à tração do concreto fctm (MPa) | F2: Cobrimento c (mm) | G2: Distância ao centro de gravidade da armadura d' (mm) | H2: Taxa de armadura r | I2: Tensão na armadura (MPa) | J2: wexp (mm) | K2: fib Model Code 2010 | L2: wm/wexp | M2: LN(wm/wexp) | N2: fib Model Code 2020 | O2: wm/wexp | P2: LN(wm/wexp) | Q2: Eurocode 2 | R2: wm/wexp | S2: LN(wm/wexp) | T2: NBR 6118 - wk1 - fissuração estabilizada | U2: NBR 6118 - wk2 - fissuração não estabilizada | V2: wm/wexp | W2: LN(wm/wexp) | X2: b variável e < 0,6 | Y2: wm/wexp | Z2: LN(wm/wexp) | AA2: slip de Yuan et al. (2025) | AB2: wm/wexp | AC2: LN(wm/wexp) | AD2: fib Model Code 2010 | AE2: wk/wexp | AF2: LN(wk/wexp) | AG2: fib Model Code 2020 | AH2: wk/wexp | AI2: LN(wk/wexp) | AJ2: Eurocode 2 | AK2: wk/wexp | AL2: LN(wk/wexp) | AM2: NBR 6118 - wk1 - fissuração estabilizada | AN2: NBR 6118 - wk2 - fissuração não estabilizada | AO2: wk/wexp | AP2: LN(wk/wexp) | AQ2: Clark (1956) | AR2: wm/wexp | AS2: LN(wm/wexp) | AT2: Leonhardt (1977) | AU2: wm/wexp | AV2: LN(wm/wexp) | AW2: Desayi;Ganesan (1985) | AX2: wm/wexp | AY2: LN(wm/wexp) | AZ2: Oh; Kang (1987) | BA2: wm/wexp | BB2: LN(wm/wexp) | BC2: Caldas (1997) | BD2: wm/wexp | BE2: LN(wm/wexp) | BF2: Gergely e Lutz (1968) | BG2: wm/wexp | BH2: LN(wm/wexp) | BI2: b variável e < 0,6 | BJ2: wm/wexp | BK2: LN(wm/wexp) | BL2: slip de Yuan et al. (2025) | BM2: wm/wexp | BN2: LN(wm/wexp) | BS2: Barras com f £ 12,7 mm e c £ 45 mm | BU2: Barras com f > 12,7 mm e c £ 45 mm | BW2: Todas as barras com c £ 45 mm e pelo menos duas barras por camada
A3: Viga S200-0.32-10 - Sokolov et al (2021) | B3: ='[1]Dados de entrada'!$B$28 -> 10 | C3: ='[1]Dados de entrada'!$B$31 -> 2 | D3: ='[1]Dados de entrada'!$B$32 -> 192 | E3: ='[1]Dados de entrada'!$B$27 -> 4.0933129 | F3: ='[1]Dados de entrada'!$B$30 -> 25 | G3: ='[1]Dados de entrada'!$B$22 -> 30 | H3: ='[1]Dados de entrada'!$B$29/(2*'[1]Dados de entrada'!$B$20*G3) -> 0.0098600509 | I3: {='[1]Dados de entrada'!$E$7:$E$12} -> 329 | J3: {='[1]Dados de entrada'!$C$7:$C$12} -> 0.16 | K3: {='[1]fib Model Code 2010'!$F$5:$F$10} -> 0.10559303 | L3: =K3/J3 -> 0.65995642 | M3: =LN(L3) -> -0.41558148 | N3: {='[1]fib Model Code 2020'!$F$5:$F$10} -> 0.1351049 | O3: =N3/J3 -> 0.84440565 | P3: =LN(O3) -> -0.16912227 | Q3: {='[1]Eurocode 2'!$F$5:$F$10} -> 0.25661111 | R3: =Q3/J3 -> 1.6038194 | S3: =LN(R3) -> 0.47238794 | T3: {='[1]NBR 6118'!$F$5:$F$10} -> 0.35473432 | U3: {='[1]NBR 6118'!$G$5:$G$10} -> 0.14103132 | V3: {='[1]NBR 6118'!$L$5:$L$10} -> 0.88144577 | W3: =LN(V3) -> -0.1261918 | X3: {=[1]Sugestão!$G$5:$G$10} -> 0.23391556 | Y3: =X3/J3 -> 1.4619723 | Z3: =LN(Y3) -> 0.3797864 | AA3: {='[1]fib Model Code 2020 modificado'!$F$5:$F$10} -> 0.17169108 | AB3: =AA3/J3 -> 1.0730693 | AC3: =LN(AB3) -> 0.07052301 | BS3: =IF(AND(B3<=12.7,F3<=45),TRUE,FALSE) -> TRUE | BU3: =IF(AND(B3>12.7,F3<=45),TRUE,FALSE) -> FALSE | BW3: =IF(AND(F3<=45,C3>1),TRUE,FALSE) -> TRUE
B4: ='[1]Dados de entrada'!$B$28 -> 10 | C4: ='[1]Dados de entrada'!$B$31 -> 2 | D4: ='[1]Dados de entrada'!$B$32 -> 192 | E4: ='[1]Dados de entrada'!$B$27 -> 4.0933129 | F4: ='[1]Dados de entrada'!$B$30 -> 25 | G4: ='[1]Dados de entrada'!$B$22 -> 30 | H4: ='[1]Dados de entrada'!$B$29/(2*'[1]Dados de entrada'!$B$20*G4) -> 0.0098600509 | I4: 355 | J4: 0.18 | K4: 0.14926432 | L4: =K4/J4 -> 0.8292462 | M4: =LN(L4) -> -0.18723818 | N4: 0.14578189 | O4: =N4/J4 -> 0.80989937 | P4: =LN(O4) -> -0.21084527 | Q4: 0.27689041 | R4: =Q4/J4 -> 1.53828 | S4: =LN(R4) -> 0.43066494 | T4: 0.38276803 | U4: 0.16420277 | V4: 0.91223763 | W4: =LN(V4) -> -0.091854763 | X4: 0.2723479 | Y4: =X4/J4 -> 1.5130439 | Z4: =LN(Y4) -> 0.41412344 | AA4: 0.18630984 | AB4: =AA4/J4 -> 1.0350546 | AC4: =LN(AB4) -> 0.03445422 | BS4: =IF(AND(B4<=12.7,F4<=45),TRUE,FALSE) -> TRUE | BU4: =IF(AND(B4>12.7,F4<=45),TRUE,FALSE) -> FALSE | BW4: =IF(AND(F4<=45,C4>1),TRUE,FALSE) -> TRUE
B5: ='[1]Dados de entrada'!$B$28 -> 10 | C5: ='[1]Dados de entrada'!$B$31 -> 2 | D5: ='[1]Dados de entrada'!$B$32 -> 192 | E5: ='[1]Dados de entrada'!$B$27 -> 4.0933129 | F5: ='[1]Dados de entrada'!$B$30 -> 25 | G5: ='[1]Dados de entrada'!$B$22 -> 30 | H5: ='[1]Dados de entrada'!$B$29/(2*'[1]Dados de entrada'!$B$20*G5) -> 0.0098600509 | I5: 387 | J5: 0.19 | K5: 0.2030136 | L5: =K5/J5 -> 1.0684926 | M5: =LN(L5) -> 0.066248877 | N5: 0.17816487 | O5: =N5/J5 -> 0.93770983 | P5: =LN(O5) -> -0.064314726 | Q5: 0.30184954 | R5: =Q5/J5 -> 1.5886818 | S5: =LN(R5) -> 0.46290462 | T5: 0.41727106 | U5: 0.19513974 | V5: 1.0270512 | W5: =LN(V5) -> 0.026691823 | X5: 0.32960485 | Y5: =X5/J5 -> 1.7347623 | Z5: =LN(Y5) -> 0.55087043 | AA5: 0.22375546 | AB5: =AA5/J5 -> 1.1776603 | AC5: =LN(AB5) -> 0.16352968 | BS5: =IF(AND(B5<=12.7,F5<=45),TRUE,FALSE) -> TRUE | BU5: =IF(AND(B5>12.7,F5<=45),TRUE,FALSE) -> FALSE | BW5: =IF(AND(F5<=45,C5>1),TRUE,FALSE) -> TRUE
B6: ='[1]Dados de entrada'!$B$28 -> 10 | C6: ='[1]Dados de entrada'!$B$31 -> 2 | D6: ='[1]Dados de entrada'!$B$32 -> 192 | E6: ='[1]Dados de entrada'!$B$27 -> 4.0933129 | F6: ='[1]Dados de entrada'!$B$30 -> 25 | G6: ='[1]Dados de entrada'!$B$22 -> 30 | H6: ='[1]Dados de entrada'!$B$29/(2*'[1]Dados de entrada'!$B$20*G6) -> 0.0098600509 | I6: 423 | J6: 0.24 | K6: 0.26348153 | L6: =K6/J6 -> 1.0978397 | M6: =LN(L6) -> 0.093344365 | N6: 0.21512366 | O6: =N6/J6 -> 0.89634857 | P6: =LN(O6) -> -0.10942592 | Q6: 0.32992857 | R6: =Q6/J6 -> 1.3747024 | S6: =LN(R6) -> 0.31823726 | T6: 0.45608698 | U6: 0.23313341 | V6: 0.97138921 | W6: =LN(V6) -> -0.029028056 | X6: 0.39424128 | Y6: =X6/J6 -> 1.642672 | Z6: =LN(Y6) -> 0.49632419 | AA6: 0.26668832 | AB6: =AA6/J6 -> 1.1112013 | AC6: =LN(AB6) -> 0.10544172 | BS6: =IF(AND(B6<=12.7,F6<=45),TRUE,FALSE) -> TRUE | BU6: =IF(AND(B6>12.7,F6<=45),TRUE,FALSE) -> FALSE | BW6: =IF(AND(F6<=45,C6>1),TRUE,FALSE) -> TRUE
B7: ='[1]Dados de entrada'!$B$28 -> 10 | C7: ='[1]Dados de entrada'!$B$31 -> 2 | D7: ='[1]Dados de entrada'!$B$32 -> 192 | E7: ='[1]Dados de entrada'!$B$27 -> 4.0933129 | F7: ='[1]Dados de entrada'!$B$30 -> 25 | G7: ='[1]Dados de entrada'!$B$22 -> 30 | H7: ='[1]Dados de entrada'!$B$29/(2*'[1]Dados de entrada'!$B$20*G7) -> 0.0098600509 | I7: 463 | J7: 0.27 | K7: 0.33066813 | L7: =K7/J7 -> 1.2246968 | M7: =LN(L7) -> 0.2026933 | N7: 0.25618898 | O7: =N7/J7 -> 0.94884806 | P7: =LN(O7) -> -0.052506598 | Q7: 0.36112749 | R7: =Q7/J7 -> 1.3375092 | S7: =LN(R7) -> 0.2908091 | T7: 0.49921577 | U7: 0.27930954 | V7: 1.0344798 | W7: =LN(V7) -> 0.033898658 | X7: 0.46605954 | Y7: =X7/J7 -> 1.7261465 | Z7: =LN(Y7) -> 0.54589144 | AA7: 0.31473749 | AB7: =AA7/J7 -> 1.1656944 | AC7: =LN(AB7) -> 0.15331696 | BS7: =IF(AND(B7<=12.7,F7<=45),TRUE,FALSE) -> TRUE | BU7: =IF(AND(B7>12.7,F7<=45),TRUE,FALSE) -> FALSE | BW7: =IF(AND(F7<=45,C7>1),TRUE,FALSE) -> TRUE
B8: ='[1]Dados de entrada'!$B$28 -> 10 | C8: ='[1]Dados de entrada'!$B$31 -> 2 | D8: ='[1]Dados de entrada'!$B$32 -> 192 | E8: ='[1]Dados de entrada'!$B$27 -> 4.0933129 | F8: ='[1]Dados de entrada'!$B$30 -> 25 | G8: ='[1]Dados de entrada'!$B$22 -> 30 | H8: ='[1]Dados de entrada'!$B$29/(2*'[1]Dados de entrada'!$B$20*G8) -> 0.0098600509 | I8: 499 | J8: 0.31 | K8: 0.39113607 | L8: =K8/J8 -> 1.2617293 | M8: =LN(L8) -> 0.23248322 | N8: 0.29314776 | O8: =N8/J8 -> 0.94563795 | P8: =LN(O8) -> -0.0558955 | Q8: 0.38920652 | R8: =Q8/J8 -> 1.2555049 | S8: =LN(R8) -> 0.2275378 | T8: 0.53803168 | U8: 0.32443289 | V8: 1.0465577 | W8: =LN(V8) -> 0.045506403 | X8: 0.51228987 | Y8: =X8/J8 -> 1.652548 | Z8: =LN(Y8) -> 0.50231832 | AA8: 0.35829312 | AB8: =AA8/J8 -> 1.1557842 | AC8: =LN(AB8) -> 0.14477912 | BS8: =IF(AND(B8<=12.7,F8<=45),TRUE,FALSE) -> TRUE | BU8: =IF(AND(B8>12.7,F8<=45),TRUE,FALSE) -> FALSE | BW8: =IF(AND(F8<=45,C8>1),TRUE,FALSE) -> TRUE
A9: Viga S200-1.76-20 - Sokolov et al (2021) | B9: ='[2]Dados de entrada'!$B$28 -> 20 | C9: ='[2]Dados de entrada'!$B$31 -> 2 | D9: ='[2]Dados de entrada'!$B$32 -> 126 | E9: ='[2]Dados de entrada'!$B$27 -> 4.1203405 | F9: ='[2]Dados de entrada'!$B$30 -> 25 | G9: ='[2]Dados de entrada'!$B$22 -> 39 | H9: ='[2]Dados de entrada'!$B$29/(2*'[2]Dados de entrada'!$B$20*G9) -> 0.037274454 | I9: {='[2]fib Model Code 2010'!$K$5:$K$10} -> 231.811 | J9: {='[2]Dados de entrada'!$C$7:$C$12} -> 0.16 | K9: {='[2]fib Model Code 2010'!$F$5:$F$10} -> 0.12445288 | L9: =K9/J9 -> 0.7778305 | M9: =LN(L9) -> -0.25124665 | N9: {='[2]fib Model Code 2020'!$F$5:$F$10} -> 0.084635219 | O9: =N9/J9 -> 0.52897012 | P9: =LN(O9) -> -0.63682333 | Q9: {='[2]Eurocode 2'!$F$5:$F$10} -> 0.12401497 | R9: =Q9/J9 -> 0.77509357 | S9: =LN(R9) -> -0.25477152 | T9: {='[2]NBR 6118'!$F$5:$F$10} -> 0.24483716 | U9: {='[2]NBR 6118'!$G$5:$G$10} -> 0.13694661 | V9: {='[2]NBR 6118'!$L$5:$L$10} -> 0.85591631 | W9: =LN(V9) -> -0.15558267 | X9: {=[2]Sugestão!$G$5:$G$10} -> 0.099913427 | Y9: =X9/J9 -> 0.62445892 | Z9: =LN(Y9) -> -0.47086974 | AA9: {='[2]fib Model Code 2020 modificado'!$F$5:$F$10} -> 0.15145884 | AB9: =AA9/J9 -> 0.94661775 | AC9: =LN(AB9) -> -0.054859908 | AD9: {='[2]fib Model Code 2010'!$L$5:$L$10} -> 0.12573407 | AE9: =AD9/$J9 -> 0.78583793 | AF9: =LN(AE9) -> -0.2410047 | AG9: {='[2]fib Model Code 2020'!$L$5:$L$10} -> 0.086159383 | AH9: =AG9/$J9 -> 0.53849614 | AI9: =LN(AH9) -> -0.61897495 | AJ9: {='[2]Eurocode 2'!$L$5:$L$10} -> 0.12529165 | AK9: =AJ9/$J9 -> 0.78307283 | AL9: =LN(AK9) -> -0.24452958 | AM9: {='[2]NBR 6118'!$Q$5:$Q$10} -> 0.26246779 | AN9: {='[2]NBR 6118'!$R$5:$R$10} -> 0.15737968 | AO9: {='[2]NBR 6118'!$W$5:$W$10} -> 0.98362299 | AP9: =LN(AO9) -> -0.016512596 | AQ9: {='[2]Clark (1956)'!$L$5:$L$10} -> 0.18100616 | AR9: =AQ9/$J9 -> 1.1312885 | AS9: =LN(AR9) -> 0.12335727 | AT9: {='[2]Leonhardt (1977)'!$L$5:$L$10} -> 0.29637407 | AU9: =AT9/$J9 -> 1.852338 | AV9: =LN(AU9) -> 0.6164486 | AW9: {='[2]Desayi; Ganesan (1985)'!$L$5:$L$10} -> 0.31268421 | AX9: =AW9/$J9 -> 1.9542763 | AY9: =LN(AX9) -> 0.67001995 | AZ9: {='[2]Oh; Kang (1987)'!$L$5:$L$10} -> 0.18596904 | BA9: =AZ9/$J9 -> 1.1623065 | BB9: =LN(BA9) -> 0.1504064 | BC9: {='[2]Caldas (1997)'!$L$5:$L$10} -> 0.12999764 | BD9: =BC9/$J9 -> 0.81248526 | BE9: =LN(BD9) -> -0.20765751 | BF9: {='[2]Gergely e Lutz (1968)'!$L$5:$L$10} -> 0.24152795 | BG9: =BF9/$J9 -> 1.5095497 | BH9: =LN(BG9) -> 0.41181138 | BI9: {=[2]Sugestão!$N$5:$N$10} -> 0.10212972 | BJ9: =BI9/$J9 -> 0.63831077 | BK9: =LN(BJ9) -> -0.44893001 | BL9: {='[2]fib Model Code 2020 modificado'!$L$5:$L$10} -> 0.15370894 | BM9: =BL9/$J9 -> 0.96068086 | BN9: =LN(BM9) -> -0.040113018 | BS9: =IF(AND(B9<=12.7,F9<=45),TRUE,FALSE) -> FALSE | BU9: =IF(AND(B9>12.7,F9<=45),TRUE,FALSE) -> TRUE | BW9: =IF(AND(F9<=45,C9>1),TRUE,FALSE) -> TRUE
B10: ='[2]Dados de entrada'!$B$28 -> 20 | C10: ='[2]Dados de entrada'!$B$31 -> 2 | D10: ='[2]Dados de entrada'!$B$32 -> 126 | E10: ='[2]Dados de entrada'!$B$27 -> 4.1203405 | F10: ='[2]Dados de entrada'!$B$30 -> 25 | G10: ='[2]Dados de entrada'!$B$22 -> 39 | H10: ='[2]Dados de entrada'!$B$29/(2*'[2]Dados de entrada'!$B$20*G10) -> 0.037274454 | I10: 304.25194 | J10: 0.23 | K10: 0.17255925 | L10: =K10/J10 -> 0.75025759 | M10: =LN(L10) -> -0.28733867 | N10: 0.14186483 | O10: =N10/J10 -> 0.61680361 | P10: =LN(O10) -> -0.4832046 | Q10: 0.17195207 | R10: =Q10/J10 -> 0.74761769 | S10: =LN(R10) -> -0.29086355 | T10: 0.31722379 | U10: 0.22989427 | V10: 0.99954029 | W10: =LN(V10) -> -0.00045981214 | X10: 0.18313142 | Y10: =X10/J10 -> 0.79622358 | Z10: =LN(Y10) -> -0.22787525 | AA10: 0.23808772 | AB10: =AA10/J10 -> 1.035164 | AC10: =LN(AB10) -> 0.034559872 | AD10: 0.17698216 | AE10: =AD10/$J10 -> 0.76948766 | AF10: =LN(AE10) -> -0.26203036 | AG10: 0.14712654 | AH10: =AG10/$J10 -> 0.63968062 | AI10: =LN(AH10) -> -0.44678626 | AJ10: 0.17635942 | AK10: =AJ10/$J10 -> 0.76678009 | AL10: =LN(AK10) -> -0.26555523 | AM10: 0.34448897 | AN10: 0.27111109 | AO10: 1.1787439 | AP10: =LN(AO10) -> 0.16444934 | AQ10: 0.24436255 | AR10: =AQ10/$J10 -> 1.0624459 | AS10: =LN(AR10) -> 0.060573665 | AT10: 0.44704918 | AU10: =AT10/$J10 -> 1.9436921 | AV10: =LN(AU10) -> 0.66458931 | AW10: 0.41039802 | AX10: =AW10/$J10 -> 1.7843392 | AY10: =LN(AX10) -> 0.57904817 | AZ10: 0.25620365 | BA10: =AZ10/$J10 -> 1.1139289 | BB10: =LN(BA10) -> 0.10789335 | BC10: 0.17474556 | BD10: =BC10/$J10 -> 0.75976329 | BE10: =LN(BD10) -> -0.27474836 | BF10: 0.31700543 | BG10: =BF10/$J10 -> 1.3782845 | BH10: =LN(BG10) -> 0.3208396 | BI10: 0.19078252 | BJ10: =BI10/$J10 -> 0.8294892 | BK10: =LN(BJ10) -> -0.18694519 | BL10: 0.24627331 | BM10: =BL10/$J10 -> 1.0707535 | BN10: =LN(BM10) -> 0.068362633 | BS10: =IF(AND(B10<=12.7,F10<=45),TRUE,FALSE) -> FALSE | BU10: =IF(AND(B10>12.7,F10<=45),TRUE,FALSE) -> TRUE | BW10: =IF(AND(F10<=45,C10>1),TRUE,FALSE) -> TRUE
B11: ='[2]Dados de entrada'!$B$28 -> 20 | C11: ='[2]Dados de entrada'!$B$31 -> 2 | D11: ='[2]Dados de entrada'!$B$32 -> 126 | E11: ='[2]Dados de entrada'!$B$27 -> 4.1203405 | F11: ='[2]Dados de entrada'!$B$30 -> 25 | G11: ='[2]Dados de entrada'!$B$22 -> 39 | H11: ='[2]Dados de entrada'!$B$29/(2*'[2]Dados de entrada'!$B$20*G11) -> 0.037274454 | I11: 314.28223 | J11: 0.24 | K11: 0.18529328 | L11: =K11/J11 -> 0.77205535 | M11: =LN(L11) -> -0.25869903 | N11: 0.15701385 | O11: =N11/J11 -> 0.65422436 | P11: =LN(O11) -> -0.42430493 | Q11: 0.1846413 | R11: =Q11/J11 -> 0.76933875 | S11: =LN(R11) -> -0.2622239 | T11: 0.33638496 | U11: 0.25850549 | V11: 1.0771062 | W11: =LN(V11) -> 0.074278028 | X11: 0.20515972 | Y11: =X11/J11 -> 0.85483216 | Z11: =LN(Y11) -> -0.15685014 | AA11: 0.26175552 | AB11: =AA11/J11 -> 1.090648 | AC11: =LN(AB11) -> 0.086772009 | AD11: 0.18407805 | AE11: =AD11/$J11 -> 0.76699189 | AF11: =LN(AE11) -> -0.26527906 | AG11: 0.15556815 | AH11: =AG11/$J11 -> 0.64820062 | AI11: =LN(AH11) -> -0.43355503 | AJ11: 0.18343034 | AK11: =AJ11/$J11 -> 0.7642931 | AL11: =LN(AK11) -> -0.26880393 | AM11: 0.35584575 | AN11: 0.28928119 | AO11: 1.2053383 | AP11: =LN(AO11) -> 0.18676028 | AQ11: 0.25313497 | AR11: =AQ11/$J11 -> 1.054729 | AS11: =LN(AR11) -> 0.053283902 | AT11: 0.46699968 | AU11: =AT11/$J11 -> 1.945832 | AV11: =LN(AU11) -> 0.66568965 | AW11: 0.42392763 | AX11: =AW11/$J11 -> 1.7663651 | AY11: =LN(AX11) -> 0.56892383 | AZ11: 0.26592845 | BA11: =AZ11/$J11 -> 1.1080352 | BB11: =LN(BA11) -> 0.10258835 | BC11: 0.18094142 | BD11: =BC11/$J11 -> 0.75392259 | BE11: =LN(BD11) -> -0.28246559 | BF11: 0.32745616 | BG11: =BF11/$J11 -> 1.3644007 | BH11: =LN(BG11) -> 0.31071526 | BI11: 0.20305752 | BJ11: =BI11/$J11 -> 0.84607299 | BK11: =LN(BJ11) -> -0.16714964 | BL11: 0.25948355 | BM11: =BL11/$J11 -> 1.0811815 | BN11: =LN(BM11) -> 0.078054382 | BS11: =IF(AND(B11<=12.7,F11<=45),TRUE,FALSE) -> FALSE | BU11: =IF(AND(B11>12.7,F11<=45),TRUE,FALSE) -> TRUE | BW11: =IF(AND(F11<=45,C11>1),TRUE,FALSE) -> TRUE
B12: ='[2]Dados de entrada'!$B$28 -> 20 | C12: ='[2]Dados de entrada'!$B$31 -> 2 | D12: ='[2]Dados de entrada'!$B$32 -> 126 | E12: ='[2]Dados de entrada'!$B$27 -> 4.1203405 | F12: ='[2]Dados de entrada'!$B$30 -> 25 | G12: ='[2]Dados de entrada'!$B$22 -> 39 | H12: ='[2]Dados de entrada'!$B$29/(2*'[2]Dados de entrada'!$B$20*G12) -> 0.037274454 | I12: 363.31917 | J12: 0.27 | K12: 0.23835178 | L12: =K12/J12 -> 0.88278436 | M12: =LN(L12) -> -0.12467432 | N12: 0.22013474 | O12: =N12/J12 -> 0.81531386 | P12: =LN(O12) -> -0.20418214 | Q12: 0.2375131 | R12: =Q12/J12 -> 0.87967814 | S12: =LN(R12) -> -0.12819919 | T12: 0.41622316 | U12: 0.3957757 | V12: 1.4658359 | W12: =LN(V12) -> 0.38242568 | X12: 0.29694427 | Y12: =X12/J12 -> 1.0997936 | Z12: =LN(Y12) -> 0.095122533 | AA12: 0.36369043 | AB12: =AA12/J12 -> 1.3470016 | AC12: =LN(AB12) -> 0.29788107 | AD12: 0.21876907 | AE12: =AD12/$J12 -> 0.81025582 | AF12: =LN(AE12) -> -0.21040526 | AG12: 0.19683823 | AH12: =AG12/$J12 -> 0.72903047 | AI12: =LN(AH12) -> -0.31603976 | AJ12: 0.21799929 | AK12: =AJ12/$J12 -> 0.80740479 | AL12: =LN(AK12) -> -0.21393013 | AM12: 0.41136778 | AN12: 0.38659585 | AO12: 1.4318365 | AP12: =LN(AO12) -> 0.35895786 | AQ12: 0.29602237 | AR12: =AQ12/$J12 -> 1.0963791 | AS12: =LN(AR12) -> 0.092013062 | AT12: 0.56249751 | AU12: =AT12/$J12 -> 2.0833241 | AV12: =LN(AU12) -> 0.73396475 | AW12: 0.49007237 | AX12: =AW12/$J12 -> 1.8150828 | AY12: =LN(AX12) -> 0.59613111 | AZ12: 0.31347188 | BA12: =AZ12/$J12 -> 1.161007 | BB12: =LN(BA12) -> 0.1492877 | BC12: 0.21123232 | BD12: =BC12/$J12 -> 0.78234191 | BE12: =LN(BD12) -> -0.2454634 | BF12: 0.37854861 | BG12: =BF12/$J12 -> 1.4020319 | BH12: =LN(BG12) -> 0.33792253 | BI12: 0.26306864 | BJ12: =BI12/$J12 -> 0.9743283 | BK12: =LN(BJ12) -> -0.026006973 | BL12: 0.32544523 | BM12: =BL12/$J12 -> 1.2053527 | BN12: =LN(BM12) -> 0.18677223 | BS12: =IF(AND(B12<=12.7,F12<=45),TRUE,FALSE) -> FALSE | BU12: =IF(AND(B12>12.7,F12<=45),TRUE,FALSE) -> TRUE | BW12: =IF(AND(F12<=45,C12>1),TRUE,FALSE) -> TRUE
B13: ='[2]Dados de entrada'!$B$28 -> 20 | C13: ='[2]Dados de entrada'!$B$31 -> 2 | D13: ='[2]Dados de entrada'!$B$32 -> 126 | E13: ='[2]Dados de entrada'!$B$27 -> 4.1203405 | F13: ='[2]Dados de entrada'!$B$30 -> 25 | G13: ='[2]Dados de entrada'!$B$22 -> 39 | H13: ='[2]Dados de entrada'!$B$29/(2*'[2]Dados de entrada'!$B$20*G13) -> 0.037274454 | I13: 459.16411 | J13: 0.35 | K13: 0.28009113 | L13: =K13/J13 -> 0.80026036 | M13: =LN(L13) -> -0.22281816 | N13: 0.26978985 | O13: =N13/J13 -> 0.77082813 | P13: =LN(O13) -> -0.26028985 | Q13: 0.27910558 | R13: =Q13/J13 -> 0.79744451 | S13: =LN(R13) -> -0.22634303 | T13: 0.47902922 | U13: 0.52422852 | V13: 1.3686549 | W13: =LN(V13) -> 0.31382844 | X13: 0.36914813 | Y13: =X13/J13 -> 1.0547089 | Z13: =LN(Y13) -> 0.053264832 | AA13: 0.44764133 | AB13: =AA13/J13 -> 1.2789752 | AC13: =LN(AB13) -> 0.24605915 | AD13: 0.28657424 | AE13: =AD13/$J13 -> 0.81878355 | AF13: =LN(AE13) -> -0.19993552 | AG13: 0.27750247 | AH13: =AG13/$J13 -> 0.79286419 | AI13: =LN(AH13) -> -0.23210333 | AJ13: 0.28556588 | AK13: =AJ13/$J13 -> 0.81590252 | AL13: =LN(AK13) -> -0.2034604 | AM13: 0.51988812 | AN13: 0.61747079 | AO13: 1.4853946 | AP13: =LN(AO13) -> 0.39568047 | AQ13: 0.37984774 | AR13: =AQ13/$J13 -> 1.0852793 | AS13: =LN(AR13) -> 0.081837328 | AT13: 0.74267836 | AU13: =AT13/$J13 -> 2.1219382 | AV13: =LN(AU13) -> 0.7523299 | AW13: 0.61935526 | AX13: =AW13/$J13 -> 1.7695865 | AY13: =LN(AX13) -> 0.57074588 | AZ13: 0.40639768 | BA13: =AZ13/$J13 -> 1.1611362 | BB13: =LN(BA13) -> 0.14939902 | BC13: 0.27043725 | BD13: =BC13/$J13 -> 0.77267786 | BE13: =LN(BD13) -> -0.25789306 | BF13: 0.47841113 | BG13: =BF13/$J13 -> 1.3668889 | BH13: =LN(BG13) -> 0.31253731 | BI13: 0.3803631 | BJ13: =BI13/$J13 -> 1.0867517 | BK13: =LN(BJ13) -> 0.083193178 | BL13: 0.46097815 | BM13: =BL13/$J13 -> 1.3170804 | BN13: =LN(BM13) -> 0.2754175 | BS13: =IF(AND(B13<=12.7,F13<=45),TRUE,FALSE) -> FALSE | BU13: =IF(AND(B13>12.7,F13<=45),TRUE,FALSE) -> TRUE | BW13: =IF(AND(F13<=45,C13>1),TRUE,FALSE) -> TRUE
B14: ='[2]Dados de entrada'!$B$28 -> 20 | C14: ='[2]Dados de entrada'!$B$31 -> 2 | D14: ='[2]Dados de entrada'!$B$32 -> 126 | E14: ='[2]Dados de entrada'!$B$27 -> 4.1203405 | F14: ='[2]Dados de entrada'!$B$30 -> 25 | G14: ='[2]Dados de entrada'!$B$22 -> 39 | H14: ='[2]Dados de entrada'!$B$29/(2*'[2]Dados de entrada'!$B$20*G14) -> 0.037274454 | I14: 500 | J14: 0.4 | K14: 0.3069741 | L14: =K14/J14 -> 0.76743524 | M14: =LN(L14) -> -0.26470118 | N14: 0.3017711 | O14: =N14/J14 -> 0.75442775 | P14: =LN(O14) -> -0.28179576 | Q14: 0.30589396 | R14: =Q14/J14 -> 0.76473489 | S14: =LN(R14) -> -0.26822606 | T14: 0.51948057 | U14: 0.61650309 | V14: 1.2987014 | W14: =LN(V14) -> 0.26136487 | X14: 0.41070663 | Y14: =X14/J14 -> 1.0267666 | Z14: =LN(Y14) -> 0.02641461 | AA14: 0.5034654 | AB14: =AA14/J14 -> 1.2586635 | AC14: =LN(AB14) -> 0.23005045 | AD14: 0.31546345 | AE14: =AD14/$J14 -> 0.78865864 | AF14: =LN(AE14) -> -0.23742171 | AG14: 0.31187044 | AH14: =AG14/$J14 -> 0.77967611 | AI14: =LN(AH14) -> -0.24887669 | AJ14: 0.31435344 | AK14: =AJ14/$J14 -> 0.78588361 | AL14: =LN(AK14) -> -0.24094658 | AM14: 0.53225469 | AN14: 0.6471957 | AO14: 1.3306367 | AP14: =LN(AO14) -> 0.28565756 | AQ14: 0.41556255 | AR14: =AQ14/$J14 -> 1.0389064 | AS14: =LN(AR14) -> 0.038168599 | AT14: 0.81781094 | AU14: =AT14/$J14 -> 2.0445274 | AV14: =LN(AU14) -> 0.71516664 | AW14: 0.6744378 | AX14: =AW14/$J14 -> 1.6860945 | AY14: =LN(AX14) -> 0.52241491 | AZ14: 0.44598984 | BA14: =AZ14/$J14 -> 1.1149746 | BB14: =LN(BA14) -> 0.10883162 | BC14: 0.29566223 | BD14: =BC14/$J14 -> 0.73915557 | BE14: =LN(BD14) -> -0.30224687 | BF14: 0.52095876 | BG14: =BF14/$J14 -> 1.3023969 | BH14: =LN(BG14) -> 0.26420634 | BI14: 0.42080597 | BJ14: =BI14/$J14 -> 1.0520149 | BK14: =LN(BJ14) -> 0.050707303 | BL14: 0.52137957 | BM14: =BL14/$J14 -> 1.3034489 | BN14: =LN(BM14) -> 0.26501377 | BS14: =IF(AND(B14<=12.7,F14<=45),TRUE,FALSE) -> FALSE | BU14: =IF(AND(B14>12.7,F14<=45),TRUE,FALSE) -> TRUE | BW14: =IF(AND(F14<=45,C14>1),TRUE,FALSE) -> TRUE
A15: Viga S200-1.98-10 - Sokolov et al (2021) | B15: ='[3]Dados de entrada'!$B$28 -> 10 | C15: ='[3]Dados de entrada'!$B$31 -> 8 | D15: ='[3]Dados de entrada'!$B$32 -> 40.7 | E15: ='[3]Dados de entrada'!$B$27 -> 4.1203405 | F15: ='[3]Dados de entrada'!$B$30 -> 25 | G15: ='[3]Dados de entrada'!$B$22 -> 49 | H15: ='[3]Dados de entrada'!$B$29/(2*'[3]Dados de entrada'!$B$20*G15) -> 0.030227185 | I15: {='[3]Dados de entrada'!$E$7:$E$9} -> 344 | J15: {='[3]Dados de entrada'!$C$7:$C$9} -> 0.16 | K15: {='[3]fib Model Code 2010'!$F$5:$F$7} -> 0.137745 | L15: =K15/J15 -> 0.86090625 | M15: =LN(L15) -> -0.14976967 | N15: {='[3]fib Model Code 2020'!$F$5:$F$7} -> 0.14773432 | O15: =N15/J15 -> 0.92333949 | P15: =LN(O15) -> -0.079758303 | Q15: {='[3]Eurocode 2'!$F$5:$F$7} -> 0.16340398 | R15: =Q15/J15 -> 1.0212749 | S15: =LN(R15) -> 0.021051728 | T15: {='[3]NBR 6118'!$F$5:$F$7} -> 0.18353711 | U15: {='[3]NBR 6118'!$G$5:$G$7} -> 0.1531731 | V15: {='[3]NBR 6118'!$L$5:$L$7} -> 0.95733188 | W15: =LN(V15) -> -0.043605157 | X15: {=[3]Sugestão!$G$5:$G$7} -> 0.19633966 | Y15: =X15/J15 -> 1.2271229 | Z15: =LN(Y15) -> 0.20467233 | AA15: {='[3]fib Model Code 2020 modificado'!$F$5:$F$7} -> 0.18643003 | AB15: =AA15/J15 -> 1.1651877 | AC15: =LN(AB15) -> 0.15288216 | BS15: =IF(AND(B15<=12.7,F15<=45),TRUE,FALSE) -> TRUE | BU15: =IF(AND(B15>12.7,F15<=45),TRUE,FALSE) -> FALSE | BW15: =IF(AND(F15<=45,C15>1),TRUE,FALSE) -> TRUE
B16: ='[3]Dados de entrada'!$B$28 -> 10 | C16: ='[3]Dados de entrada'!$B$31 -> 8 | D16: ='[3]Dados de entrada'!$B$32 -> 40.7 | E16: ='[3]Dados de entrada'!$B$27 -> 4.1203405 | F16: ='[3]Dados de entrada'!$B$30 -> 25 | G16: ='[3]Dados de entrada'!$B$22 -> 49 | H16: ='[3]Dados de entrada'!$B$29/(2*'[3]Dados de entrada'!$B$20*G16) -> 0.030227185 | I16: 424 | J16: 0.22 | K16: 0.175636 | L16: =K16/J16 -> 0.79834545 | M16: =LN(L16) -> -0.22521388 | N16: 0.20301592 | O16: =N16/J16 -> 0.92279964 | P16: =LN(O16) -> -0.08034314 | Q16: 0.20835327 | R16: =Q16/J16 -> 0.94706033 | S16: =LN(R16) -> -0.054392482 | T16: 0.22622016 | U16: 0.23270051 | V16: 1.0282735 | W16: =LN(V16) -> 0.027881135 | X16: 0.27687469 | Y16: =X16/J16 -> 1.2585213 | Z16: =LN(Y16) -> 0.22993749 | AA16: 0.25454004 | AB16: =AA16/J16 -> 1.1570002 | AC16: =LN(AB16) -> 0.14583062 | BS16: =IF(AND(B16<=12.7,F16<=45),TRUE,FALSE) -> TRUE | BU16: =IF(AND(B16>12.7,F16<=45),TRUE,FALSE) -> FALSE | BW16: =IF(AND(F16<=45,C16>1),TRUE,FALSE) -> TRUE
B17: ='[3]Dados de entrada'!$B$28 -> 10 | C17: ='[3]Dados de entrada'!$B$31 -> 8 | D17: ='[3]Dados de entrada'!$B$32 -> 40.7 | E17: ='[3]Dados de entrada'!$B$27 -> 4.1203405 | F17: ='[3]Dados de entrada'!$B$30 -> 25 | G17: ='[3]Dados de entrada'!$B$22 -> 49 | H17: ='[3]Dados de entrada'!$B$29/(2*'[3]Dados de entrada'!$B$20*G17) -> 0.030227185 | I17: 475 | J17: 0.29 | K17: 0.19979151 | L17: =K17/J17 -> 0.68893625 | M17: =LN(L17) -> -0.37260654 | N17: 0.23825794 | O17: =N17/J17 -> 0.82157912 | P17: =LN(O17) -> -0.19652704 | Q17: 0.23700845 | R17: =Q17/J17 -> 0.8172705 | S17: =LN(R17) -> -0.20178514 | T17: 0.2534306 | U17: 0.29204706 | V17: 0.87389863 | W17: =LN(V17) -> -0.13479089 | X17: 0.32821577 | Y17: =X17/J17 -> 1.1317785 | Z17: =LN(Y17) -> 0.12379032 | AA17: 0.29871443 | AB17: =AA17/J17 -> 1.0300498 | AC17: =LN(AB17) -> 0.029607124 | BS17: =IF(AND(B17<=12.7,F17<=45),TRUE,FALSE) -> TRUE | BU17: =IF(AND(B17>12.7,F17<=45),TRUE,FALSE) -> FALSE | BW17: =IF(AND(F17<=45,C17>1),TRUE,FALSE) -> TRUE
A18: Viga S600-0.36-20 - Sokolov et al (2021) | B18: ='[4]Dados de entrada'!$B$28 -> 20 | C18: ='[4]Dados de entrada'!$B$31 -> 2 | D18: ='[4]Dados de entrada'!$B$32 -> 221 | E18: ='[4]Dados de entrada'!$B$27 -> 4.1311268 | F18: ='[4]Dados de entrada'!$B$30 -> 25 | G18: ='[4]Dados de entrada'!$B$22 -> 41 | H18: ='[4]Dados de entrada'!$B$29/(2*'[4]Dados de entrada'!$B$20*G18) -> 0.02462552 | I18: {='[4]Dados de entrada'!$E$7:$E$13} -> 262 | J18: {='[4]Dados de entrada'!$C$7:$C$13} -> 0.16 | K18: {='[4]fib Model Code 2010'!$F$5:$F$11} -> 0.20384075 | L18: =K18/J18 -> 1.2740047 | M18: =LN(L18) -> 0.24216524 | N18: {='[4]fib Model Code 2020'!$F$5:$F$11} -> 0.1574904 | O18: =N18/J18 -> 0.98431502 | P18: =LN(O18) -> -0.015809291 | Q18: {='[4]Eurocode 2'!$F$5:$F$11} -> 0.20246196 | R18: =Q18/J18 -> 1.2653873 | S18: =LN(R18) -> 0.2353782 | T18: {='[4]NBR 6118'!$F$5:$F$11} -> 0.38312941 | U18: {='[4]NBR 6118'!$G$5:$G$11} -> 0.17724043 | V18: {='[4]NBR 6118'!$L$5:$L$11} -> 1.1077527 | W18: =LN(V18) -> 0.10233333 | X18: {=[4]Sugestão!$G$5:$G$11} -> 0.18660042 | Y18: =X18/J18 -> 1.1662526 | Z18: =LN(Y18) -> 0.15379571 | AA18: {='[4]fib Model Code 2020 modificado'!$F$5:$F$11} -> 0.23744975 | AB18: =AA18/J18 -> 1.4840609 | AC18: =LN(AB18) -> 0.39478221 | BS18: =IF(AND(B18<=12.7,F18<=45),TRUE,FALSE) -> FALSE | BU18: =IF(AND(B18>12.7,F18<=45),TRUE,FALSE) -> TRUE | BW18: =IF(AND(F18<=45,C18>1),TRUE,FALSE) -> TRUE
B19: ='[4]Dados de entrada'!$B$28 -> 20 | C19: ='[4]Dados de entrada'!$B$31 -> 2 | D19: ='[4]Dados de entrada'!$B$32 -> 221 | E19: ='[4]Dados de entrada'!$B$27 -> 4.1311268 | F19: ='[4]Dados de entrada'!$B$30 -> 25 | G19: ='[4]Dados de entrada'!$B$22 -> 41 | H19: ='[4]Dados de entrada'!$B$29/(2*'[4]Dados de entrada'!$B$20*G19) -> 0.02462552 | I19: 289 | J19: 0.19 | K19: 0.24866101 | L19: =K19/J19 -> 1.3087422 | M19: =LN(L19) -> 0.2690665 | N19: 0.18560029 | O19: =N19/J19 -> 0.97684361 | P19: =LN(O19) -> -0.02342871 | Q19: 0.22332636 | R19: =Q19/J19 -> 1.1754019 | S19: =LN(R19) -> 0.16161013 | T19: 0.42261221 | U19: 0.21565319 | V19: 1.1350168 | W19: =LN(V19) -> 0.12664745 | X19: 0.22563016 | Y19: =X19/J19 -> 1.1875271 | Z19: =LN(Y19) -> 0.17187311 | AA19: 0.27750008 | AB19: =AA19/J19 -> 1.4605267 | AC19: =LN(AB19) -> 0.37879714 | BS19: =IF(AND(B19<=12.7,F19<=45),TRUE,FALSE) -> FALSE | BU19: =IF(AND(B19>12.7,F19<=45),TRUE,FALSE) -> TRUE | BW19: =IF(AND(F19<=45,C19>1),TRUE,FALSE) -> TRUE
B20: ='[4]Dados de entrada'!$B$28 -> 20 | C20: ='[4]Dados de entrada'!$B$31 -> 2 | D20: ='[4]Dados de entrada'!$B$32 -> 221 | E20: ='[4]Dados de entrada'!$B$27 -> 4.1311268 | F20: ='[4]Dados de entrada'!$B$30 -> 25 | G20: ='[4]Dados de entrada'!$B$22 -> 41 | H20: ='[4]Dados de entrada'!$B$29/(2*'[4]Dados de entrada'!$B$20*G20) -> 0.02462552 | I20: 315 | J20: 0.21 | K20: 0.29182127 | L20: =K20/J20 -> 1.3896251 | M20: =LN(L20) -> 0.32903398 | N20: 0.21266906 | O20: =N20/J20 -> 1.0127098 | P20: =LN(O20) -> 0.012629729 | Q20: 0.24341801 | R20: =Q20/J20 -> 1.1591334 | S20: =LN(R20) -> 0.14767262 | T20: 0.46063269 | U20: 0.25620129 | V20: 1.2200061 | W20: =LN(V20) -> 0.19885589 | X20: 0.26321435 | Y20: =X20/J20 -> 1.2534017 | Z20: =LN(Y20) -> 0.22586119 | AA20: 0.31672053 | AB20: =AA20/J20 -> 1.508193 | AC20: =LN(AB20) -> 0.41091226 | BS20: =IF(AND(B20<=12.7,F20<=45),TRUE,FALSE) -> FALSE | BU20: =IF(AND(B20>12.7,F20<=45),TRUE,FALSE) -> TRUE | BW20: =IF(AND(F20<=45,C20>1),TRUE,FALSE) -> TRUE
B21: ='[4]Dados de entrada'!$B$28 -> 20 | C21: ='[4]Dados de entrada'!$B$31 -> 2 | D21: ='[4]Dados de entrada'!$B$32 -> 221 | E21: ='[4]Dados de entrada'!$B$27 -> 4.1311268 | F21: ='[4]Dados de entrada'!$B$30 -> 25 | G21: ='[4]Dados de entrada'!$B$22 -> 41 | H21: ='[4]Dados de entrada'!$B$29/(2*'[4]Dados de entrada'!$B$20*G21) -> 0.02462552 | I21: 362 | J21: 0.24 | K21: 0.36984172 | L21: =K21/J21 -> 1.5410072 | M21: =LN(L21) -> 0.43243622 | N21: 0.26160108 | O21: =N21/J21 -> 1.0900045 | P21: =LN(O21) -> 0.086181828 | Q21: 0.28694335 | R21: =Q21/J21 -> 1.1955973 | S21: =LN(R21) -> 0.17864589 | T21: 0.52936201 | U21: 0.3383587 | V21: 1.4098279 | W21: =LN(V21) -> 0.34346764 | X21: 0.33115501 | Y21: =X21/J21 -> 1.3798125 | Z21: =LN(Y21) -> 0.32194765 | AA21: 0.38924611 | AB21: =AA21/J21 -> 1.6218588 | AC21: =LN(AB21) -> 0.4835729 | BS21: =IF(AND(B21<=12.7,F21<=45),TRUE,FALSE) -> FALSE | BU21: =IF(AND(B21>12.7,F21<=45),TRUE,FALSE) -> TRUE | BW21: =IF(AND(F21<=45,C21>1),TRUE,FALSE) -> TRUE
B22: ='[4]Dados de entrada'!$B$28 -> 20 | C22: ='[4]Dados de entrada'!$B$31 -> 2 | D22: ='[4]Dados de entrada'!$B$32 -> 221 | E22: ='[4]Dados de entrada'!$B$27 -> 4.1311268 | F22: ='[4]Dados de entrada'!$B$30 -> 25 | G22: ='[4]Dados de entrada'!$B$22 -> 41 | H22: ='[4]Dados de entrada'!$B$29/(2*'[4]Dados de entrada'!$B$20*G22) -> 0.02462552 | I22: 405 | J22: 0.27 | K22: 0.44122214 | L22: =K22/J22 -> 1.6341561 | M22: =LN(L22) -> 0.49112651 | N22: 0.30636867 | O22: =N22/J22 -> 1.1346988 | P22: =LN(O22) -> 0.12636723 | Q22: 0.34232417 | R22: =Q22/J22 -> 1.2678673 | S22: =LN(R22) -> 0.23733619 | T22: 0.59224203 | U22: 0.42351642 | V22: 1.5685793 | W22: =LN(V22) -> 0.45017032 | X22: 0.39331349 | Y22: =X22/J22 -> 1.4567166 | Z22: =LN(Y22) -> 0.37618501 | AA22: 0.45743454 | AB22: =AA22/J22 -> 1.694202 | AC22: =LN(AB22) -> 0.52721183 | BS22: =IF(AND(B22<=12.7,F22<=45),TRUE,FALSE) -> FALSE | BU22: =IF(AND(B22>12.7,F22<=45),TRUE,FALSE) -> TRUE | BW22: =IF(AND(F22<=45,C22>1),TRUE,FALSE) -> TRUE
B23: ='[4]Dados de entrada'!$B$28 -> 20 | C23: ='[4]Dados de entrada'!$B$31 -> 2 | D23: ='[4]Dados de entrada'!$B$32 -> 221 | E23: ='[4]Dados de entrada'!$B$27 -> 4.1311268 | F23: ='[4]Dados de entrada'!$B$30 -> 25 | G23: ='[4]Dados de entrada'!$B$22 -> 41 | H23: ='[4]Dados de entrada'!$B$29/(2*'[4]Dados de entrada'!$B$20*G23) -> 0.02462552 | I23: 451 | J23: 0.3 | K23: 0.51758259 | L23: =K23/J23 -> 1.7252753 | M23: =LN(L23) -> 0.54538663 | N23: 0.35425958 | O23: =N23/J23 -> 1.1808653 | P23: =LN(O23) -> 0.16624746 | Q23: 0.40156876 | R23: =Q23/J23 -> 1.3385625 | S23: =LN(R23) -> 0.2915963 | T23: 0.65950902 | U23: 0.52518618 | V23: 1.7506206 | W23: =LN(V23) -> 0.55997035 | X23: 0.4598086 | Y23: =X23/J23 -> 1.5326953 | Z23: =LN(Y23) -> 0.42702784 | AA23: 0.53232177 | AB23: =AA23/J23 -> 1.7744059 | AC23: =LN(AB23) -> 0.57346565 | BS23: =IF(AND(B23<=12.7,F23<=45),TRUE,FALSE) -> FALSE | BU23: =IF(AND(B23>12.7,F23<=45),TRUE,FALSE) -> TRUE | BW23: =IF(AND(F23<=45,C23>1),TRUE,FALSE) -> TRUE
B24: ='[4]Dados de entrada'!$B$28 -> 20 | C24: ='[4]Dados de entrada'!$B$31 -> 2 | D24: ='[4]Dados de entrada'!$B$32 -> 221 | E24: ='[4]Dados de entrada'!$B$27 -> 4.1311268 | F24: ='[4]Dados de entrada'!$B$30 -> 25 | G24: ='[4]Dados de entrada'!$B$22 -> 41 | H24: ='[4]Dados de entrada'!$B$29/(2*'[4]Dados de entrada'!$B$20*G24) -> 0.02462552 | I24: 489 | J24: 0.33 | K24: 0.58066296 | L24: =K24/J24 -> 1.7595847 | M24: =LN(L24) -> 0.56507783 | N24: 0.39382164 | O24: =N24/J24 -> 1.1933989 | P24: =LN(O24) -> 0.17680547 | Q24: 0.45050995 | R24: =Q24/J24 -> 1.3651817 | S24: =LN(R24) -> 0.3112875 | T24: 0.71507741 | U24: 0.61741606 | V24: 1.8709578 | W24: =LN(V24) -> 0.62645047 | X24: 0.50910121 | Y24: =X24/J24 -> 1.542731 | Z24: =LN(Y24) -> 0.43355419 | AA24: 0.59569884 | AB24: =AA24/J24 -> 1.805148 | AC24: =LN(AB24) -> 0.59064259 | BS24: =IF(AND(B24<=12.7,F24<=45),TRUE,FALSE) -> FALSE | BU24: =IF(AND(B24>12.7,F24<=45),TRUE,FALSE) -> TRUE | BW24: =IF(AND(F24<=45,C24>1),TRUE,FALSE) -> TRUE
A25: Viga S600-0.37-10 - Sokolov et al (2021) | B25: ='[5]Dados de entrada'!$B$28 -> 10 | C25: ='[5]Dados de entrada'!$B$31 -> 8 | D25: ='[5]Dados de entrada'!$B$32 -> 87.7 | E25: ='[5]Dados de entrada'!$B$27 -> 4.1311268 | F25: ='[5]Dados de entrada'!$B$30 -> 25 | G25: ='[5]Dados de entrada'!$B$22 -> 53 | H25: ='[5]Dados de entrada'!$B$29/(2*'[5]Dados de entrada'!$B$20*G25) -> 0.019235481 | I25: {='[5]fib Model Code 2010'!$K$5:$K$7} -> 322.91972 | J25: {='[5]Dados de entrada'!$C$7:$C$9} -> 0.16 | K25: {='[5]fib Model Code 2010'!$F$5:$F$7} -> 0.17235205 | L25: =K25/J25 -> 1.0772003 | M25: =LN(L25) -> 0.074365387 | N25: {='[5]fib Model Code 2020'!$F$5:$F$7} -> 0.13686888 | O25: =N25/J25 -> 0.85543047 | P25: =LN(O25) -> -0.15615046 | Q25: {='[5]Eurocode 2'!$F$5:$F$7} -> 0.18999969 | R25: =Q25/J25 -> 1.187498 | S25: =LN(R25) -> 0.17184861 | T25: {='[5]NBR 6118'!$F$5:$F$7} -> 0.23525549 | U25: {='[5]NBR 6118'!$G$5:$G$7} -> 0.13552525 | V25: {='[5]NBR 6118'!$L$5:$L$7} -> 0.84703283 | W25: =LN(V25) -> -0.16601582 | X25: {=[5]Sugestão!$G$5:$G$7} -> 0.22227013 | Y25: =X25/J25 -> 1.3891883 | Z25: =LN(Y25) -> 0.32871961 | AA25: {='[5]fib Model Code 2020 modificado'!$F$5:$F$7} -> 0.1725313 | AB25: =AA25/J25 -> 1.0783206 | AC25: =LN(AB25) -> 0.075404872 | AD25: {='[5]fib Model Code 2010'!$L$5:$L$7} -> 0.17110696 | AE25: =AD25/J25 -> 1.0694185 | AF25: {=LN(AE25:AE27)} -> 0.067115064 | AG25: {='[5]fib Model Code 2020'!$L$5:$L$7} -> 0.13580673 | AH25: =AG25/J25 -> 0.84879204 | AI25: {=LN(AH25:AH27)} -> -0.16394107 | AJ25: {='[5]Eurocode 2'!$L$5:$L$7} -> 0.18936619 | AK25: =AJ25/J25 -> 1.1835387 | AL25: {=LN(AK25:AK27)} -> 0.16850883 | AM25: {='[5]NBR 6118'!$Q$5:$Q$7} -> 0.2432138 | AN25: {='[5]NBR 6118'!$R$5:$R$7} -> 0.14484953 | AO25: {='[5]NBR 6118'!$W$5:$W$7} -> 0.90530958 | AP25: {=LN(AO25:AO27)} -> -0.099478313 | AQ25: {='[5]Clark (1956)'!$L$5:$L$7} -> 0.18168754 | AR25: =AQ25/J25 -> 1.1355471 | AS25: {=LN(AR25:AR27)} -> 0.12711456 | AT25: {='[5]Leonhardt (1977)'!$L$5:$L$7} -> 0.25673146 | AU25: =AT25/J25 -> 1.6045716 | AV25: {=LN(AU25:AU27)} -> 0.47285683 | AW25: {='[5]Desayi; Ganesan (1985)'!$L$5:$L$7} -> 0.26529738 | AX25: =AW25/J25 -> 1.6581086 | AY25: {=LN(AX25:AX27)} -> 0.50567757 | AZ25: {='[5]Oh; Kang (1987)'!$L$5:$L$7} -> 0.10483023 | BA25: =AZ25/J25 -> 0.65518891 | BB25: {=LN(BA25:BA27)} -> -0.42283167 | BC25: {='[5]Caldas (1997)'!$L$5:$L$7} -> 0.25496881 | BD25: =BC25/J25 -> 1.5935551 | BE25: {=LN(BD25:BD27)} -> 0.46596742 | BF25: {='[5]Gergely e Lutz (1968)'!$L$5:$L$7} -> 0.18984253 | BG25: =BF25/J25 -> 1.1865158 | BH25: {=LN(BG25:BG27)} -> 0.1710211 | BI25: {=[5]Sugestão!$N$5:$N$7} -> 0.22051937 | BJ25: =BI25/J25 -> 1.378246 | BK25: {=LN(BJ25:BJ27)} -> 0.3208117 | BL25: {='[5]fib Model Code 2020 modificado'!$L$5:$L$7} -> 0.17131099 | BM25: =BL25/J25 -> 1.0706937 | BN25: {=LN(BM25:BM27)} -> 0.068306751 | BS25: =IF(AND(B25<=12.7,F25<=45),TRUE,FALSE) -> TRUE | BU25: =IF(AND(B25>12.7,F25<=45),TRUE,FALSE) -> FALSE | BW25: =IF(AND(F25<=45,C25>1),TRUE,FALSE) -> TRUE
B26: ='[5]Dados de entrada'!$B$28 -> 10 | C26: ='[5]Dados de entrada'!$B$31 -> 8 | D26: ='[5]Dados de entrada'!$B$32 -> 87.7 | E26: ='[5]Dados de entrada'!$B$27 -> 4.1311268 | F26: ='[5]Dados de entrada'!$B$30 -> 25 | G26: ='[5]Dados de entrada'!$B$22 -> 53 | H26: ='[5]Dados de entrada'!$B$29/(2*'[5]Dados de entrada'!$B$20*G26) -> 0.019235481 | I26: 367.82093 | J26: 0.18 | K26: 0.22882733 | L26: =K26/J26 -> 1.2712629 | M26: =LN(L26) -> 0.24001084 | N26: 0.18504628 | O26: =N26/J26 -> 1.0280349 | P26: =LN(O26) -> 0.027649091 | Q26: 0.21873421 | R26: =Q26/J26 -> 1.21519 | S26: =LN(R26) -> 0.19490048 | T26: 0.27083426 | U26: 0.17961718 | V26: 0.99787321 | W26: =LN(V26) -> -0.0021290508 | X26: 0.30168188 | Y26: =X26/J26 -> 1.6760104 | Z26: =LN(Y26) -> 0.51641624 | AA26: 0.22815889 | AB26: =AA26/J26 -> 1.2675494 | AC26: =LN(AB26) -> 0.2370854 | AD26: 0.22285816 | AE26: =AD26/J26 -> 1.2381009 | AF26: 0.21357866 | AG26: 0.17995416 | AH26: =AG26/J26 -> 0.99974531 | AI26: -0.00025472468 | AJ26: 0.21569711 | AK26: =AJ26/J26 -> 1.1983173 | AL26: 0.18091829 | AM26: 0.2770321 | AN26: 0.18793205 | AO26: 1.044067 | AP26: 0.043123635 | AQ26: 0.21973648 | AR26: =AQ26/J26 -> 1.2207582 | AS26: 0.19947218 | AT26: 0.3010927 | AU26: =AT26/J26 -> 1.6727372 | AV26: 0.51446134 | AW26: 0.30218635 | AX26: =AW26/J26 -> 1.678813 | AY26: 0.51808702 | AZ26: 0.12146747 | BA26: =AZ26/J26 -> 0.67481929 | BB26: -0.39331035 | BC26: 0.29679814 | BD26: =BC26/J26 -> 1.6488785 | BE26: 0.50009539 | BF26: 0.21623968 | BG26: =BF26/J26 -> 1.2013315 | BH26: 0.18343056 | BI26: 0.29328844 | BJ26: =BI26/J26 -> 1.6293802 | BK26: 0.4881997 | BL26: 0.22225378 | BM26: =BL26/J26 -> 1.2347432 | BN26: 0.21086301 | BS26: =IF(AND(B26<=12.7,F26<=45),TRUE,FALSE) -> TRUE | BU26: =IF(AND(B26>12.7,F26<=45),TRUE,FALSE) -> FALSE | BW26: =IF(AND(F26<=45,C26>1),TRUE,FALSE) -> TRUE
B27: ='[5]Dados de entrada'!$B$28 -> 10 | C27: ='[5]Dados de entrada'!$B$31 -> 8 | D27: ='[5]Dados de entrada'!$B$32 -> 87.7 | E27: ='[5]Dados de entrada'!$B$27 -> 4.1311268 | F27: ='[5]Dados de entrada'!$B$30 -> 25 | G27: ='[5]Dados de entrada'!$B$22 -> 53 | H27: ='[5]Dados de entrada'!$B$29/(2*'[5]Dados de entrada'!$B$20*G27) -> 0.019235481 | I27: 500 | J27: 0.26 | K27: 0.34177788 | L27: =K27/J27 -> 1.3145303 | M27: =LN(L27) -> 0.27347941 | N27: 0.28140108 | O27: =N27/J27 -> 1.0823118 | P27: =LN(O27) -> 0.079099355 | Q27: 0.28982664 | R27: =Q27/J27 -> 1.1147179 | S27: =LN(R27) -> 0.10860132 | T27: 0.34199178 | U27: 0.28639935 | V27: 1.1015359 | W27: =LN(V27) -> 0.096705518 | X27: 0.46050539 | Y27: =X27/J27 -> 1.7711746 | Z27: =LN(Y27) -> 0.57164293 | AA27: 0.34103522 | AB27: =AA27/J27 -> 1.3116739 | AC27: =LN(AB27) -> 0.27130412 | AD27: 0.37520202 | AE27: =AD27/J27 -> 1.4430847 | AF27: 0.36678296 | AG27: 0.30991424 | AH27: =AG27/J27 -> 1.1919778 | AI27: 0.17561397 | AJ27: 0.31817022 | AK27: =AJ27/J27 -> 1.2237316 | AL27: 0.20190488 | AM27: 0.3630486 | AN27: 0.32275295 | AO27: 1.2413575 | AP27: 0.21620553 | AQ27: 0.33174401 | AR27: =AQ27/J27 -> 1.2759385 | AS27: 0.243682 | AT27: 0.42745969 | AU27: =AT27/J27 -> 1.6440757 | AV27: 0.49717836 | AW27: 0.41077916 | AX27: =AW27/J27 -> 1.5799198 | AY27: 0.45737412 | AZ27: 0.17044377 | BA27: =AZ27/J27 -> 0.65555297 | BB27: -0.42227616 | BC27: 0.43772597 | BD27: =BC27/J27 -> 1.6835614 | BE27: 0.52091146 | BF27: 0.30517474 | BG27: =BF27/J27 -> 1.173749 | BH27: 0.16020288 | BI27: 0.49160614 | BJ27: =BI27/J27 -> 1.8907928 | BK27: 0.63699624 | BL27: 0.37485186 | BM27: =BL27/J27 -> 1.4417379 | BN27: 0.36584929 | BS27: =IF(AND(B27<=12.7,F27<=45),TRUE,FALSE) -> TRUE | BU27: =IF(AND(B27>12.7,F27<=45),TRUE,FALSE) -> FALSE | BW27: =IF(AND(F27<=45,C27>1),TRUE,FALSE) -> TRUE
A28: Viga V1 - Oliveira (2007) | B28: ='[6]Dados de entrada'!$B$28 -> 10 | C28: ='[6]Dados de entrada'!$B$31 -> 4 | D28: ='[6]Leonhardt (1977)'!$B$27 -> 32.466667 | E28: ='[6]Dados de entrada'!$B$27 -> 3.262 | F28: ='[6]Dados de entrada'!$B$30 -> 25 | G28: ='[6]Dados de entrada'!$B$22 -> 36 | H28: ='[6]Dados de entrada'!$B$29/('[6]Dados de entrada'!$B$20*2*G28) -> 0.021805556 | I28: ='[6]fib Model Code 2010'!$K$5 -> 285.04803 | J28: ='[6]Dados de entrada'!$C$7 -> 0.16 | K28: ='[6]fib Model Code 2010'!$F$5 -> 0.10601037 | L28: =K28/J28 -> 0.6625648 | M28: =LN(L28) -> -0.41163692 | N28: ='[6]fib Model Code 2020'!$F$5 -> 0.093253932 | O28: =N28/J28 -> 0.58283707 | P28: =LN(O28) -> -0.53984759 | Q28: ='[6]Eurocode 2'!$F$5 -> 0.120309 | R28: =Q28/J28 -> 0.75193125 | S28: =LN(R28) -> -0.28511038 | T28: ='[6]NBR 6118'!$F$5 -> 0.14505628 | U28: ='[6]NBR 6118'!$G$5 -> 0.082939124 | V28: ='[6]NBR 6118'!$L$5 -> 0.51836953 | W28: =LN(V28) -> -0.65706692 | X28: {=[6]Sugestão!$G$5:$G$9} -> 0.1036973 | Y28: =X28/J28 -> 0.6481081 | Z28: =LN(Y28) -> -0.43369778 | AA28: {='[6]fib Model Code 2020 modificado'!$F$5:$F$9} -> 0.11850024 | AB28: =AA28/J28 -> 0.74062649 | AC28: =LN(AB28) -> -0.30025884 | AD28: ='[6]fib Model Code 2010'!$L$5 -> 0.16007092 | AE28: =AD28/J28 -> 1.0004432 | AF28: =LN(AE28) -> 0.00044314 | AG28: ='[6]fib Model Code 2020'!$L$5 -> 0.13868029 | AH28: =AG28/J28 -> 0.86675181 | AI28: =LN(AH28) -> -0.1430026 | AJ28: ='[6]Eurocode 2'!$L$5 -> 0.14859328 | AK28: =AJ28/J28 -> 0.92870802 | AL28: =LN(AK28) -> -0.073960888 | AM28: ='[6]NBR 6118'!$Q$5 -> 0.184404 | AN28: ='[6]NBR 6118'!$R$5 -> 0.13403772 | AO28: ='[6]NBR 6118'!$W$5 -> 0.83773573 | AP28: =LN(AO28) -> -0.17705258 | AQ28: ='[6]Clark (1956)'!$L$5 -> 0.10601728 | AR28: =AQ28/J28 -> 0.66260803 | AS28: =LN(AR28) -> -0.41157168 | AT28: ='[6]Leonhardt (1977)'!$L$5 -> 0.22216283 | AU28: =AT28/J28 -> 1.3885177 | AV28: =LN(AU28) -> 0.32823675 | AW28: ='[6]Desayi; Ganesan (1985)'!$L$5 -> 0.16892963 | AX28: =AW28/J28 -> 1.0558102 | AY28: =LN(AX28) -> 0.054308402 | AZ28: ='[6]Oh; Kang (1987)'!$L$5 -> 0.11084938 | BA28: =AZ28/J28 -> 0.69280866 | BB28: =LN(BA28) -> -0.36700143 | BC28: ='[6]Caldas (1997)'!$L$5 -> 0.21176099 | BD28: =BC28/J28 -> 1.3235062 | BE28: =LN(BD28) -> 0.2802844 | BF28: {='[6]Gergely e Lutz (1968)'!$L$5:$L$14} -> 0.17087505 | BG28: =BF28/J28 -> 1.0679691 | BH28: =LN(BG28) -> 0.065758788 | BI28: {=[6]Sugestão!$N$5:$N$14} -> 0.16724728 | BJ28: =BI28/J28 -> 1.0452955 | BK28: =LN(BJ28) -> 0.04429965 | BL28: {='[6]fib Model Code 2020 modificado'!$L$5:$L$14} -> 0.17212596 | BM28: =BL28/J28 -> 1.0757873 | BN28: =LN(BM28) -> 0.073052743 | BS28: =IF(AND(B28<=12.7,F28<=45),TRUE,FALSE) -> TRUE | BU28: =IF(AND(B28>12.7,F28<=45),TRUE,FALSE) -> FALSE | BW28: =IF(AND(F28<=45,C28>1),TRUE,FALSE) -> TRUE
B29: =B32 -> 10 | C29: ='[6]Dados de entrada'!$B$31 -> 4 | D29: ='[6]Leonhardt (1977)'!$B$27 -> 32.466667 | E29: ='[6]Dados de entrada'!$B$27 -> 3.262 | F29: ='[6]Dados de entrada'!$B$30 -> 25 | G29: ='[6]Dados de entrada'!$B$22 -> 36 | H29: ='[6]Dados de entrada'!$B$29/('[6]Dados de entrada'!$B$20*2*G29) -> 0.021805556 | I29: ='[6]fib Model Code 2010'!$K$6 -> 324.99965 | J29: ='[6]Dados de entrada'!$C$8 -> 0.2 | K29: ='[6]fib Model Code 2010'!$F$6 -> 0.16627024 | L29: =K29/J29 -> 0.8313512 | M29: =LN(L29) -> -0.18470295 | N29: ='[6]fib Model Code 2020'!$F$6 -> 0.1438895 | O29: =N29/J29 -> 0.71944749 | P29: =LN(O29) -> -0.32927174 | Q29: ='[6]Eurocode 2'!$F$6 -> 0.15183675 | R29: =Q29/J29 -> 0.75918373 | S29: =LN(R29) -> -0.27551147 | T29: ='[6]NBR 6118'!$F$6 -> 0.18306921 | U29: ='[6]NBR 6118'!$G$6 -> 0.13210431 | V29: ='[6]NBR 6118'!$L$6 -> 0.66052155 | W29: =LN(V29) -> -0.41472554 | X29: 0.1745348 | Y29: =X29/J29 -> 0.87267398 | Z29: =LN(Y29) -> -0.13619324 | AA29: 0.17833051 | AB29: =AA29/J29 -> 0.89165255 | AC29: =LN(AB29) -> -0.11467875 | AD29: ='[6]fib Model Code 2010'!$L$6 -> 0.19987712 | AE29: =AD29/J29 -> 0.99938561 | AF29: =LN(AE29) -> -0.00061458239 | AG29: ='[6]fib Model Code 2020'!$L$6 -> 0.17212891 | AH29: =AG29/J29 -> 0.86064456 | AI29: =LN(AH29) -> -0.15007369 | AJ29: ='[6]Eurocode 2'!$L$6 -> 0.17429163 | AK29: =AJ29/J29 -> 0.87145816 | AL29: =LN(AK29) -> -0.13758742 | AM29: ='[6]NBR 6118'!$Q$6 -> 0.2102496 | AN29: ='[6]NBR 6118'!$R$6 -> 0.17424355 | AO29: ='[6]NBR 6118'!$W$6 -> 0.87121774 | AP29: =LN(AO29) -> -0.13786335 | AQ29: ='[6]Clark (1956)'!$L$6 -> 0.13588175 | AR29: =AQ29/J29 -> 0.67940876 | AS29: =LN(AR29) -> -0.38653233 | AT29: ='[6]Leonhardt (1977)'!$L$6 -> 0.26988804 | AU29: =AT29/J29 -> 1.3494402 | AV29: =LN(AU29) -> 0.29968985 | AW29: ='[6]Desayi; Ganesan (1985)'!$L$6 -> 0.19260638 | AX29: =AW29/J29 -> 0.96303189 | AY29: =LN(AX29) -> -0.037668756 | AZ29: ='[6]Oh; Kang (1987)'!$L$6 -> 0.12907052 | BA29: =AZ29/J29 -> 0.64535262 | BB29: =LN(BA29) -> -0.43795842 | BC29: ='[6]Caldas (1997)'!$L$6 -> 0.24668621 | BD29: =BC29/J29 -> 1.233431 | BE29: =LN(BD29) -> 0.20979976 | BF29: 0.19482447 | BG29: =BF29/J29 -> 0.97412235 | BH29: =LN(BG29) -> -0.026218369 | BI29: 0.21404081 | BJ29: =BI29/J29 -> 1.0702041 | BK29: =LN(BJ29) -> 0.067849335 | BL29: 0.21216297 | BM29: =BL29/J29 -> 1.0608148 | BN29: =LN(BM29) -> 0.059037331 | BS29: =IF(AND(B29<=12.7,F29<=45),TRUE,FALSE) -> TRUE | BU29: =IF(AND(B29>12.7,F29<=45),TRUE,FALSE) -> FALSE | BW29: =IF(AND(F29<=45,C29>1),TRUE,FALSE) -> TRUE
B30: ='Dados gerais'!$B$32 -> 10 | C30: ='[6]Dados de entrada'!$B$31 -> 4 | D30: ='[6]Leonhardt (1977)'!$B$27 -> 32.466667 | E30: ='[6]Dados de entrada'!$B$27 -> 3.262 | F30: ='[6]Dados de entrada'!$B$30 -> 25 | G30: ='[6]Dados de entrada'!$B$22 -> 36 | H30: ='[6]Dados de entrada'!$B$29/('[6]Dados de entrada'!$B$20*2*G30) -> 0.021805556 | I30: ='[6]fib Model Code 2010'!$K$7 -> 367.64463 | J30: ='[6]Dados de entrada'!$C$9 -> 0.2 | K30: ='[6]fib Model Code 2010'!$F$7 -> 0.22443776 | L30: =K30/J30 -> 1.1221888 | M30: =LN(L30) -> 0.11528105 | N30: ='[6]fib Model Code 2020'!$F$7 -> 0.19276688 | O30: =N30/J30 -> 0.96383442 | P30: =LN(O30) -> -0.036835762 | Q30: ='[6]Eurocode 2'!$F$7 -> 0.19570836 | R30: =Q30/J30 -> 0.97854178 | S30: =LN(R30) -> -0.021691791 | T30: ='[6]NBR 6118'!$F$7 -> 0.21976225 | U30: ='[6]NBR 6118'!$G$7 -> 0.19036738 | V30: ='[6]NBR 6118'!$L$7 -> 0.95183691 | W30: =LN(V30) -> -0.049361572 | X30: 0.24291266 | Y30: =X30/J30 -> 1.2145633 | Z30: =LN(Y30) -> 0.19438459 | AA30: 0.23709912 | AB30: =AA30/J30 -> 1.1854956 | AC30: =LN(AB30) -> 0.17016093 | AD30: ='[6]fib Model Code 2010'!$L$7 -> 0.24236689 | AE30: =AD30/J30 -> 1.2118344 | AF30: =LN(AE30) -> 0.19213528 | AG30: ='[6]fib Model Code 2020'!$L$7 -> 0.20783249 | AH30: =AG30/J30 -> 1.0391625 | AI30: =LN(AH30) -> 0.038415076 | AJ30: ='[6]Eurocode 2'!$L$7 -> 0.21134245 | AK30: =AJ30/J30 -> 1.0567123 | AL30: =LN(AK30) -> 0.055162444 | AM30: ='[6]NBR 6118'!$Q$7 -> 0.2378376 | AN30: ='[6]NBR 6118'!$R$7 -> 0.22297048 | AO30: ='[6]NBR 6118'!$W$7 -> 1.1148524 | AP30: =LN(AO30) -> 0.10872204 | AQ30: ='[6]Clark (1956)'!$L$7 -> 0.16775955 | AR30: =AQ30/J30 -> 0.83879777 | AS30: =LN(AR30) -> -0.17578564 | AT30: ='[6]Leonhardt (1977)'!$L$7 -> 0.31897202 | AU30: =AT30/J30 -> 1.5948601 | AV30: =LN(AU30) -> 0.46678603 | AW30: ='[6]Desayi; Ganesan (1985)'!$L$7 -> 0.21787931 | AX30: =AW30/J30 -> 1.0893966 | AY30: =LN(AX30) -> 0.085623936 | AZ30: ='[6]Oh; Kang (1987)'!$L$7 -> 0.14852005 | BA30: =AZ30/J30 -> 0.74260027 | BB30: =LN(BA30) -> -0.29759738 | BC30: ='[6]Caldas (1997)'!$L$7 -> 0.28396594 | BD30: =BC30/J30 -> 1.4198297 | BE30: =LN(BD30) -> 0.35053695 | BF30: 0.22038845 | BG30: =BF30/J30 -> 1.1019423 | BH30: =LN(BG30) -> 0.097074322 | BI30: 0.26398896 | BJ30: =BI30/J30 -> 1.3199448 | BK30: =LN(BJ30) -> 0.2775899 | BL30: 0.25541472 | BM30: =BL30/J30 -> 1.2770736 | BN30: =LN(BM30) -> 0.2445712 | BS30: =IF(AND(B30<=12.7,F30<=45),TRUE,FALSE) -> TRUE | BU30: =IF(AND(B30>12.7,F30<=45),TRUE,FALSE) -> FALSE | BW30: =IF(AND(F30<=45,C30>1),TRUE,FALSE) -> TRUE
B31: ='[6]Dados de entrada'!$B$28 -> 10 | C31: ='[6]Dados de entrada'!$B$31 -> 4 | D31: ='[6]Leonhardt (1977)'!$B$27 -> 32.466667 | E31: ='[6]Dados de entrada'!$B$27 -> 3.262 | F31: ='[6]Dados de entrada'!$B$30 -> 25 | G31: ='[6]Dados de entrada'!$B$22 -> 36 | H31: ='[6]Dados de entrada'!$B$29/('[6]Dados de entrada'!$B$20*2*G31) -> 0.021805556 | I31: ='[6]fib Model Code 2010'!$K$8 -> 410.7385 | J31: ='[6]Dados de entrada'!$C$10 -> 0.24 | K31: ='[6]fib Model Code 2010'!$F$8 -> 0.26712183 | L31: =K31/J31 -> 1.1130076 | M31: =LN(L31) -> 0.10706593 | N31: ='[6]fib Model Code 2020'!$F$8 -> 0.22863374 | O31: =N31/J31 -> 0.9526406 | P31: =LN(O31) -> -0.048517574 | Q31: ='[6]Eurocode 2'!$F$8 -> 0.23292861 | R31: =Q31/J31 -> 0.97053588 | S31: =LN(R31) -> -0.029906905 | T31: ='[6]NBR 6118'!$F$8 -> 0.24668807 | U31: ='[6]NBR 6118'!$G$8 -> 0.23987372 | V31: ='[6]NBR 6118'!$L$8 -> 0.99947382 | W31: =LN(V31) -> -0.00052631874 | X31: 0.29308922 | Y31: =X31/J31 -> 1.2212051 | Z31: =LN(Y31) -> 0.19983815 | AA31: 0.28085906 | AB31: =AA31/J31 -> 1.1702461 | AC31: =LN(AB31) -> 0.15721407 | AD31: ='[6]fib Model Code 2010'!$L$8 -> 0.28530392 | AE31: =AD31/J31 -> 1.1887663 | AF31: =LN(AE31) -> 0.17291606 | AG31: ='[6]fib Model Code 2020'!$L$8 -> 0.24391191 | AH31: =AG31/J31 -> 1.0162996 | AI31: =LN(AH31) -> 0.016168196 | AJ31: ='[6]Eurocode 2'!$L$8 -> 0.24878328 | AK31: =AJ31/J31 -> 1.036597 | AL31: =LN(AK31) -> 0.035943227 | AM31: ='[6]NBR 6118'!$Q$8 -> 0.265716 | AN31: ='[6]NBR 6118'!$R$8 -> 0.27830548 | AO31: ='[6]NBR 6118'!$W$8 -> 1.10715 | AP31: =LN(AO31) -> 0.10178913 | AQ31: ='[6]Clark (1956)'!$L$8 -> 0.19997291 | AR31: =AQ31/J31 -> 0.83322047 | AS31: =LN(AR31) -> -0.182457 | AT31: ='[6]Leonhardt (1977)'!$L$8 -> 0.36721962 | AU31: =AT31/J31 -> 1.5300817 | AV31: =LN(AU31) -> 0.42532116 | AW31: ='[6]Desayi; Ganesan (1985)'!$L$8 -> 0.24341828 | AX31: =AW31/J31 -> 1.0142428 | AY31: =LN(AX31) -> 0.01414236 | AZ31: ='[6]Oh; Kang (1987)'!$L$8 -> 0.16817431 | BA31: =AZ31/J31 -> 0.70072631 | BB31: =LN(BA31) -> -0.35563789 | BC31: ='[6]Caldas (1997)'!$L$8 -> 0.3216381 | BD31: =BC31/J31 -> 1.3401587 | BE31: =LN(BD31) -> 0.29278806 | BF31: 0.24622153 | BG31: =BF31/J31 -> 1.0259231 | BH31: =LN(BG31) -> 0.025592747 | BI31: 0.31446287 | BJ31: =BI31/J31 -> 1.310262 | BK31: =LN(BJ31) -> 0.27022709 | BL31: 0.29966262 | BM31: =BL31/J31 -> 1.2485943 | BN31: =LN(BM31) -> 0.22201833 | BS31: =IF(AND(B31<=12.7,F31<=45),TRUE,FALSE) -> TRUE | BU31: =IF(AND(B31>12.7,F31<=45),TRUE,FALSE) -> FALSE | BW31: =IF(AND(F31<=45,C31>1),TRUE,FALSE) -> TRUE
B32: ='[6]Dados de entrada'!$B$28 -> 10 | C32: ='[6]Dados de entrada'!$B$31 -> 4 | D32: ='[6]Leonhardt (1977)'!$B$27 -> 32.466667 | E32: ='[6]Dados de entrada'!$B$27 -> 3.262 | F32: ='[6]Dados de entrada'!$B$30 -> 25 | G32: ='[6]Dados de entrada'!$B$22 -> 36 | H32: ='[6]Dados de entrada'!$B$29/('[6]Dados de entrada'!$B$20*2*G32) -> 0.021805556 | I32: ='[6]fib Model Code 2010'!$K$9 -> 438.56996 | J32: ='[6]Dados de entrada'!$C$11 -> 0.3 | K32: ='[6]fib Model Code 2010'!$F$9 -> 0.2792575 | L32: =K32/J32 -> 0.93085834 | M32: =LN(L32) -> -0.071648175 | N32: ='[6]fib Model Code 2020'!$F$9 -> 0.23883118 | O32: =N32/J32 -> 0.79610395 | P32: =LN(O32) -> -0.22802552 | Q32: ='[6]Eurocode 2'!$F$9 -> 0.24351084 | R32: =Q32/J32 -> 0.8117028 | S32: =LN(R32) -> -0.20862101 | T32: ='[6]NBR 6118'!$F$9 -> 0.25434346 | U32: ='[6]NBR 6118'!$G$9 -> 0.25499255 | V32: ='[6]NBR 6118'!$L$9 -> 0.84781152 | W32: =LN(V32) -> -0.16509694 | X32: 0.30735511 | Y32: =X32/J32 -> 1.024517 | Z32: =LN(Y32) -> 0.024221307 | AA32: 0.29339872 | AB32: =AA32/J32 -> 0.97799572 | AC32: =LN(AB32) -> -0.022249983 | AD32: ='[6]fib Model Code 2010'!$L$9 -> 0.31303408 | AE32: =AD32/J32 -> 1.0434469 | AF32: =LN(AE32) -> 0.042529595 | AG32: ='[6]fib Model Code 2020'!$L$9 -> 0.26721319 | AH32: =AG32/J32 -> 0.89071064 | AI32: =LN(AH32) -> -0.11573566 | AJ32: ='[6]Eurocode 2'!$L$9 -> 0.27296381 | AK32: =AJ32/J32 -> 0.90987938 | AL32: =LN(AK32) -> -0.094443243 | AM32: ='[6]NBR 6118'!$Q$9 -> 0.2837208 | AN32: ='[6]NBR 6118'!$R$9 -> 0.317299 | AO32: ='[6]NBR 6118'!$W$9 -> 0.94573599 | AP32: =LN(AO32) -> -0.05579183 | AQ32: ='[6]Clark (1956)'!$L$9 -> 0.22077737 | AR32: =AQ32/J32 -> 0.73592458 | AS32: =LN(AR32) -> -0.30662764 | AT32: ='[6]Leonhardt (1977)'!$L$9 -> 0.39784385 | AU32: =AT32/J32 -> 1.3261462 | AV32: =LN(AU32) -> 0.28227711 | AW32: ='[6]Desayi; Ganesan (1985)'!$L$9 -> 0.2599122 | AX32: =AW32/J32 -> 0.86637399 | AY32: =LN(AX32) -> -0.1434386 | AZ32: ='[6]Oh; Kang (1987)'!$L$9 -> 0.18086769 | BA32: =AZ32/J32 -> 0.60289231 | BB32: =LN(BA32) -> -0.50601669 | BC32: ='[6]Caldas (1997)'!$L$9 -> 0.34596803 | BD32: =BC32/J32 -> 1.1532268 | BE32: =LN(BD32) -> 0.14256389 | BF32: 0.2629054 | BG32: =BF32/J32 -> 0.87635132 | BH32: =LN(BG32) -> -0.13198822 | BI32: 0.34706061 | BJ32: =BI32/J32 -> 1.1568687 | BK32: =LN(BJ32) -> 0.14571696 | BL32: 0.32852835 | BM32: =BL32/J32 -> 1.0950945 | BN32: =LN(BM32) -> 0.090840673 | BS32: =IF(AND(B32<=12.7,F32<=45),TRUE,FALSE) -> TRUE | BU32: =IF(AND(B32>12.7,F32<=45),TRUE,FALSE) -> FALSE | BW32: =IF(AND(F32<=45,C32>1),TRUE,FALSE) -> TRUE
B33: ='[6]Dados de entrada'!$B$28 -> 10 | C33: ='[6]Dados de entrada'!$B$31 -> 4 | D33: ='[6]Leonhardt (1977)'!$B$27 -> 32.466667 | E33: ='[6]Dados de entrada'!$B$27 -> 3.262 | F33: ='[6]Dados de entrada'!$B$30 -> 25 | G33: ='[6]Dados de entrada'!$B$22 -> 36 | H33: ='[6]Dados de entrada'!$B$29/('[6]Dados de entrada'!$B$20*2*G33) -> 0.021805556 | I33: ='[6]fib Model Code 2010'!$K$10 -> 498.27294 | J33: ='[6]Dados de entrada'!$C$12 -> 0.32 | AD33: ='[6]fib Model Code 2010'!$L$10 -> 0.37251976 | AE33: =AD33/J33 -> 1.1641242 | AF33: =LN(AE33) -> 0.15196907 | AG33: ='[6]fib Model Code 2020'!$L$10 -> 0.31719821 | AH33: =AG33/J33 -> 0.99124441 | AI33: =LN(AH33) -> -0.008794149 | AJ33: ='[6]Eurocode 2'!$L$10 -> 0.32483496 | AK33: =AJ33/J33 -> 1.0151092 | AL33: =LN(AK33) -> 0.014996238 | AM33: ='[6]NBR 6118'!$Q$10 -> 0.322344 | AN33: ='[6]NBR 6118'!$R$10 -> 0.40956754 | AO33: ='[6]NBR 6118'!$W$10 -> 1.007325 | AP33: =LN(AO33) -> 0.0072982911 | AQ33: ='[6]Clark (1956)'!$L$10 -> 0.2654063 | AR33: =AQ33/J33 -> 0.82939468 | AS33: =LN(AR33) -> -0.18705915 | AT33: ='[6]Leonhardt (1977)'!$L$10 -> 0.46249134 | AU33: =AT33/J33 -> 1.4452854 | AV33: =LN(AU33) -> 0.36830683 | AW33: ='[6]Desayi; Ganesan (1985)'!$L$10 -> 0.29529431 | AX33: =AW33/J33 -> 0.92279471 | AY33: =LN(AX33) -> -0.080348483 | AZ33: ='[6]Oh; Kang (1987)'!$L$10 -> 0.20809703 | BA33: =AZ33/J33 -> 0.65030323 | BB33: =LN(BA33) -> -0.43031652 | BC33: ='[6]Caldas (1997)'!$L$10 -> 0.39815965 | BD33: =BC33/J33 -> 1.2442489 | BE33: =LN(BD33) -> 0.21853207 | BF33: 0.29869497 | BG33: =BF33/J33 -> 0.93342179 | BH33: =LN(BG33) -> -0.068898097 | BI33: 0.41698801 | BJ33: =BI33/J33 -> 1.3030875 | BK33: =LN(BJ33) -> 0.26473648 | BL33: 0.39121503 | BM33: =BL33/J33 -> 1.222547 | BN33: =LN(BM33) -> 0.20093636 | BS33: =IF(AND(B33<=12.7,F33<=45),TRUE,FALSE) -> TRUE | BU33: =IF(AND(B33>12.7,F33<=45),TRUE,FALSE) -> FALSE | BW33: =IF(AND(F33<=45,C33>1),TRUE,FALSE) -> TRUE
B34: ='[6]Dados de entrada'!$B$28 -> 10 | C34: ='[6]Dados de entrada'!$B$31 -> 4 | D34: ='[6]Leonhardt (1977)'!$B$27 -> 32.466667 | E34: ='[6]Dados de entrada'!$B$27 -> 3.262 | F34: ='[6]Dados de entrada'!$B$30 -> 25 | G34: ='[6]Dados de entrada'!$B$22 -> 36 | H34: ='[6]Dados de entrada'!$B$29/('[6]Dados de entrada'!$B$20*2*G34) -> 0.021805556 | I34: ='[6]fib Model Code 2010'!$K$11 -> 502.76188 | J34: ='[6]Dados de entrada'!$C$13 -> 0.38 | AD34: ='[6]fib Model Code 2010'!$L$11 -> 0.37699236 | AE34: =AD34/J34 -> 0.99208516 | AF34: =LN(AE34) -> -0.0079463245 | AG34: ='[6]fib Model Code 2020'!$L$11 -> 0.32095648 | AH34: =AG34/J34 -> 0.84462232 | AI34: =LN(AH34) -> -0.16886571 | AJ34: ='[6]Eurocode 2'!$L$11 -> 0.32873504 | AK34: =AJ34/J34 -> 0.86509222 | AL34: =LN(AK34) -> -0.14491916 | AM34: ='[6]NBR 6118'!$Q$11 -> 0.325248 | AN34: ='[6]NBR 6118'!$R$11 -> 0.41698038 | AO34: ='[6]NBR 6118'!$W$11 -> 0.85591578 | AP34: =LN(AO34) -> -0.1555833 | AQ34: ='[6]Clark (1956)'!$L$11 -> 0.26876185 | AR34: =AQ34/J34 -> 0.70726804 | AS34: =LN(AR34) -> -0.34634556 | AT34: ='[6]Leonhardt (1977)'!$L$11 -> 0.46730491 | AU34: =AT34/J34 -> 1.2297498 | AV34: =LN(AU34) -> 0.20681071 | AW34: ='[6]Desayi; Ganesan (1985)'!$L$11 -> 0.29795462 | AX34: =AW34/J34 -> 0.7840911 | AY34: =LN(AX34) -> -0.24323007 | AZ34: ='[6]Oh; Kang (1987)'!$L$11 -> 0.21014435 | BA34: =AZ34/J34 -> 0.55301145 | BB34: =LN(BA34) -> -0.59237656 | BC34: ='[6]Caldas (1997)'!$L$11 -> 0.40208384 | BD34: =BC34/J34 -> 1.0581154 | BE34: =LN(BD34) -> 0.056489364 | BF34: 0.30138592 | BG34: =BF34/J34 -> 0.79312084 | BH34: =LN(BG34) -> -0.23177968 | BI34: 0.42092646 | BJ34: =BI34/J34 -> 1.1077012 | BK34: =LN(BJ34) -> 0.10228689 | BL34: 0.3959705 | BM34: =BL34/J34 -> 1.0420276 | BN34: =LN(BM34) -> 0.041168453 | BS34: =IF(AND(B34<=12.7,F34<=45),TRUE,FALSE) -> TRUE | BU34: =IF(AND(B34>12.7,F34<=45),TRUE,FALSE) -> FALSE | BW34: =IF(AND(F34<=45,C34>1),TRUE,FALSE) -> TRUE
B35: ='[6]Dados de entrada'!$B$28 -> 10 | C35: ='[6]Dados de entrada'!$B$31 -> 4 | D35: ='[6]Leonhardt (1977)'!$B$27 -> 32.466667 | E35: ='[6]Dados de entrada'!$B$27 -> 3.262 | F35: ='[6]Dados de entrada'!$B$30 -> 25 | G35: ='[6]Dados de entrada'!$B$22 -> 36 | H35: ='[6]Dados de entrada'!$B$29/('[6]Dados de entrada'!$B$20*2*G35) -> 0.021805556 | I35: ='[6]fib Model Code 2010'!$K$12 -> 538.67345 | J35: ='[6]Dados de entrada'!$C$14 -> 0.42 | AD35: ='[6]fib Model Code 2010'!$L$12 -> 0.41277322 | AE35: =AD35/J35 -> 0.98279338 | AF35: =LN(AE35) -> -0.017356375 | AG35: ='[6]fib Model Code 2020'!$L$12 -> 0.35102266 | AH35: =AG35/J35 -> 0.83576823 | AI35: =LN(AH35) -> -0.17940394 | AJ35: ='[6]Eurocode 2'!$L$12 -> 0.35993573 | AK35: =AJ35/J35 -> 0.85698984 | AL35: =LN(AK35) -> -0.15432921 | AM35: ='[6]NBR 6118'!$Q$12 -> 0.34848 | AN35: ='[6]NBR 6118'!$R$12 -> 0.47867645 | AO35: ='[6]NBR 6118'!$W$12 -> 0.82971428 | AP35: =LN(AO35) -> -0.18667388 | AQ35: ='[6]Clark (1956)'!$L$12 -> 0.29560632 | AR35: =AQ35/J35 -> 0.70382457 | AS35: =LN(AR35) -> -0.35122614 | AT35: ='[6]Leonhardt (1977)'!$L$12 -> 0.50562031 | AU35: =AT35/J35 -> 1.2038579 | AV35: =LN(AU35) -> 0.18553129 | AW35: ='[6]Desayi; Ganesan (1985)'!$L$12 -> 0.31923709 | AX35: =AW35/J35 -> 0.76008831 | AY35: =LN(AX35) -> -0.27432066 | AZ35: ='[6]Oh; Kang (1987)'!$L$12 -> 0.2265229 | BA35: =AZ35/J35 -> 0.53934025 | BB35: =LN(BA35) -> -0.61740865 | BC35: ='[6]Caldas (1997)'!$L$12 -> 0.4334773 | BD35: =BC35/J35 -> 1.0320888 | BE35: =LN(BD35) -> 0.031584712 | BF35: 0.32291349 | BG35: =BF35/J35 -> 0.76884163 | BH35: =LN(BG35) -> -0.26287027 | BI35: 0.45099264 | BJ35: =BI35/J35 -> 1.073792 | BK35: =LN(BJ35) -> 0.071196308 | BL35: 0.43422661 | BM35: =BL35/J35 -> 1.0338729 | BN35: =LN(BM35) -> 0.033311825 | BS35: =IF(AND(B35<=12.7,F35<=45),TRUE,FALSE) -> TRUE | BU35: =IF(AND(B35>12.7,F35<=45),TRUE,FALSE) -> FALSE | BW35: =IF(AND(F35<=45,C35>1),TRUE,FALSE) -> TRUE
B36: ='[6]Dados de entrada'!$B$28 -> 10 | C36: ='[6]Dados de entrada'!$B$31 -> 4 | D36: ='[6]Leonhardt (1977)'!$B$27 -> 32.466667 | E36: ='[6]Dados de entrada'!$B$27 -> 3.262 | F36: ='[6]Dados de entrada'!$B$30 -> 25 | G36: ='[6]Dados de entrada'!$B$22 -> 36 | H36: ='[6]Dados de entrada'!$B$29/('[6]Dados de entrada'!$B$20*2*G36) -> 0.021805556 | I36: ='[6]fib Model Code 2010'!$K$13 -> 628 | J36: ='[6]Dados de entrada'!$C$15 -> 0.44 | AD36: ='[6]fib Model Code 2010'!$L$13 -> 0.50177465 | AE36: =AD36/J36 -> 1.1403969 | AF36: =LN(AE36) -> 0.13137639 | AG36: ='[6]fib Model Code 2020'!$L$13 -> 0.42580937 | AH36: =AG36/J36 -> 0.96774858 | AI36: =LN(AH36) -> -0.03278296 | AJ36: ='[6]Eurocode 2'!$L$13 -> 0.43754444 | AK36: =AJ36/J36 -> 0.99441919 | AL36: =LN(AK36) -> -0.0055964433 | AM36: ='[6]NBR 6118'!$Q$13 -> 0.39471097 | AN36: ='[6]NBR 6118'!$R$13 -> 0.61410801 | AO36: ='[6]NBR 6118'!$W$13 -> 0.8970704 | AP36: =LN(AO36) -> -0.10862094 | AQ36: ='[6]Clark (1956)'!$L$13 -> 0.36237934 | AR36: =AQ36/J36 -> 0.82358941 | AS36: =LN(AR36) -> -0.19408316 | AT36: ='[6]Leonhardt (1977)'!$L$13 -> 0.59974401 | AU36: =AT36/J36 -> 1.3630546 | AV36: =LN(AU36) -> 0.30972819 | AW36: ='[6]Desayi; Ganesan (1985)'!$L$13 -> 0.37217519 | AX36: =AW36/J36 -> 0.8458527 | AY36: =LN(AX36) -> -0.16741004 | AZ36: ='[6]Oh; Kang (1987)'!$L$13 -> 0.26726297 | BA36: =AZ36/J36 -> 0.60741585 | BB36: =LN(BA36) -> -0.49854164 | BC36: ='[6]Caldas (1997)'!$L$13 -> 0.5115655 | BD36: =BC36/J36 -> 1.1626489 | BE36: =LN(BD36) -> 0.15070091 | BF36: 0.37646123 | BG36: =BF36/J36 -> 0.85559371 | BH36: =LN(BG36) -> -0.15595966 | BI36: 0.52577936 | BJ36: =BI36/J36 -> 1.1949531 | BK36: =LN(BJ36) -> 0.17810692 | BL36: 0.53102264 | BM36: =BL36/J36 -> 1.2068696 | BN36: =LN(BM36) -> 0.18802993 | BS36: =IF(AND(B36<=12.7,F36<=45),TRUE,FALSE) -> TRUE | BU36: =IF(AND(B36>12.7,F36<=45),TRUE,FALSE) -> FALSE | BW36: =IF(AND(F36<=45,C36>1),TRUE,FALSE) -> TRUE
