Workbook

Sheet Com TS variável MC2010
P1: Opção 3 de equação | S1: Opção 4 de equação
P2: A1 | Q2: 1.728 | S2: A1 | T2: 0.392
P3: A2 | Q3: 0.011 | S3: A2 | T3: 1.148
P4: A3 | Q4: 0.339 | S4: A3 | T4: 0.854
P5: A4 | Q5: 1.102 | S5: A4 | T5: 0.555
P6: A5 | Q6: -0.495 | S6: A5 | T6: -0.686
P7: A6 | Q7: 0.838 | S7: A6 | T7: 1.952
A9: Autor | B9: Inputs | K9: Output
B10: Diâmetro da armadura (mm) | C10: Resistência do aço - fy (MPa) | D10: Número de barras em uma camada | E10: Espaçamento entre as barras (mm) | F10: Resistência à tração do concreto (MPa) | G10: Cobrimento (mm) | H10: Distância ao centro de gravidade da armadura (mm) | I10: Taxa de armadura | J10: Tensão na armadura menos tension stiffening (MPa) | K10: w (mm) | L10: Deformação na armadura menos tension stiffening (MPa)
A11: Viga S200-1.76-20 - Sokolov et al (2021) | B11: 20 | C11: 500 | D11: 2 | E11: 126 | F11: 4.1203405 | G11: 25 | H11: 39 | I11: 0.060723546 | J11: 185.31436 | K11: 0.16 | L11: =J11/200000 -> 0.00092657181 | P11: =$Q$2*($Q$3*$G11+$Q$4*$B11^$Q$5*$I11^$Q$6)*$L11^$Q$7 -> 0.18415873 | Q11: =P11/$K11 -> 1.1509921 | S11: =$T$2*$B11^$T$3*$L11^$T$4*($T$5*$I11^$T$6+$T$7) -> 0.18022921 | T11: =S11/$K11 -> 1.1264326
B12: 20 | C12: 500 | D12: 2 | E12: 126 | F12: 4.1203405 | G12: 25 | H12: 39 | I12: 0.060723546 | J12: 270.65736 | K12: 0.23 | L12: =J12/200000 -> 0.0013532868 | P12: =$Q$2*($Q$3*$G12+$Q$4*$B12^$Q$5*$I12^$Q$6)*$L12^$Q$7 -> 0.25296029 | Q12: =P12/$K12 -> 1.0998273 | S12: =$T$2*$B12^$T$3*$L12^$T$4*($T$5*$I12^$T$6+$T$7) -> 0.24906768 | T12: =S12/$K12 -> 1.082903
B13: 20 | C13: 500 | D13: 2 | E13: 126 | F13: 4.1203405 | G13: 25 | H13: 39 | I13: 0.060723546 | J13: 284.1029 | K13: 0.24 | L13: =J13/200000 -> 0.0014205145 | P13: =$Q$2*($Q$3*$G13+$Q$4*$B13^$Q$5*$I13^$Q$6)*$L13^$Q$7 -> 0.26344934 | Q13: =P13/$K13 -> 1.0977056 | S13: =$T$2*$B13^$T$3*$L13^$T$4*($T$5*$I13^$T$6+$T$7) -> 0.25959663 | T13: =S13/$K13 -> 1.0816526
B14: 20 | C14: 500 | D14: 2 | E14: 126 | F14: 4.1203405 | G14: 25 | H14: 39 | I14: 0.060723546 | J14: 347.37006 | K14: 0.27 | L14: =J14/200000 -> 0.0017368503 | P14: =$Q$2*($Q$3*$G14+$Q$4*$B14^$Q$5*$I14^$Q$6)*$L14^$Q$7 -> 0.31179456 | Q14: =P14/$K14 -> 1.1547947 | S14: =$T$2*$B14^$T$3*$L14^$T$4*($T$5*$I14^$T$6+$T$7) -> 0.30822476 | T14: =S14/$K14 -> 1.1415732
B15: 20 | C15: 500 | D15: 2 | E15: 126 | F15: 4.1203405 | G15: 25 | H15: 39 | I15: 0.060723546 | J15: 454.40943 | K15: 0.35 | L15: =J15/200000 -> 0.0022720472 | P15: =$Q$2*($Q$3*$G15+$Q$4*$B15^$Q$5*$I15^$Q$6)*$L15^$Q$7 -> 0.3905039 | Q15: =P15/$K15 -> 1.1157254 | S15: =$T$2*$B15^$T$3*$L15^$T$4*($T$5*$I15^$T$6+$T$7) -> 0.38769558 | T15: =S15/$K15 -> 1.1077017
B16: 20 | C16: 500 | D16: 2 | E16: 126 | F16: 4.1203405 | G16: 25 | H16: 39 | I16: 0.060723546 | J16: 500 | K16: 0.4 | L16: =J16/200000 -> 0.0025 | P16: =$Q$2*($Q$3*$G16+$Q$4*$B16^$Q$5*$I16^$Q$6)*$L16^$Q$7 -> 0.42307891 | Q16: =P16/$K16 -> 1.0576973 | S16: =$T$2*$B16^$T$3*$L16^$T$4*($T$5*$I16^$T$6+$T$7) -> 0.42067936 | T16: =S16/$K16 -> 1.0516984
A17: Viga S600-0.37-10 - Sokolov et al (2021) | B17: 10 | C17: 500 | D17: 8 | E17: 87.7 | F17: 4.1311268 | G17: 25 | H17: 53 | I17: 0.015388385 | J17: 230.46115 | K17: 0.16 | L17: =J17/200000 -> 0.0011523057 | P17: =$Q$2*($Q$3*$G17+$Q$4*$B17^$Q$5*$I17^$Q$6)*$L17^$Q$7 -> 0.203325 | Q17: =P17/$K17 -> 1.2707812 | S17: =$T$2*$B17^$T$3*$L17^$T$4*($T$5*$I17^$T$6+$T$7) -> 0.19915306 | T17: =S17/$K17 -> 1.2447066
B18: 10 | C18: 500 | D18: 8 | E18: 87.7 | F18: 4.1311268 | G18: 25 | H18: 53 | I18: 0.015388385 | J18: 305.35368 | K18: 0.18 | L18: =J18/200000 -> 0.0015267684 | P18: =$Q$2*($Q$3*$G18+$Q$4*$B18^$Q$5*$I18^$Q$6)*$L18^$Q$7 -> 0.25739431 | Q18: =P18/$K18 -> 1.4299684 | S18: =$T$2*$B18^$T$3*$L18^$T$4*($T$5*$I18^$T$6+$T$7) -> 0.25325056 | T18: =S18/$K18 -> 1.4069476
B19: 10 | C19: 500 | D19: 8 | E19: 87.7 | F19: 4.1311268 | G19: 25 | H19: 53 | I19: 0.015388385 | J19: 497.51538 | K19: 0.26 | L19: =J19/200000 -> 0.0024875769 | P19: =$Q$2*($Q$3*$G19+$Q$4*$B19^$Q$5*$I19^$Q$6)*$L19^$Q$7 -> 0.38748754 | Q19: =P19/$K19 -> 1.4903367 | S19: =$T$2*$B19^$T$3*$L19^$T$4*($T$5*$I19^$T$6+$T$7) -> 0.38423886 | T19: =S19/$K19 -> 1.4778418
A20: Viga V1 - Oliveira (2007) | B20: 10 | C20: 628 | D20: 4 | E20: 32.466667 | F20: 3.262 | G20: 25 | H20: 36 | I20: 0.017444444 | J20: 173.6503 | K20: 0.16 | L20: =J20/200000 -> 0.00086825151 | P20: =$Q$2*($Q$3*$G20+$Q$4*$B20^$Q$5*$I20^$Q$6)*$L20^$Q$7 -> 0.15081563 | Q20: =P20/$K20 -> 0.9425977 | S20: =$T$2*$B20^$T$3*$L20^$T$4*($T$5*$I20^$T$6+$T$7) -> 0.14565419 | T20: =S20/$K20 -> 0.91033866
B21: 10 | C21: 628 | D21: 4 | E21: 32.466667 | F21: 3.262 | G21: 25 | H21: 36 | I21: 0.017444444 | J21: 238.73913 | K21: 0.2 | L21: =J21/200000 -> 0.0011936956 | P21: =$Q$2*($Q$3*$G21+$Q$4*$B21^$Q$5*$I21^$Q$6)*$L21^$Q$7 -> 0.19692381 | Q21: =P21/$K21 -> 0.98461906 | S21: =$T$2*$B21^$T$3*$L21^$T$4*($T$5*$I21^$T$6+$T$7) -> 0.19115551 | T21: =S21/$K21 -> 0.95577754
B22: 10 | C22: 628 | D22: 4 | E22: 32.466667 | F22: 3.262 | G22: 25 | H22: 36 | I22: 0.017444444 | J22: 305.6485 | K22: 0.2 | L22: =J22/200000 -> 0.0015282425 | P22: =$Q$2*($Q$3*$G22+$Q$4*$B22^$Q$5*$I22^$Q$6)*$L22^$Q$7 -> 0.24222252 | Q22: =P22/$K22 -> 1.2111126 | S22: =$T$2*$B22^$T$3*$L22^$T$4*($T$5*$I22^$T$6+$T$7) -> 0.23605863 | T22: =S22/$K22 -> 1.1802931
B23: 10 | C23: 628 | D23: 4 | E23: 32.466667 | F23: 3.262 | G23: 25 | H23: 36 | I23: 0.017444444 | J23: 366.5479 | K23: 0.24 | L23: =J23/200000 -> 0.0018327395 | P23: =$Q$2*($Q$3*$G23+$Q$4*$B23^$Q$5*$I23^$Q$6)*$L23^$Q$7 -> 0.2820589 | Q23: =P23/$K23 -> 1.1752454 | S23: =$T$2*$B23^$T$3*$L23^$T$4*($T$5*$I23^$T$6+$T$7) -> 0.27568155 | T23: =S23/$K23 -> 1.1486731
B24: 10 | C24: 628 | D24: 4 | E24: 32.466667 | F24: 3.262 | G24: 25 | H24: 36 | I24: 0.017444444 | J24: 399.44172 | K24: 0.3 | L24: =J24/200000 -> 0.0019972086 | P24: =$Q$2*($Q$3*$G24+$Q$4*$B24^$Q$5*$I24^$Q$6)*$L24^$Q$7 -> 0.30312114 | Q24: =P24/$K24 -> 1.0104038 | S24: =$T$2*$B24^$T$3*$L24^$T$4*($T$5*$I24^$T$6+$T$7) -> 0.29667522 | T24: =S24/$K24 -> 0.98891741
B25: 10 | C25: 628 | D25: 4 | E25: 32.466667 | F25: 3.262 | G25: 25 | H25: 36 | I25: 0.017444444 | J25: 498.04874 | K25: 0.32 | L25: =J25/200000 -> 0.0024902437 | P25: =$Q$2*($Q$3*$G25+$Q$4*$B25^$Q$5*$I25^$Q$6)*$L25^$Q$7 -> 0.3646801 | Q25: =P25/$K25 -> 1.1396253 | S25: =$T$2*$B25^$T$3*$L25^$T$4*($T$5*$I25^$T$6+$T$7) -> 0.35818733 | T25: =S25/$K25 -> 1.1193354
B26: 10 | C26: 628 | D26: 4 | E26: 32.466667 | F26: 3.262 | G26: 25 | H26: 36 | I26: 0.017444444 | J26: 502.76188 | K26: 0.38 | L26: =J26/200000 -> 0.0025138094 | P26: =$Q$2*($Q$3*$G26+$Q$4*$B26^$Q$5*$I26^$Q$6)*$L26^$Q$7 -> 0.36756986 | Q26: =P26/$K26 -> 0.96728912 | S26: =$T$2*$B26^$T$3*$L26^$T$4*($T$5*$I26^$T$6+$T$7) -> 0.36108005 | T26: =S26/$K26 -> 0.95021067
B27: 10 | C27: 628 | D27: 4 | E27: 32.466667 | F27: 3.262 | G27: 25 | H27: 36 | I27: 0.017444444 | J27: 538.67345 | K27: 0.42 | L27: =J27/200000 -> 0.0026933672 | P27: =$Q$2*($Q$3*$G27+$Q$4*$B27^$Q$5*$I27^$Q$6)*$L27^$Q$7 -> 0.38944764 | Q27: =P27/$K27 -> 0.92725629 | S27: =$T$2*$B27^$T$3*$L27^$T$4*($T$5*$I27^$T$6+$T$7) -> 0.38299411 | T27: =S27/$K27 -> 0.91189073
B28: 10 | C28: 628 | D28: 4 | E28: 32.466667 | F28: 3.262 | G28: 25 | H28: 36 | I28: 0.017444444 | J28: 628 | K28: 0.44 | L28: =J28/200000 -> 0.00314 | P28: =$Q$2*($Q$3*$G28+$Q$4*$B28^$Q$5*$I28^$Q$6)*$L28^$Q$7 -> 0.44288241 | Q28: =P28/$K28 -> 1.0065509 | S28: =$T$2*$B28^$T$3*$L28^$T$4*($T$5*$I28^$T$6+$T$7) -> 0.43661394 | T28: =S28/$K28 -> 0.9923044
B29: 10 | C29: 628 | D29: 4 | E29: 32.466667 | F29: 3.262 | G29: 25 | H29: 36 | I29: 0.017444444 | J29: 628 | K29: 0.5 | L29: =J29/200000 -> 0.00314 | P29: =$Q$2*($Q$3*$G29+$Q$4*$B29^$Q$5*$I29^$Q$6)*$L29^$Q$7 -> 0.44288241 | Q29: =P29/$K29 -> 0.88576483 | S29: =$T$2*$B29^$T$3*$L29^$T$4*($T$5*$I29^$T$6+$T$7) -> 0.43661394 | T29: =S29/$K29 -> 0.87322787
A30: Viga V2 - Oliveira (2007) | B30: 10 | C30: 628 | D30: 4 | E30: 32.466667 | F30: 3.514 | G30: 25 | H30: 36 | I30: 0.017444444 | J30: 246.62969 | K30: 0.24 | L30: =J30/200000 -> 0.0012331485 | P30: =$Q$2*($Q$3*$G30+$Q$4*$B30^$Q$5*$I30^$Q$6)*$L30^$Q$7 -> 0.20236354 | Q30: =P30/$K30 -> 0.84318141 | S30: =$T$2*$B30^$T$3*$L30^$T$4*($T$5*$I30^$T$6+$T$7) -> 0.19653812 | T30: =S30/$K30 -> 0.81890883
B31: 10 | C31: 628 | D31: 4 | E31: 32.466667 | F31: 3.514 | G31: 25 | H31: 36 | I31: 0.017444444 | J31: 335.69608 | K31: 0.3 | L31: =J31/200000 -> 0.0016784804 | P31: =$Q$2*($Q$3*$G31+$Q$4*$B31^$Q$5*$I31^$Q$6)*$L31^$Q$7 -> 0.26202409 | Q31: =P31/$K31 -> 0.87341364 | S31: =$T$2*$B31^$T$3*$L31^$T$4*($T$5*$I31^$T$6+$T$7) -> 0.25573971 | T31: =S31/$K31 -> 0.8524657
B32: 10 | C32: 628 | D32: 4 | E32: 32.466667 | F32: 3.514 | G32: 25 | H32: 36 | I32: 0.017444444 | J32: 361.50872 | K32: 0.3 | L32: =J32/200000 -> 0.0018075436 | P32: =$Q$2*($Q$3*$G32+$Q$4*$B32^$Q$5*$I32^$Q$6)*$L32^$Q$7 -> 0.27880579 | Q32: =P32/$K32 -> 0.92935263 | S32: =$T$2*$B32^$T$3*$L32^$T$4*($T$5*$I32^$T$6+$T$7) -> 0.27244164 | T32: =S32/$K32 -> 0.90813881
B33: 10 | C33: 628 | D33: 4 | E33: 32.466667 | F33: 3.514 | G33: 25 | H33: 36 | I33: 0.017444444 | J33: 392.91007 | K33: 0.3 | L33: =J33/200000 -> 0.0019645504 | P33: =$Q$2*($Q$3*$G33+$Q$4*$B33^$Q$5*$I33^$Q$6)*$L33^$Q$7 -> 0.29896195 | Q33: =P33/$K33 -> 0.99653985 | S33: =$T$2*$B33^$T$3*$L33^$T$4*($T$5*$I33^$T$6+$T$7) -> 0.29252731 | T33: =S33/$K33 -> 0.97509103
B34: 10 | C34: 628 | D34: 4 | E34: 32.466667 | F34: 3.514 | G34: 25 | H34: 36 | I34: 0.017444444 | J34: 424.16428 | K34: 0.38 | L34: =J34/200000 -> 0.0021208214 | P34: =$Q$2*($Q$3*$G34+$Q$4*$B34^$Q$5*$I34^$Q$6)*$L34^$Q$7 -> 0.31876588 | Q34: =P34/$K34 -> 0.83885757 | S34: =$T$2*$B34^$T$3*$L34^$T$4*($T$5*$I34^$T$6+$T$7) -> 0.31228719 | T34: =S34/$K34 -> 0.8218084
B35: 10 | C35: 628 | D35: 4 | E35: 32.466667 | F35: 3.514 | G35: 25 | H35: 36 | I35: 0.017444444 | J35: 491.13759 | K35: 0.44 | L35: =J35/200000 -> 0.0024556879 | P35: =$Q$2*($Q$3*$G35+$Q$4*$B35^$Q$5*$I35^$Q$6)*$L35^$Q$7 -> 0.36043463 | Q35: =P35/$K35 -> 0.81916962 | S35: =$T$2*$B35^$T$3*$L35^$T$4*($T$5*$I35^$T$6+$T$7) -> 0.35393831 | T35: =S35/$K35 -> 0.80440524
A36: Viga T1F000 - Silva Neto (2017) | B36: 16 | C36: 571 | D36: 4 | E36: 37 | F36: 4.2588 | G36: 33 | H36: 59 | I36: 0.1168 | J36: 104.26922 | K36: 0.18 | L36: =J36/200000 -> 0.00052134608 | P36: =$Q$2*($Q$3*$G36+$Q$4*$B36^$Q$5*$I36^$Q$6)*$L36^$Q$7 -> 0.064976028 | Q36: =P36/$K36 -> 0.36097793 | S36: =$T$2*$B36^$T$3*$L36^$T$4*($T$5*$I36^$T$6+$T$7) -> 0.06498886 | T36: =S36/$K36 -> 0.36104922
B37: 16 | C37: 571 | D37: 4 | E37: 37 | F37: 4.2588 | G37: 33 | H37: 59 | I37: 0.1168 | J37: 166.90492 | K37: 0.2 | L37: =J37/200000 -> 0.00083452461 | P37: =$Q$2*($Q$3*$G37+$Q$4*$B37^$Q$5*$I37^$Q$6)*$L37^$Q$7 -> 0.096375687 | Q37: =P37/$K37 -> 0.48187844 | S37: =$T$2*$B37^$T$3*$L37^$T$4*($T$5*$I37^$T$6+$T$7) -> 0.097123038 | T37: =S37/$K37 -> 0.48561519
B38: 16 | C38: 571 | D38: 4 | E38: 37 | F38: 4.2588 | G38: 33 | H38: 59 | I38: 0.1168 | J38: 214.45813 | K38: 0.26 | L38: =J38/200000 -> 0.0010722906 | P38: =$Q$2*($Q$3*$G38+$Q$4*$B38^$Q$5*$I38^$Q$6)*$L38^$Q$7 -> 0.11890589 | Q38: =P38/$K38 -> 0.45733034 | S38: =$T$2*$B38^$T$3*$L38^$T$4*($T$5*$I38^$T$6+$T$7) -> 0.12030955 | T38: =S38/$K38 -> 0.46272905
B39: 16 | C39: 571 | D39: 4 | E39: 37 | F39: 4.2588 | G39: 33 | H39: 59 | I39: 0.1168 | J39: 293.13707 | K39: 0.44 | L39: =J39/200000 -> 0.0014656853 | P39: =$Q$2*($Q$3*$G39+$Q$4*$B39^$Q$5*$I39^$Q$6)*$L39^$Q$7 -> 0.15450538 | Q39: =P39/$K39 -> 0.3511486 | S39: =$T$2*$B39^$T$3*$L39^$T$4*($T$5*$I39^$T$6+$T$7) -> 0.15711296 | T39: =S39/$K39 -> 0.35707491
B40: 16 | C40: 571 | D40: 4 | E40: 37 | F40: 4.2588 | G40: 33 | H40: 59 | I40: 0.1168 | J40: 408.12936 | K40: 0.6 | L40: =J40/200000 -> 0.0020406468 | P40: =$Q$2*($Q$3*$G40+$Q$4*$B40^$Q$5*$I40^$Q$6)*$L40^$Q$7 -> 0.20388578 | Q40: =P40/$K40 -> 0.33980963 | S40: =$T$2*$B40^$T$3*$L40^$T$4*($T$5*$I40^$T$6+$T$7) -> 0.20842747 | T40: =S40/$K40 -> 0.34737912
A41: Viga 12-20-00 - Caldentey et al (2013) | B41: 12 | C41: 500 | D41: 4 | E41: 79.3 | F41: 2.6933292 | G41: 20 | H41: 38 | I41: 0.013593985 | J41: 220.98185 | K41: 0.36 | L41: =J41/200000 -> 0.0011049092 | P41: =$Q$2*($Q$3*$G41+$Q$4*$B41^$Q$5*$I41^$Q$6)*$L41^$Q$7 -> 0.2543714 | Q41: =P41/$K41 -> 0.70658721 | S41: =$T$2*$B41^$T$3*$L41^$T$4*($T$5*$I41^$T$6+$T$7) -> 0.25438251 | T41: =S41/$K41 -> 0.7066181
...

Sheet Sem TS MC2010
A1: Autor | B1: Inputs | K1: Output
B2: Diâmetro da armadura f (mm) | C2: Resistência do aço - fy (MPa) | D2: Número de barras em uma camada | E2: Espaçamento entre as barras (mm) | F2: Resistência à tração do concreto fctm (MPa) | G2: Cobrimento c (mm) | H2: Distância ao centro de gravidade da armadura d' (mm) | I2: Taxa de armadura r | J2: Tensão na armadura (MPa) | K2: wexp (mm)
A3: Viga S200-1.76-20 - Sokolov et al (2021) | B3: 20 | C3: 500 | D3: 2 | E3: 126 | F3: 4.1203405 | G3: 25 | H3: 39 | I3: 0.060723546 | J3: 231.811 | K3: 0.16
B4: 20 | C4: 500 | D4: 2 | E4: 126 | F4: 4.1203405 | G4: 25 | H4: 39 | I4: 0.060723546 | J4: 304.25194 | K4: 0.23
B5: 20 | C5: 500 | D5: 2 | E5: 126 | F5: 4.1203405 | G5: 25 | H5: 39 | I5: 0.060723546 | J5: 314.28223 | K5: 0.24
B6: 20 | C6: 500 | D6: 2 | E6: 126 | F6: 4.1203405 | G6: 25 | H6: 39 | I6: 0.060723546 | J6: 363.31917 | K6: 0.27
B7: 20 | C7: 500 | D7: 2 | E7: 126 | F7: 4.1203405 | G7: 25 | H7: 39 | I7: 0.060723546 | J7: 459.16411 | K7: 0.35
B8: 20 | C8: 500 | D8: 2 | E8: 126 | F8: 4.1203405 | G8: 25 | H8: 39 | I8: 0.060723546 | J8: 500 | K8: 0.4
A9: Viga S600-0.37-10 - Sokolov et al (2021) | B9: 10 | C9: 500 | D9: 8 | E9: 87.7 | F9: 4.1311268 | G9: 25 | H9: 53 | I9: 0.015388385 | J9: 322.91972 | K9: 0.16
B10: 10 | C10: 500 | D10: 8 | E10: 87.7 | F10: 4.1311268 | G10: 25 | H10: 53 | I10: 0.015388385 | J10: 367.82093 | K10: 0.18
B11: 10 | C11: 500 | D11: 8 | E11: 87.7 | F11: 4.1311268 | G11: 25 | H11: 53 | I11: 0.015388385 | J11: 500 | K11: 0.26
A12: Viga V1 - Oliveira (2007) | B12: 10 | C12: 628 | D12: 4 | E12: 32.466667 | F12: 3.262 | G12: 25 | H12: 36 | I12: 0.017444444 | J12: 285.04803 | K12: 0.16
B13: 10 | C13: 628 | D13: 4 | E13: 32.466667 | F13: 3.262 | G13: 25 | H13: 36 | I13: 0.017444444 | J13: 324.99965 | K13: 0.2
B14: 10 | C14: 628 | D14: 4 | E14: 32.466667 | F14: 3.262 | G14: 25 | H14: 36 | I14: 0.017444444 | J14: 367.64463 | K14: 0.2
B15: 10 | C15: 628 | D15: 4 | E15: 32.466667 | F15: 3.262 | G15: 25 | H15: 36 | I15: 0.017444444 | J15: 410.7385 | K15: 0.24
B16: 10 | C16: 628 | D16: 4 | E16: 32.466667 | F16: 3.262 | G16: 25 | H16: 36 | I16: 0.017444444 | J16: 438.56996 | K16: 0.3
B17: 10 | C17: 628 | D17: 4 | E17: 32.466667 | F17: 3.262 | G17: 25 | H17: 36 | I17: 0.017444444 | J17: 498.27294 | K17: 0.32
B18: 10 | C18: 628 | D18: 4 | E18: 32.466667 | F18: 3.262 | G18: 25 | H18: 36 | I18: 0.017444444 | J18: 502.76188 | K18: 0.38
B19: 10 | C19: 628 | D19: 4 | E19: 32.466667 | F19: 3.262 | G19: 25 | H19: 36 | I19: 0.017444444 | J19: 538.67345 | K19: 0.42
B20: 10 | C20: 628 | D20: 4 | E20: 32.466667 | F20: 3.262 | G20: 25 | H20: 36 | I20: 0.017444444 | J20: 628 | K20: 0.44
B21: 10 | C21: 628 | D21: 4 | E21: 32.466667 | F21: 3.262 | G21: 25 | H21: 36 | I21: 0.017444444 | J21: 628 | K21: 0.5
A22: Viga V2 - Oliveira (2007) | B22: 10 | C22: 628 | D22: 4 | E22: 32.466667 | F22: 3.514 | G22: 25 | H22: 36 | I22: 0.017444444 | J22: 321.47188 | K22: 0.24
B23: 10 | C23: 628 | D23: 4 | E23: 32.466667 | F23: 3.514 | G23: 25 | H23: 36 | I23: 0.017444444 | J23: 357.19097 | K23: 0.3
B24: 10 | C24: 628 | D24: 4 | E24: 32.466667 | F24: 3.514 | G24: 25 | H24: 36 | I24: 0.017444444 | J24: 370.58564 | K24: 0.3
B25: 10 | C25: 628 | D25: 4 | E25: 32.466667 | F25: 3.514 | G25: 25 | H25: 36 | I25: 0.017444444 | J25: 392.91007 | K25: 0.3
B26: 10 | C26: 628 | D26: 4 | E26: 32.466667 | F26: 3.514 | G26: 25 | H26: 36 | I26: 0.017444444 | J26: 424.16428 | K26: 0.38
B27: 10 | C27: 628 | D27: 4 | E27: 32.466667 | F27: 3.514 | G27: 25 | H27: 36 | I27: 0.017444444 | J27: 491.13759 | K27: 0.44
A28: Viga T1F000 - Silva Neto (2017) | B28: 16 | C28: 571 | D28: 4 | E28: 37 | F28: 4.2588 | G28: 33 | H28: 59 | I28: 0.1168 | J28: 140.04197 | K28: 0.18
B29: 16 | C29: 571 | D29: 4 | E29: 37 | F29: 4.2588 | G29: 33 | H29: 59 | I29: 0.1168 | J29: 201.59887 | K29: 0.2
B30: 16 | C30: 571 | D30: 4 | E30: 37 | F30: 4.2588 | G30: 33 | H30: 59 | I30: 0.1168 | J30: 243.91925 | K30: 0.26
B31: 16 | C31: 571 | D31: 4 | E31: 37 | F31: 4.2588 | G31: 33 | H31: 59 | I31: 0.1168 | J31: 313.94023 | K31: 0.44
B32: 16 | C32: 571 | D32: 4 | E32: 37 | F32: 4.2588 | G32: 33 | H32: 59 | I32: 0.1168 | J32: 416.27859 | K32: 0.6
A33: Viga 12-20-00 - Caldentey et al (2013) | B33: 12 | C33: 500 | D33: 4 | E33: 79.3 | F33: 2.6933292 | G33: 20 | H33: 38 | I33: 0.013593985 | J33: 300.43296 | K33: 0.36
B34: 12 | C34: 500 | D34: 4 | E34: 79.3 | F34: 2.6933292 | G34: 20 | H34: 38 | I34: 0.013593985 | J34: 386.27094 | K34: 0.43
B35: 12 | C35: 500 | D35: 4 | E35: 79.3 | F35: 2.6933292 | G35: 20 | H35: 38 | I35: 0.013593985 | J35: 500 | K35: 0.56
B36: 12 | C36: 500 | D36: 4 | E36: 79.3 | F36: 2.6933292 | G36: 20 | H36: 38 | I36: 0.013593985 | J36: 500 | K36: 0.71
B37: 12 | C37: 500 | D37: 4 | E37: 79.3 | F37: 2.6933292 | G37: 20 | H37: 38 | I37: 0.013593985 | J37: 500 | K37: 0.79
A38: Viga 25-20-00 - Caldentey et al (2013) | B38: 25 | C38: 500 | D38: 4 | E38: 62 | F38: 2.6933292 | G38: 20 | H38: 44.5 | I38: 0.054467051 | J38: 106.51266 | K38: 0.2
B39: 25 | C39: 500 | D39: 4 | E39: 62 | F39: 2.6933292 | G39: 20 | H39: 44.5 | I39: 0.054467051 | J39: 191.72278 | K39: 0.25
B40: 25 | C40: 500 | D40: 4 | E40: 62 | F40: 2.6933292 | G40: 20 | H40: 44.5 | I40: 0.054467051 | J40: 276.9329 | K40: 0.36
...

Sheet Com TS variável MC2020
W1: Opção 3 de equação | Z1: Opção 4 de equação | AC1: Equações (13) e (15) do artigo Flexural cracking behavior and parametric analysis of steel-UHPC composite decks without longitudinal ribs (sem Tension stiffening). w=A1*(A2+A3*ft/(ro*Sigmas))*eps*(A4*c+A5*fi/ro)*(h-xii)/(h-xii-dl) | AP1: Equações (13) e (15) do artigo Flexural cracking behavior and parametric analysis of steel-UHPC composite decks without longitudinal ribs (sem Tension stiffening) + proposta de correção por fy. w=A1*(A2+A3*ft/(ro*Sigmas))*(A4*c+A5*fi/ro)*(Sigmas**A6/200000)*(h-xii)/(h-xii-dl)+(Sigmas-fy/A7)*(A4*c+A5*fi/ro)/200000
W2: A1 | X2: 0.515 | Z2: A1 | AA2: 0.391 | AC2: A1 | AD2: 1.22 | AP2: A1 | AQ2: 7.37
W3: A2 | X3: -0.00169 | Z3: A2 | AA3: 0.701 | AC3: A2 | AD3: 1.93 | AP3: A2 | AQ3: 4.87
W4: A3 | X4: 1 | Z4: A3 | AA4: 0.628 | AC4: A3 | AD4: -1.05 | AP4: A3 | AQ4: -2.7
W5: A4 | X5: 0.672 | Z5: A4 | AA5: 0.389 | AC5: A4 | AD5: 0.568 | AP5: A4 | AQ5: 0.09
W6: A5 | X6: -0.417 | Z6: A5 | AA6: -0.631 | AC6: A5 | AD6: 0.08 | AP6: A5 | AQ6: 0.016
W7: A6 | X7: 0.617 | Z7: A6 | AA7: 2.011 | AP7: A6 | AQ7: 0.82
AP8: A7 | AQ8: 2
A9: Autor | B9: Inputs | R9: Output
B10: Diâmetro da armadura (mm) | C10: Resistência do aço - fy (MPa) | D10: Número de barras em uma camada | E10: Espaçamento entre as barras (mm) | F10: Resistência à tração do concreto (MPa) | G10: Cobrimento (mm) | H10: Distância ao centro de gravidade da armadura (mm) | I10: Largura da viga - b (mm) | J10: Altura da viga - h (mm) | K10: Área de aço tracionada - As (mm2) | L10: Área de concreto efetiva - Ace (mm2) | M10: Linha neutra no Estádio II - XII (mm) | N10: Taxa de armadura | O10: Momento fletor - Ms (kNm) | P10: Tensão na armadura menos tension stiffening (MPa) | Q10: Normalizado Tensão na armadura menos tension stiffening (MPa) | R10: w (mm) | S10: Deformação na armadura menos tension stiffening | AE10: resíduo | AF10: Erro | AG10: wpred*Erro/wobs | AR10: resíduo
A11: Viga S200-1.76-20 - Sokolov et al (2021) | B11: 20 | C11: 500 | D11: 2 | E11: 126 | F11: 4.1203405 | G11: 25 | H11: 39 | I11: 216 | J11: 201 | K11: 628 | L11: 29484 | M11: 57.361777 | N11: 0.021299688 | O11: 20.8 | P11: 120.52775 | Q11: =(P11-P$354)/P$355 -> -1.0409508 | R11: 0.16 | S11: =P11/200000 -> 0.00060263873 | W11: =$X$2*($X$3*$G11+$X$4*$B11^$X$5*$N11^$X$6)*$S11^$X$7 -> 0.19768346 | X11: =W11/$R11 -> 1.2355216 | Z11: =$AA$2*$B11^$AA$3*$S11^$AA$4*($AA$5*$N11^$AA$6+$AA$7) -> 0.1949344 | AA11: =Z11/$R11 -> 1.21834 | AC11: =$AD$2*($AD$3+$AD$4*$F11/($N11*'Sem TS MC2020'!P3))*($AD$5*$G11+$AD$6*$B11/$N11)*'Sem TS MC2020'!R3*($J11-$M11)/($J11-$M11-$H11) -> 0.18269773 | AD11: =AC11/$R11 -> 1.1418608 | AE11: =AC11-$R11 -> 0.022697733 | AF11: =1/AD11 -> 0.87576347 | AG11: =AC11*(14.068*'Sem TS MC2020'!$P3^-0.457)/$R11 -> 1.3334578 | AP11: =$AQ$2*($AQ$3+$AQ$4*$F11/($N11*'Sem TS MC2020'!P3))*($AQ$5*$G11+$AQ$6*$B11/$N11)*('Sem TS MC2020'!P3^$AQ$7/200000)*($J11-$M11)/($J11-$M11-$H11)+('Sem TS MC2020'!P3-$C11/$AQ$8)*($AQ$5*$G11+$AQ$6*$B11/$N11)/200000 -> 0.19730926 | AQ11: =AP11/$R11 -> 1.2331829 | AR11: =AP11-$R11 -> 0.037309263
B12: 20 | C12: 500 | D12: 2 | E12: 126 | F12: 4.1203405 | G12: 25 | H12: 39 | I12: 216 | J12: 201 | K12: 628 | L12: 29484 | M12: 57.361777 | N12: 0.021299688 | O12: 27.3 | P12: 223.84798 | Q12: =(P12-P$354)/P$355 -> -0.17474156 | R12: 0.23 | S12: =P12/200000 -> 0.0011192399 | W12: =$X$2*($X$3*$G12+$X$4*$B12^$X$5*$N12^$X$6)*$S12^$X$7 -> 0.28964147 | X12: =W12/$R12 -> 1.2593108 | Z12: =$AA$2*$B12^$AA$3*$S12^$AA$4*($AA$5*$N12^$AA$6+$AA$7) -> 0.28756527 | AA12: =Z12/$R12 -> 1.2502838 | AC12: =$AD$2*($AD$3+$AD$4*$F12/($N12*'Sem TS MC2020'!P4))*($AD$5*$G12+$AD$6*$B12/$N12)*'Sem TS MC2020'!R4*($J12-$M12)/($J12-$M12-$H12) -> 0.28726414 | AD12: =AC12/$R12 -> 1.2489745 | AE12: =AC12-$R12 -> 0.057264135 | AF12: =1/AD12 -> 0.80065686 | AG12: =AC12*(14.068*'Sem TS MC2020'!$P4^-0.457)/$R12 -> 1.2880962 | AP12: =$AQ$2*($AQ$3+$AQ$4*$F12/($N12*'Sem TS MC2020'!P4))*($AQ$5*$G12+$AQ$6*$B12/$N12)*('Sem TS MC2020'!P4^$AQ$7/200000)*($J12-$M12)/($J12-$M12-$H12)+('Sem TS MC2020'!P4-$C12/$AQ$8)*($AQ$5*$G12+$AQ$6*$B12/$N12)/200000 -> 0.30420253 | AQ12: =AP12/$R12 -> 1.3226197 | AR12: =AP12-$R12 -> 0.074202527
B13: 20 | C13: 500 | D13: 2 | E13: 126 | F13: 4.1203405 | G13: 25 | H13: 39 | I13: 216 | J13: 201 | K13: 628 | L13: 29484 | M13: 57.361777 | N13: 0.021299688 | O13: 28.2 | P13: 242.0522 | Q13: =(P13-P$354)/P$355 -> -0.022122286 | R13: 0.24 | S13: =P13/200000 -> 0.001210261 | W13: =$X$2*($X$3*$G13+$X$4*$B13^$X$5*$N13^$X$6)*$S13^$X$7 -> 0.30395655 | X13: =W13/$R13 -> 1.2664856 | Z13: =$AA$2*$B13^$AA$3*$S13^$AA$4*($AA$5*$N13^$AA$6+$AA$7) -> 0.30203739 | AA13: =Z13/$R13 -> 1.2584891 | AC13: =$AD$2*($AD$3+$AD$4*$F13/($N13*'Sem TS MC2020'!P5))*($AD$5*$G13+$AD$6*$B13/$N13)*'Sem TS MC2020'!R5*($J13-$M13)/($J13-$M13-$H13) -> 0.30174256 | AD13: =AC13/$R13 -> 1.2572607 | AE13: =AC13-$R13 -> 0.06174256 | AF13: =1/AD13 -> 0.79538001 | AG13: =AC13*(14.068*'Sem TS MC2020'!$P5^-0.457)/$R13 -> 1.2775636 | AP13: =$AQ$2*($AQ$3+$AQ$4*$F13/($N13*'Sem TS MC2020'!P5))*($AQ$5*$G13+$AQ$6*$B13/$N13)*('Sem TS MC2020'!P5^$AQ$7/200000)*($J13-$M13)/($J13-$M13-$H13)+('Sem TS MC2020'!P5-$C13/$AQ$8)*($AQ$5*$G13+$AQ$6*$B13/$N13)/200000 -> 0.31848621 | AQ13: =AP13/$R13 -> 1.3270259 | AR13: =AP13-$R13 -> 0.078486208
B14: 20 | C14: 500 | D14: 2 | E14: 126 | F14: 4.1203405 | G14: 25 | H14: 39 | I14: 216 | J14: 201 | K14: 628 | L14: 29484 | M14: 57.361777 | N14: 0.021299688 | O14: 32.6 | P14: 325.14719 | Q14: =(P14-P$354)/P$355 -> 0.67452391 | R14: 0.27 | S14: =P14/200000 -> 0.001625736 | W14: =$X$2*($X$3*$G14+$X$4*$B14^$X$5*$N14^$X$6)*$S14^$X$7 -> 0.36466409 | X14: =W14/$R14 -> 1.3506077 | Z14: =$AA$2*$B14^$AA$3*$S14^$AA$4*($AA$5*$N14^$AA$6+$AA$7) -> 0.36353989 | AA14: =Z14/$R14 -> 1.346444 | AC14: =$AD$2*($AD$3+$AD$4*$F14/($N14*'Sem TS MC2020'!P6))*($AD$5*$G14+$AD$6*$B14/$N14)*'Sem TS MC2020'!R6*($J14-$M14)/($J14-$M14-$H14) -> 0.37252597 | AD14: =AC14/$R14 -> 1.3797258 | AE14: =AC14-$R14 -> 0.10252597 | AF14: =1/AD14 -> 0.72478168 | AG14: =AC14*(14.068*'Sem TS MC2020'!$P6^-0.457)/$R14 -> 1.3121195 | AP14: =$AQ$2*($AQ$3+$AQ$4*$F14/($N14*'Sem TS MC2020'!P6))*($AQ$5*$G14+$AQ$6*$B14/$N14)*('Sem TS MC2020'!P6^$AQ$7/200000)*($J14-$M14)/($J14-$M14-$H14)+('Sem TS MC2020'!P6-$C14/$AQ$8)*($AQ$5*$G14+$AQ$6*$B14/$N14)/200000 -> 0.38687098 | AQ14: =AP14/$R14 -> 1.4328555 | AR14: =AP14-$R14 -> 0.11687098
B15: 20 | C15: 500 | D15: 2 | E15: 126 | F15: 4.1203405 | G15: 25 | H15: 39 | I15: 216 | J15: 201 | K15: 628 | L15: 29484 | M15: 57.361777 | N15: 0.021299688 | O15: 41.2 | P15: 447.78446 | Q15: =(P15-P$354)/P$355 -> 1.702682 | R15: 0.35 | S15: =P15/200000 -> 0.0022389223 | W15: =$X$2*($X$3*$G15+$X$4*$B15^$X$5*$N15^$X$6)*$S15^$X$7 -> 0.44427228 | X15: =W15/$R15 -> 1.2693494 | Z15: =$AA$2*$B15^$AA$3*$S15^$AA$4*($AA$5*$N15^$AA$6+$AA$7) -> 0.4444646 | AA15: =Z15/$R15 -> 1.2698988 | AC15: =$AD$2*($AD$3+$AD$4*$F15/($N15*'Sem TS MC2020'!P7))*($AD$5*$G15+$AD$6*$B15/$N15)*'Sem TS MC2020'!R7*($J15-$M15)/($J15-$M15-$H15) -> 0.51087536 | AD15: =AC15/$R15 -> 1.4596439 | AE15: =AC15-$R15 -> 0.16087536 | AF15: =1/AD15 -> 0.68509861 | AG15: =AC15*(14.068*'Sem TS MC2020'!$P7^-0.457)/$R15 -> 1.2472684 | AP15: =$AQ$2*($AQ$3+$AQ$4*$F15/($N15*'Sem TS MC2020'!P7))*($AQ$5*$G15+$AQ$6*$B15/$N15)*('Sem TS MC2020'!P7^$AQ$7/200000)*($J15-$M15)/($J15-$M15-$H15)+('Sem TS MC2020'!P7-$C15/$AQ$8)*($AQ$5*$G15+$AQ$6*$B15/$N15)/200000 -> 0.51490295 | AQ15: =AP15/$R15 -> 1.4711513 | AR15: =AP15-$R15 -> 0.16490295
B16: 20 | C16: 500 | D16: 2 | E16: 126 | F16: 4.1203405 | G16: 25 | H16: 39 | I16: 216 | J16: 201 | K16: 628 | L16: 29484 | M16: 57.361777 | N16: 0.021299688 | O16: 44.9 | P16: 500 | Q16: =(P16-P$354)/P$355 -> 2.1404431 | R16: 0.4 | S16: =P16/200000 -> 0.0025 | W16: =$X$2*($X$3*$G16+$X$4*$B16^$X$5*$N16^$X$6)*$S16^$X$7 -> 0.4755587 | X16: =W16/$R16 -> 1.1888967 | Z16: =$AA$2*$B16^$AA$3*$S16^$AA$4*($AA$5*$N16^$AA$6+$AA$7) -> 0.47634213 | AA16: =Z16/$R16 -> 1.1908553 | AC16: =$AD$2*($AD$3+$AD$4*$F16/($N16*'Sem TS MC2020'!P8))*($AD$5*$G16+$AD$6*$B16/$N16)*'Sem TS MC2020'!R8*($J16-$M16)/($J16-$M16-$H16) -> 0.5698208 | AD16: =AC16/$R16 -> 1.424552 | AE16: =AC16-$R16 -> 0.1698208 | AF16: =1/AD16 -> 0.70197508 | AG16: =AC16*(14.068*'Sem TS MC2020'!$P8^-0.457)/$R16 -> 1.1707964 | AP16: =$AQ$2*($AQ$3+$AQ$4*$F16/($N16*'Sem TS MC2020'!P8))*($AQ$5*$G16+$AQ$6*$B16/$N16)*('Sem TS MC2020'!P8^$AQ$7/200000)*($J16-$M16)/($J16-$M16-$H16)+('Sem TS MC2020'!P8-$C16/$AQ$8)*($AQ$5*$G16+$AQ$6*$B16/$N16)/200000 -> 0.56764369 | AQ16: =AP16/$R16 -> 1.4191092 | AR16: =AP16-$R16 -> 0.16764369
A17: Viga S600-0.37-10 - Sokolov et al (2021) | B17: 10 | C17: 500 | D17: 8 | E17: 87.7 | F17: 4.1311268 | G17: 25 | H17: 53 | I17: 308 | J17: 604 | K17: 628 | L17: 43428 | M17: 99.6964 | N17: 0.014460717 | O17: 105 | P17: 224.98496 | Q17: =(P17-P$354)/P$355 -> -0.16520943 | R17: 0.16 | S17: =P17/200000 -> 0.0011249248 | W17: =$X$2*($X$3*$G17+$X$4*$B17^$X$5*$N17^$X$6)*$S17^$X$7 -> 0.2142315 | X17: =W17/$R17 -> 1.3389469 | Z17: =$AA$2*$B17^$AA$3*$S17^$AA$4*($AA$5*$N17^$AA$6+$AA$7) -> 0.2112024 | AA17: =Z17/$R17 -> 1.320015 | AC17: =$AD$2*($AD$3+$AD$4*$F17/($N17*'Sem TS MC2020'!P9))*($AD$5*$G17+$AD$6*$B17/$N17)*'Sem TS MC2020'!R9*($J17-$M17)/($J17-$M17-$H17) -> 0.15319516 | AD17: =AC17/$R17 -> 0.95746978 | AE17: =AC17-$R17 -> -0.0068048354 | AF17: =1/AD17 -> 1.0444194 | AG17: =AC17*(14.068*'Sem TS MC2020'!$P9^-0.457)/$R17 -> 0.96095095 | AP17: =$AQ$2*($AQ$3+$AQ$4*$F17/($N17*'Sem TS MC2020'!P9))*($AQ$5*$G17+$AQ$6*$B17/$N17)*('Sem TS MC2020'!P9^$AQ$7/200000)*($J17-$M17)/($J17-$M17-$H17)+('Sem TS MC2020'!P9-$C17/$AQ$8)*($AQ$5*$G17+$AQ$6*$B17/$N17)/200000 -> 0.16014114 | AQ17: =AP17/$R17 -> 1.0008821 | AR17: =AP17-$R17 -> 0.00014113896
B18: 10 | C18: 500 | D18: 8 | E18: 87.7 | F18: 4.1311268 | G18: 25 | H18: 53 | I18: 308 | J18: 604 | K18: 628 | L18: 43428 | M18: 99.6964 | N18: 0.014460717 | O18: 119.6 | P18: 301.65384 | Q18: =(P18-P$354)/P$355 -> 0.47756193 | R18: 0.18 | S18: =P18/200000 -> 0.0015082692 | W18: =$X$2*($X$3*$G18+$X$4*$B18^$X$5*$N18^$X$6)*$S18^$X$7 -> 0.25672111 | X18: =W18/$R18 -> 1.4262284 | Z18: =$AA$2*$B18^$AA$3*$S18^$AA$4*($AA$5*$N18^$AA$6+$AA$7) -> 0.25390896 | AA18: =Z18/$R18 -> 1.4106053 | AC18: =$AD$2*($AD$3+$AD$4*$F18/($N18*'Sem TS MC2020'!P10))*($AD$5*$G18+$AD$6*$B18/$N18)*'Sem TS MC2020'!R10*($J18-$M18)/($J18-$M18-$H18) -> 0.19426213 | AD18: =AC18/$R18 -> 1.0792341 | AE18: =AC18-$R18 -> 0.014262131 | AF18: =1/AD18 -> 0.92658306 | AG18: =AC18*(14.068*'Sem TS MC2020'!$P10^-0.457)/$R18 -> 1.020592 | AP18: =$AQ$2*($AQ$3+$AQ$4*$F18/($N18*'Sem TS MC2020'!P10))*($AQ$5*$G18+$AQ$6*$B18/$N18)*('Sem TS MC2020'!P10^$AQ$7/200000)*($J18-$M18)/($J18-$M18-$H18)+('Sem TS MC2020'!P10-$C18/$AQ$8)*($AQ$5*$G18+$AQ$6*$B18/$N18)/200000 -> 0.20092938 | AQ18: =AP18/$R18 -> 1.1162744 | AR18: =AP18-$R18 -> 0.020929385
B19: 10 | C19: 500 | D19: 8 | E19: 87.7 | F19: 4.1311268 | G19: 25 | H19: 53 | I19: 308 | J19: 604 | K19: 628 | L19: 43428 | M19: 99.6964 | N19: 0.014460717 | O19: 174.3 | P19: 497.36822 | Q19: =(P19-P$354)/P$355 -> 2.118379 | R19: 0.26 | S19: =P19/200000 -> 0.0024868411 | W19: =$X$2*($X$3*$G19+$X$4*$B19^$X$5*$N19^$X$6)*$S19^$X$7 -> 0.34950627 | X19: =W19/$R19 -> 1.3442549 | Z19: =$AA$2*$B19^$AA$3*$S19^$AA$4*($AA$5*$N19^$AA$6+$AA$7) -> 0.34758439 | AA19: =Z19/$R19 -> 1.336863 | AC19: =$AD$2*($AD$3+$AD$4*$F19/($N19*'Sem TS MC2020'!P11))*($AD$5*$G19+$AD$6*$B19/$N19)*'Sem TS MC2020'!R11*($J19-$M19)/($J19-$M19-$H19) -> 0.31515403 | AD19: =AC19/$R19 -> 1.2121309 | AE19: =AC19-$R19 -> 0.055154025 | AF19: =1/AD19 -> 0.82499343 | AG19: =AC19*(14.068*'Sem TS MC2020'!$P11^-0.457)/$R19 -> 0.99621386 | AP19: =$AQ$2*($AQ$3+$AQ$4*$F19/($N19*'Sem TS MC2020'!P11))*($AQ$5*$G19+$AQ$6*$B19/$N19)*('Sem TS MC2020'!P11^$AQ$7/200000)*($J19-$M19)/($J19-$M19-$H19)+('Sem TS MC2020'!P11-$C19/$AQ$8)*($AQ$5*$G19+$AQ$6*$B19/$N19)/200000 -> 0.31465649 | AQ19: =AP19/$R19 -> 1.2102173 | AR19: =AP19-$R19 -> 0.05465649
A20: Viga V1 - Oliveira (2007) | B20: 10 | C20: 628 | D20: 4 | E20: 32.466667 | F20: 3.262 | G20: 25 | H20: 36 | I20: 200 | J20: 600 | K20: 314 | L20: 17200 | M20: 95.721927 | N20: 0.018255814 | O20: 47.625 | P20: 178.11588 | Q20: =(P20-P$354)/P$355 -> -0.55814724 | R20: 0.16 | S20: =P20/200000 -> 0.00089057942 | W20: =$X$2*($X$3*$G20+$X$4*$B20^$X$5*$N20^$X$6)*$S20^$X$7 -> 0.16827313 | X20: =W20/$R20 -> 1.0517071 | Z20: =$AA$2*$B20^$AA$3*$S20^$AA$4*($AA$5*$N20^$AA$6+$AA$7) -> 0.16400319 | AA20: =Z20/$R20 -> 1.0250199 | AC20: =$AD$2*($AD$3+$AD$4*$F20/($N20*'Sem TS MC2020'!P12))*($AD$5*$G20+$AD$6*$B20/$N20)*'Sem TS MC2020'!R12*($J20-$M20)/($J20-$M20-$H20) -> 0.1381736 | AD20: =AC20/$R20 -> 0.86358503 | AE20: =AC20-$R20 -> -0.021826395 | AF20: =1/AD20 -> 1.1579636 | AG20: =AC20*(14.068*'Sem TS MC2020'!$P12^-0.457)/$R20 -> 0.9175715 | AP20: =$AQ$2*($AQ$3+$AQ$4*$F20/($N20*'Sem TS MC2020'!P12))*($AQ$5*$G20+$AQ$6*$B20/$N20)*('Sem TS MC2020'!P12^$AQ$7/200000)*($J20-$M20)/($J20-$M20-$H20)+('Sem TS MC2020'!P12-$C20/$AQ$8)*($AQ$5*$G20+$AQ$6*$B20/$N20)/200000 -> 0.14151898 | AQ20: =AP20/$R20 -> 0.88449366 | AR20: =AP20-$R20 -> -0.018481015
B21: 10 | C21: 628 | D21: 4 | E21: 32.466667 | F21: 3.262 | G21: 25 | H21: 36 | I21: 200 | J21: 600 | K21: 314 | L21: 17200 | M21: 95.721927 | N21: 0.018255814 | O21: 54.3 | P21: 242.19704 | Q21: =(P21-P$354)/P$355 -> -0.020907976 | R21: 0.2 | S21: =P21/200000 -> 0.0012109852 | W21: =$X$2*($X$3*$G21+$X$4*$B21^$X$5*$N21^$X$6)*$S21^$X$7 -> 0.20340584 | X21: =W21/$R21 -> 1.0170292 | Z21: =$AA$2*$B21^$AA$3*$S21^$AA$4*($AA$5*$N21^$AA$6+$AA$7) -> 0.19891569 | AA21: =Z21/$R21 -> 0.99457847 | AC21: =$AD$2*($AD$3+$AD$4*$F21/($N21*'Sem TS MC2020'!P13))*($AD$5*$G21+$AD$6*$B21/$N21)*'Sem TS MC2020'!R13*($J21-$M21)/($J21-$M21-$H21) -> 0.16756213 | AD21: =AC21/$R21 -> 0.83781067 | AE21: =AC21-$R21 -> -0.032437866 | AF21: =1/AD21 -> 1.1935871 | AG21: =AC21*(14.068*'Sem TS MC2020'!$P13^-0.457)/$R21 -> 0.83839324 | AP21: =$AQ$2*($AQ$3+$AQ$4*$F21/($N21*'Sem TS MC2020'!P13))*($AQ$5*$G21+$AQ$6*$B21/$N21)*('Sem TS MC2020'!P13^$AQ$7/200000)*($J21-$M21)/($J21-$M21-$H21)+('Sem TS MC2020'!P13-$C21/$AQ$8)*($AQ$5*$G21+$AQ$6*$B21/$N21)/200000 -> 0.17040509 | AQ21: =AP21/$R21 -> 0.85202543 | AR21: =AP21-$R21 -> -0.029594915
B22: 10 | C22: 628 | D22: 4 | E22: 32.466667 | F22: 3.262 | G22: 25 | H22: 36 | I22: 200 | J22: 600 | K22: 314 | L22: 17200 | M22: 95.721927 | N22: 0.018255814 | O22: 61.425 | P22: 308.13373 | Q22: =(P22-P$354)/P$355 -> 0.53188761 | R22: 0.2 | S22: =P22/200000 -> 0.0015406687 | W22: =$X$2*($X$3*$G22+$X$4*$B22^$X$5*$N22^$X$6)*$S22^$X$7 -> 0.23598443 | X22: =W22/$R22 -> 1.1799222 | Z22: =$AA$2*$B22^$AA$3*$S22^$AA$4*($AA$5*$N22^$AA$6+$AA$7) -> 0.23138717 | AA22: =Z22/$R22 -> 1.1569358 | AC22: =$AD$2*($AD$3+$AD$4*$F22/($N22*'Sem TS MC2020'!P14))*($AD$5*$G22+$AD$6*$B22/$N22)*'Sem TS MC2020'!R14*($J22-$M22)/($J22-$M22-$H22) -> 0.19893191 | AD22: =AC22/$R22 -> 0.99465956 | AE22: =AC22-$R22 -> -0.0010680871 | AF22: =1/AD22 -> 1.0053691 | AG22: =AC22*(14.068*'Sem TS MC2020'!$P14^-0.457)/$R22 -> 0.9408191 | AP22: =$AQ$2*($AQ$3+$AQ$4*$F22/($N22*'Sem TS MC2020'!P14))*($AQ$5*$G22+$AQ$6*$B22/$N22)*('Sem TS MC2020'!P14^$AQ$7/200000)*($J22-$M22)/($J22-$M22-$H22)+('Sem TS MC2020'!P14-$C22/$AQ$8)*($AQ$5*$G22+$AQ$6*$B22/$N22)/200000 -> 0.20037279 | AQ22: =AP22/$R22 -> 1.0018639 | AR22: =AP22-$R22 -> 0.0003727879
B23: 10 | C23: 628 | D23: 4 | E23: 32.466667 | F23: 3.262 | G23: 25 | H23: 36 | I23: 200 | J23: 600 | K23: 314 | L23: 17200 | M23: 95.721927 | N23: 0.018255814 | O23: 68.625 | P23: 368.31936 | Q23: =(P23-P$354)/P$355 -> 1.0364679 | R23: 0.24 | S23: =P23/200000 -> 0.0018415968 | W23: =$X$2*($X$3*$G23+$X$4*$B23^$X$5*$N23^$X$6)*$S23^$X$7 -> 0.26344611 | X23: =W23/$R23 -> 1.0976921 | Z23: =$AA$2*$B23^$AA$3*$S23^$AA$4*($AA$5*$N23^$AA$6+$AA$7) -> 0.25882132 | AA23: =Z23/$R23 -> 1.0784222 | AC23: =$AD$2*($AD$3+$AD$4*$F23/($N23*'Sem TS MC2020'!P15))*($AD$5*$G23+$AD$6*$B23/$N23)*'Sem TS MC2020'!R15*($J23-$M23)/($J23-$M23-$H23) -> 0.2306319 | AD23: =AC23/$R23 -> 0.96096625 | AE23: =AC23-$R23 -> -0.0093681003 | AF23: =1/AD23 -> 1.0406193 | AG23: =AC23*(14.068*'Sem TS MC2020'!$P15^-0.457)/$R23 -> 0.86405443 | AP23: =$AQ$2*($AQ$3+$AQ$4*$F23/($N23*'Sem TS MC2020'!P15))*($AQ$5*$G23+$AQ$6*$B23/$N23)*('Sem TS MC2020'!P15^$AQ$7/200000)*($J23-$M23)/($J23-$M23-$H23)+('Sem TS MC2020'!P15-$C23/$AQ$8)*($AQ$5*$G23+$AQ$6*$B23/$N23)/200000 -> 0.22989655 | AQ23: =AP23/$R23 -> 0.9579023 | AR23: =AP23-$R23 -> -0.010103449
B24: 10 | C24: 628 | D24: 4 | E24: 32.466667 | F24: 3.262 | G24: 25 | H24: 36 | I24: 200 | J24: 600 | K24: 314 | L24: 17200 | M24: 95.721927 | N24: 0.018255814 | O24: 73.275 | P24: 401.01025 | Q24: =(P24-P$354)/P$355 -> 1.3105395 | R24: 0.3 | S24: =P24/200000 -> 0.0020050512 | W24: =$X$2*($X$3*$G24+$X$4*$B24^$X$5*$N24^$X$6)*$S24^$X$7 -> 0.27763753 | X24: =W24/$R24 -> 0.92545842 | Z24: =$AA$2*$B24^$AA$3*$S24^$AA$4*($AA$5*$N24^$AA$6+$AA$7) -> 0.27301887 | AA24: =Z24/$R24 -> 0.91006289 | AC24: =$AD$2*($AD$3+$AD$4*$F24/($N24*'Sem TS MC2020'!P16))*($AD$5*$G24+$AD$6*$B24/$N24)*'Sem TS MC2020'!R16*($J24-$M24)/($J24-$M24-$H24) -> 0.25110481 | AD24: =AC24/$R24 -> 0.83701603 | AE24: =AC24-$R24 -> -0.048895192 | AF24: =1/AD24 -> 1.1947203 | AG24: =AC24*(14.068*'Sem TS MC2020'!$P16^-0.457)/$R24 -> 0.73038923 | AP24: =$AQ$2*($AQ$3+$AQ$4*$F24/($N24*'Sem TS MC2020'!P16))*($AQ$5*$G24+$AQ$6*$B24/$N24)*('Sem TS MC2020'!P16^$AQ$7/200000)*($J24-$M24)/($J24-$M24-$H24)+('Sem TS MC2020'!P16-$C24/$AQ$8)*($AQ$5*$G24+$AQ$6*$B24/$N24)/200000 -> 0.24861266 | AQ24: =AP24/$R24 -> 0.82870885 | AR24: =AP24-$R24 -> -0.051387344
B25: 10 | C25: 628 | D25: 4 | E25: 32.466667 | F25: 3.262 | G25: 25 | H25: 36 | I25: 200 | J25: 600 | K25: 314 | L25: 17200 | M25: 95.721927 | N25: 0.018255814 | O25: 83.25 | P25: 498.05773 | Q25: =(P25-P$354)/P$355 -> 2.1241596 | R25: 0.32 | S25: =P25/200000 -> 0.0024902886 | W25: =$X$2*($X$3*$G25+$X$4*$B25^$X$5*$N25^$X$6)*$S25^$X$7 -> 0.31736045 | X25: =W25/$R25 -> 0.99175142 | Z25: =$AA$2*$B25^$AA$3*$S25^$AA$4*($AA$5*$N25^$AA$6+$AA$7) -> 0.31282587 | AA25: =Z25/$R25 -> 0.97758086 | AC25: =$AD$2*($AD$3+$AD$4*$F25/($N25*'Sem TS MC2020'!P17))*($AD$5*$G25+$AD$6*$B25/$N25)*'Sem TS MC2020'!R17*($J25-$M25)/($J25-$M25-$H25) -> 0.2950225 | AD25: =AC25/$R25 -> 0.92194531 | AE25: =AC25-$R25 -> -0.024977502 | AF25: =1/AD25 -> 1.084663 | AG25: =AC25*(14.068*'Sem TS MC2020'!$P17^-0.457)/$R25 -> 0.75891819 | AP25: =$AQ$2*($AQ$3+$AQ$4*$F25/($N25*'Sem TS MC2020'!P17))*($AQ$5*$G25+$AQ$6*$B25/$N25)*('Sem TS MC2020'!P17^$AQ$7/200000)*($J25-$M25)/($J25-$M25-$H25)+('Sem TS MC2020'!P17-$C25/$AQ$8)*($AQ$5*$G25+$AQ$6*$B25/$N25)/200000 -> 0.28795738 | AQ25: =AP25/$R25 -> 0.89986681 | AR25: =AP25-$R25 -> -0.03204262
B26: 10 | C26: 628 | D26: 4 | E26: 32.466667 | F26: 3.262 | G26: 25 | H26: 36 | I26: 200 | J26: 600 | K26: 314 | L26: 17200 | M26: 95.721927 | N26: 0.018255814 | O26: 84 | P26: 502.76188 | Q26: =(P26-P$354)/P$355 -> 2.163598 | R26: 0.38 | S26: =P26/200000 -> 0.0025138094 | W26: =$X$2*($X$3*$G26+$X$4*$B26^$X$5*$N26^$X$6)*$S26^$X$7 -> 0.31920656 | X26: =W26/$R26 -> 0.84001726 | Z26: =$AA$2*$B26^$AA$3*$S26^$AA$4*($AA$5*$N26^$AA$6+$AA$7) -> 0.31467814 | AA26: =Z26/$R26 -> 0.82810038 | AC26: =$AD$2*($AD$3+$AD$4*$F26/($N26*'Sem TS MC2020'!P18))*($AD$5*$G26+$AD$6*$B26/$N26)*'Sem TS MC2020'!R18*($J26-$M26)/($J26-$M26-$H26) -> 0.29832458 | AD26: =AC26/$R26 -> 0.78506468 | AE26: =AC26-$R26 -> -0.08167542 | AF26: =1/AD26 -> 1.2737804 | AG26: =AC26*(14.068*'Sem TS MC2020'!$P18^-0.457)/$R26 -> 0.64359878 | AP26: =$AQ$2*($AQ$3+$AQ$4*$F26/($N26*'Sem TS MC2020'!P18))*($AQ$5*$G26+$AQ$6*$B26/$N26)*('Sem TS MC2020'!P18^$AQ$7/200000)*($J26-$M26)/($J26-$M26-$H26)+('Sem TS MC2020'!P18-$C26/$AQ$8)*($AQ$5*$G26+$AQ$6*$B26/$N26)/200000 -> 0.29087529 | AQ26: =AP26/$R26 -> 0.76546129 | AR26: =AP26-$R26 -> -0.089124711
B27: 10 | C27: 628 | D27: 4 | E27: 32.466667 | F27: 3.262 | G27: 25 | H27: 36 | I27: 200 | J27: 600 | K27: 314 | L27: 17200 | M27: 95.721927 | N27: 0.018255814 | O27: 90 | P27: 538.67345 | Q27: =(P27-P$354)/P$355 -> 2.4646709 | R27: 0.42 | S27: =P27/200000 -> 0.0026933672 | W27: =$X$2*($X$3*$G27+$X$4*$B27^$X$5*$N27^$X$6)*$S27^$X$7 -> 0.3330881 | X27: =W27/$R27 -> 0.79306691 | Z27: =$AA$2*$B27^$AA$3*$S27^$AA$4*($AA$5*$N27^$AA$6+$AA$7) -> 0.32861205 | AA27: =Z27/$R27 -> 0.78240964 | AC27: =$AD$2*($AD$3+$AD$4*$F27/($N27*'Sem TS MC2020'!P19))*($AD$5*$G27+$AD$6*$B27/$N27)*'Sem TS MC2020'!R19*($J27-$M27)/($J27-$M27-$H27) -> 0.32474124 | AD27: =AC27/$R27 -> 0.77319342 | AE27: =AC27-$R27 -> -0.095258764 | AF27: =1/AD27 -> 1.2933374 | AG27: =AC27*(14.068*'Sem TS MC2020'!$P19^-0.457)/$R27 -> 0.6141928 | AP27: =$AQ$2*($AQ$3+$AQ$4*$F27/($N27*'Sem TS MC2020'!P19))*($AQ$5*$G27+$AQ$6*$B27/$N27)*('Sem TS MC2020'!P19^$AQ$7/200000)*($J27-$M27)/($J27-$M27-$H27)+('Sem TS MC2020'!P19-$C27/$AQ$8)*($AQ$5*$G27+$AQ$6*$B27/$N27)/200000 -> 0.31403394 | AQ27: =AP27/$R27 -> 0.74769985 | AR27: =AP27-$R27 -> -0.10596606
B28: 10 | C28: 628 | D28: 4 | E28: 32.466667 | F28: 3.262 | G28: 25 | H28: 36 | I28: 200 | J28: 600 | K28: 314 | L28: 17200 | M28: 95.721927 | N28: 0.018255814 | O28: 108 | P28: 628 | Q28: =(P28-P$354)/P$355 -> 3.2135609 | R28: 0.44 | S28: =P28/200000 -> 0.00314 | W28: =$X$2*($X$3*$G28+$X$4*$B28^$X$5*$N28^$X$6)*$S28^$X$7 -> 0.36616122 | X28: =W28/$R28 -> 0.83218458 | Z28: =$AA$2*$B28^$AA$3*$S28^$AA$4*($AA$5*$N28^$AA$6+$AA$7) -> 0.36185092 | AA28: =Z28/$R28 -> 0.82238846 | AC28: =$AD$2*($AD$3+$AD$4*$F28/($N28*'Sem TS MC2020'!P20))*($AD$5*$G28+$AD$6*$B28/$N28)*'Sem TS MC2020'!R20*($J28-$M28)/($J28-$M28-$H28) -> 0.39045012 | AD28: =AC28/$R28 -> 0.88738664 | AE28: =AC28-$R28 -> -0.049549879 | AF28: =1/AD28 -> 1.1269045 | AG28: =AC28*(14.068*'Sem TS MC2020'!$P20^-0.457)/$R28 -> 0.65716994 | AP28: =$AQ$2*($AQ$3+$AQ$4*$F28/($N28*'Sem TS MC2020'!P20))*($AQ$5*$G28+$AQ$6*$B28/$N28)*('Sem TS MC2020'!P20^$AQ$7/200000)*($J28-$M28)/($J28-$M28-$H28)+('Sem TS MC2020'!P20-$C28/$AQ$8)*($AQ$5*$G28+$AQ$6*$B28/$N28)/200000 -> 0.37036258 | AQ28: =AP28/$R28 -> 0.84173314 | AR28: =AP28-$R28 -> -0.069637417
B29: 10 | C29: 628 | D29: 4 | E29: 32.466667 | F29: 3.262 | G29: 25 | H29: 36 | I29: 200 | J29: 600 | K29: 314 | L29: 17200 | M29: 95.721927 | N29: 0.018255814 | O29: 120 | P29: 628 | Q29: =(P29-P$354)/P$355 -> 3.2135609 | R29: 0.5 | S29: =P29/200000 -> 0.00314 | W29: =$X$2*($X$3*$G29+$X$4*$B29^$X$5*$N29^$X$6)*$S29^$X$7 -> 0.36616122 | X29: =W29/$R29 -> 0.73232243 | Z29: =$AA$2*$B29^$AA$3*$S29^$AA$4*($AA$5*$N29^$AA$6+$AA$7) -> 0.36185092 | AA29: =Z29/$R29 -> 0.72370184 | AC29: =$AD$2*($AD$3+$AD$4*$F29/($N29*'Sem TS MC2020'!P21))*($AD$5*$G29+$AD$6*$B29/$N29)*'Sem TS MC2020'!R21*($J29-$M29)/($J29-$M29-$H29) -> 0.39045012 | AD29: =AC29/$R29 -> 0.78090024 | AE29: =AC29-$R29 -> -0.10954988 | AF29: =1/AD29 -> 1.2805733 | AG29: =AC29*(14.068*'Sem TS MC2020'!$P21^-0.457)/$R29 -> 0.57830954 | AP29: =$AQ$2*($AQ$3+$AQ$4*$F29/($N29*'Sem TS MC2020'!P21))*($AQ$5*$G29+$AQ$6*$B29/$N29)*('Sem TS MC2020'!P21^$AQ$7/200000)*($J29-$M29)/($J29-$M29-$H29)+('Sem TS MC2020'!P21-$C29/$AQ$8)*($AQ$5*$G29+$AQ$6*$B29/$N29)/200000 -> 0.37036258 | AQ29: =AP29/$R29 -> 0.74072517 | AR29: =AP29-$R29 -> -0.12963742
A30: Viga V2 - Oliveira (2007) | B30: 10 | C30: 628 | D30: 4 | E30: 32.466667 | F30: 3.514 | G30: 25 | H30: 36 | I30: 200 | J30: 600 | K30: 314 | L30: 17200 | M30: 87.120679 | N30: 0.018255814 | O30: 54 | P30: 249.68578 | Q30: =(P30-P$354)/P$355 -> 0.041875657 | R30: 0.24 | S30: =P30/200000 -> 0.0012484289 | W30: =$X$2*($X$3*$G30+$X$4*$B30^$X$5*$N30^$X$6)*$S30^$X$7 -> 0.20726369 | X30: =W30/$R30 -> 0.86359871 | Z30: =$AA$2*$B30^$AA$3*$S30^$AA$4*($AA$5*$N30^$AA$6+$AA$7) -> 0.20275629 | AA30: =Z30/$R30 -> 0.84481789 | AC30: =$AD$2*($AD$3+$AD$4*$F30/($N30*'Sem TS MC2020'!P22))*($AD$5*$G30+$AD$6*$B30/$N30)*'Sem TS MC2020'!R22*($J30-$M30)/($J30-$M30-$H30) -> 0.15923753 | AD30: =AC30/$R30 -> 0.66348969 | AE30: =AC30-$R30 -> -0.080762474 | AF30: =1/AD30 -> 1.5071824 | AG30: =AC30*(14.068*'Sem TS MC2020'!$P22^-0.457)/$R30 -> 0.66727091 | AP30: =$AQ$2*($AQ$3+$AQ$4*$F30/($N30*'Sem TS MC2020'!P22))*($AQ$5*$G30+$AQ$6*$B30/$N30)*('Sem TS MC2020'!P22^$AQ$7/200000)*($J30-$M30)/($J30-$M30-$H30)+('Sem TS MC2020'!P22-$C30/$AQ$8)*($AQ$5*$G30+$AQ$6*$B30/$N30)/200000 -> 0.16191714 | AQ30: =AP30/$R30 -> 0.67465473 | AR30: =AP30-$R30 -> -0.078082865
B31: 10 | C31: 628 | D31: 4 | E31: 32.466667 | F31: 3.514 | G31: 25 | H31: 36 | I31: 200 | J31: 600 | K31: 314 | L31: 17200 | M31: 87.120679 | N31: 0.018255814 | O31: 60 | P31: 336.5738 | Q31: =(P31-P$354)/P$355 -> 0.77032152 | R31: 0.3 | S31: =P31/200000 -> 0.001682869 | W31: =$X$2*($X$3*$G31+$X$4*$B31^$X$5*$N31^$X$6)*$S31^$X$7 -> 0.24919527 | X31: =W31/$R31 -> 0.83065089 | Z31: =$AA$2*$B31^$AA$3*$S31^$AA$4*($AA$5*$N31^$AA$6+$AA$7) -> 0.24457804 | AA31: =Z31/$R31 -> 0.81526012 | AC31: =$AD$2*($AD$3+$AD$4*$F31/($N31*'Sem TS MC2020'!P23))*($AD$5*$G31+$AD$6*$B31/$N31)*'Sem TS MC2020'!R23*($J31-$M31)/($J31-$M31-$H31) -> 0.18547877 | AD31: =AC31/$R31 -> 0.61826257 | AE31: =AC31-$R31 -> -0.11452123 | AF31: =1/AD31 -> 1.6174358 | AG31: =AC31*(14.068*'Sem TS MC2020'!$P23^-0.457)/$R31 -> 0.59255654 | AP31: =$AQ$2*($AQ$3+$AQ$4*$F31/($N31*'Sem TS MC2020'!P23))*($AQ$5*$G31+$AQ$6*$B31/$N31)*('Sem TS MC2020'!P23^$AQ$7/200000)*($J31-$M31)/($J31-$M31-$H31)+('Sem TS MC2020'!P23-$C31/$AQ$8)*($AQ$5*$G31+$AQ$6*$B31/$N31)/200000 -> 0.187208 | AQ31: =AP31/$R31 -> 0.62402667 | AR31: =AP31-$R31 -> -0.112792
B32: 10 | C32: 628 | D32: 4 | E32: 32.466667 | F32: 3.514 | G32: 25 | H32: 36 | I32: 200 | J32: 600 | K32: 314 | L32: 17200 | M32: 87.120679 | N32: 0.018255814 | O32: 62.25 | P32: 361.87936 | Q32: =(P32-P$354)/P$355 -> 0.98247663 | R32: 0.3 | S32: =P32/200000 -> 0.0018093968 | W32: =$X$2*($X$3*$G32+$X$4*$B32^$X$5*$N32^$X$6)*$S32^$X$7 -> 0.26059442 | X32: =W32/$R32 -> 0.86864808 | Z32: =$AA$2*$B32^$AA$3*$S32^$AA$4*($AA$5*$N32^$AA$6+$AA$7) -> 0.25597002 | AA32: =Z32/$R32 -> 0.8532334 | AC32: =$AD$2*($AD$3+$AD$4*$F32/($N32*'Sem TS MC2020'!P24))*($AD$5*$G32+$AD$6*$B32/$N32)*'Sem TS MC2020'!R24*($J32-$M32)/($J32-$M32-$H32) -> 0.19531924 | AD32: =AC32/$R32 -> 0.65106413 | AE32: =AC32-$R32 -> -0.10468076 | AF32: =1/AD32 -> 1.535947 | AG32: =AC32*(14.068*'Sem TS MC2020'!$P24^-0.457)/$R32 -> 0.61358403 | AP32: =$AQ$2*($AQ$3+$AQ$4*$F32/($N32*'Sem TS MC2020'!P24))*($AQ$5*$G32+$AQ$6*$B32/$N32)*('Sem TS MC2020'!P24^$AQ$7/200000)*($J32-$M32)/($J32-$M32-$H32)+('Sem TS MC2020'!P24-$C32/$AQ$8)*($AQ$5*$G32+$AQ$6*$B32/$N32)/200000 -> 0.19654385 | AQ32: =AP32/$R32 -> 0.65514615 | AR32: =AP32-$R32 -> -0.10345615
B33: 10 | C33: 628 | D33: 4 | E33: 32.466667 | F33: 3.514 | G33: 25 | H33: 36 | I33: 200 | J33: 600 | K33: 314 | L33: 17200 | M33: 87.120679 | N33: 0.018255814 | O33: 66 | P33: 392.91007 | Q33: =(P33-P$354)/P$355 -> 1.2426298 | R33: 0.3 | S33: =P33/200000 -> 0.0019645504 | W33: =$X$2*($X$3*$G33+$X$4*$B33^$X$5*$N33^$X$6)*$S33^$X$7 -> 0.27416381 | X33: =W33/$R33 -> 0.91387936 | Z33: =$AA$2*$B33^$AA$3*$S33^$AA$4*($AA$5*$N33^$AA$6+$AA$7) -> 0.26954242 | AA33: =Z33/$R33 -> 0.89847475 | AC33: =$AD$2*($AD$3+$AD$4*$F33/($N33*'Sem TS MC2020'!P25))*($AD$5*$G33+$AD$6*$B33/$N33)*'Sem TS MC2020'!R25*($J33-$M33)/($J33-$M33-$H33) -> 0.21172002 | AD33: =AC33/$R33 -> 0.70573339 | AE33: =AC33-$R33 -> -0.088279984 | AF33: =1/AD33 -> 1.4169657 | AG33: =AC33*(14.068*'Sem TS MC2020'!$P25^-0.457)/$R33 -> 0.64756154 | AP33: =$AQ$2*($AQ$3+$AQ$4*$F33/($N33*'Sem TS MC2020'!P25))*($AQ$5*$G33+$AQ$6*$B33/$N33)*('Sem TS MC2020'!P25^$AQ$7/200000)*($J33-$M33)/($J33-$M33-$H33)+('Sem TS MC2020'!P25-$C33/$AQ$8)*($AQ$5*$G33+$AQ$6*$B33/$N33)/200000 -> 0.21194075 | AQ33: =AP33/$R33 -> 0.70646917 | AR33: =AP33-$R33 -> -0.08805925
B34: 10 | C34: 628 | D34: 4 | E34: 32.466667 | F34: 3.514 | G34: 25 | H34: 36 | I34: 200 | J34: 600 | K34: 314 | L34: 17200 | M34: 87.120679 | N34: 0.018255814 | O34: 71.25 | P34: 424.16428 | Q34: =(P34-P$354)/P$355 -> 1.5046567 | R34: 0.38 | S34: =P34/200000 -> 0.0021208214 | W34: =$X$2*($X$3*$G34+$X$4*$B34^$X$5*$N34^$X$6)*$S34^$X$7 -> 0.28742185 | X34: =W34/$R34 -> 0.75637329 | Z34: =$AA$2*$B34^$AA$3*$S34^$AA$4*($AA$5*$N34^$AA$6+$AA$7) -> 0.282815 | AA34: =Z34/$R34 -> 0.74424999 | AC34: =$AD$2*($AD$3+$AD$4*$F34/($N34*'Sem TS MC2020'!P26))*($AD$5*$G34+$AD$6*$B34/$N34)*'Sem TS MC2020'!R26*($J34-$M34)/($J34-$M34-$H34) -> 0.23468111 | AD34: =AC34/$R34 -> 0.61758186 | AE34: =AC34-$R34 -> -0.14531889 | AF34: =1/AD34 -> 1.6192186 | AG34: =AC34*(14.068*'Sem TS MC2020'!$P26^-0.457)/$R34 -> 0.54719713 | AP34: =$AQ$2*($AQ$3+$AQ$4*$F34/($N34*'Sem TS MC2020'!P26))*($AQ$5*$G34+$AQ$6*$B34/$N34)*('Sem TS MC2020'!P26^$AQ$7/200000)*($J34-$M34)/($J34-$M34-$H34)+('Sem TS MC2020'!P26-$C34/$AQ$8)*($AQ$5*$G34+$AQ$6*$B34/$N34)/200000 -> 0.23318211 | AQ34: =AP34/$R34 -> 0.61363714 | AR34: =AP34-$R34 -> -0.14681789
B35: 10 | C35: 628 | D35: 4 | E35: 32.466667 | F35: 3.514 | G35: 25 | H35: 36 | I35: 200 | J35: 600 | K35: 314 | L35: 17200 | M35: 87.120679 | N35: 0.018255814 | O35: 82.5 | P35: 491.13759 | Q35: =(P35-P$354)/P$355 -> 2.066143 | R35: 0.44 | S35: =P35/200000 -> 0.0024556879 | W35: =$X$2*($X$3*$G35+$X$4*$B35^$X$5*$N35^$X$6)*$S35^$X$7 -> 0.31463251 | X35: =W35/$R35 -> 0.7150739 | Z35: =$AA$2*$B35^$AA$3*$S35^$AA$4*($AA$5*$N35^$AA$6+$AA$7) -> 0.31008918 | AA35: =Z35/$R35 -> 0.70474815 | AC35: =$AD$2*($AD$3+$AD$4*$F35/($N35*'Sem TS MC2020'!P27))*($AD$5*$G35+$AD$6*$B35/$N35)*'Sem TS MC2020'!R27*($J35-$M35)/($J35-$M35-$H35) -> 0.28388344 | AD35: =AC35/$R35 -> 0.64518964 | AE35: =AC35-$R35 -> -0.15611656 | AF35: =1/AD35 -> 1.5499319 | AG35: =AC35*(14.068*'Sem TS MC2020'!$P27^-0.457)/$R35 -> 0.53461346 | AP35: =$AQ$2*($AQ$3+$AQ$4*$F35/($N35*'Sem TS MC2020'!P27))*($AQ$5*$G35+$AQ$6*$B35/$N35)*('Sem TS MC2020'!P27^$AQ$7/200000)*($J35-$M35)/($J35-$M35-$H35)+('Sem TS MC2020'!P27-$C35/$AQ$8)*($AQ$5*$G35+$AQ$6*$B35/$N35)/200000 -> 0.27762328 | AQ35: =AP35/$R35 -> 0.630962 | AR35: =AP35-$R35 -> -0.16237672
A36: Viga T1F000 - Silva Neto (2017) | B36: 16 | C36: 571 | D36: 4 | E36: 37 | F36: 4.2588 | G36: 33 | H36: 59 | I36: 125 | J36: 250 | K36: 800 | L36: 19625 | M36: 87.082519 | N36: 0.0408 | O36: 18.2 | P36: 63.458454 | Q36: =(P36-P$354)/P$355 -> -1.5194045 | R36: 0.18 | S36: =P36/200000 -> 0.00031729227 | W36: =$X$2*($X$3*$G36+$X$4*$B36^$X$5*$N36^$X$6)*$S36^$X$7 -> 0.087244867 | X36: =W36/$R36 -> 0.48469371 | Z36: =$AA$2*$B36^$AA$3*$S36^$AA$4*($AA$5*$N36^$AA$6+$AA$7) -> 0.085674437 | AA36: =Z36/$R36 -> 0.4759691 | AC36: =$AD$2*($AD$3+$AD$4*$F36/($N36*'Sem TS MC2020'!P28))*($AD$5*$G36+$AD$6*$B36/$N36)*'Sem TS MC2020'!R28*($J36-$M36)/($J36-$M36-$H36) -> 0.077010617 | AD36: =AC36/$R36 -> 0.42783676 | AE36: =AC36-$R36 -> -0.10298938 | AF36: =1/AD36 -> 2.3373401 | AG36: =AC36*(14.068*'Sem TS MC2020'!$P28^-0.457)/$R36 -> 0.6290287 | AP36: =$AQ$2*($AQ$3+$AQ$4*$F36/($N36*'Sem TS MC2020'!P28))*($AQ$5*$G36+$AQ$6*$B36/$N36)*('Sem TS MC2020'!P28^$AQ$7/200000)*($J36-$M36)/($J36-$M36-$H36)+('Sem TS MC2020'!P28-$C36/$AQ$8)*($AQ$5*$G36+$AQ$6*$B36/$N36)/200000 -> 0.081081852 | AQ36: =AP36/$R36 -> 0.45045473 | AR36: =AP36-$R36 -> -0.098918148
B37: 16 | C37: 571 | D37: 4 | E37: 37 | F37: 4.2588 | G37: 33 | H37: 59 | I37: 125 | J37: 250 | K37: 800 | L37: 19625 | M37: 87.082519 | N37: 0.0408 | O37: 26.2 | P37: 132.58577 | Q37: =(P37-P$354)/P$355 -> -0.93985955 | R37: 0.2 | S37: =P37/200000 -> 0.00066292885 | W37: =$X$2*($X$3*$G37+$X$4*$B37^$X$5*$N37^$X$6)*$S37^$X$7 -> 0.13746257 | X37: =W37/$R37 -> 0.68731286 | Z37: =$AA$2*$B37^$AA$3*$S37^$AA$4*($AA$5*$N37^$AA$6+$AA$7) -> 0.13608678 | AA37: =Z37/$R37 -> 0.68043388 | AC37: =$AD$2*($AD$3+$AD$4*$F37/($N37*'Sem TS MC2020'!P29))*($AD$5*$G37+$AD$6*$B37/$N37)*'Sem TS MC2020'!R29*($J37-$M37)/($J37-$M37-$H37) -> 0.1339515 | AD37: =AC37/$R37 -> 0.66975748 | AE37: =AC37-$R37 -> -0.066048503 | AF37: =1/AD37 -> 1.4930778 | AG37: =AC37*(14.068*'Sem TS MC2020'!$P29^-0.457)/$R37 -> 0.83367902 | AP37: =$AQ$2*($AQ$3+$AQ$4*$F37/($N37*'Sem TS MC2020'!P29))*($AQ$5*$G37+$AQ$6*$B37/$N37)*('Sem TS MC2020'!P29^$AQ$7/200000)*($J37-$M37)/($J37-$M37-$H37)+('Sem TS MC2020'!P29-$C37/$AQ$8)*($AQ$5*$G37+$AQ$6*$B37/$N37)/200000 -> 0.13995609 | AQ37: =AP37/$R37 -> 0.69978044 | AR37: =AP37-$R37 -> -0.060043913
B38: 16 | C38: 571 | D38: 4 | E38: 37 | F38: 4.2588 | G38: 33 | H38: 59 | I38: 125 | J38: 250 | K38: 800 | L38: 19625 | M38: 87.082519 | N38: 0.0408 | O38: 31.7 | P38: 182.10678 | Q38: =(P38-P$354)/P$355 -> -0.52468863 | R38: 0.26 | S38: =P38/200000 -> 0.00091053391 | W38: =$X$2*($X$3*$G38+$X$4*$B38^$X$5*$N38^$X$6)*$S38^$X$7 -> 0.16719569 | X38: =W38/$R38 -> 0.64306036 | Z38: =$AA$2*$B38^$AA$3*$S38^$AA$4*($AA$5*$N38^$AA$6+$AA$7) -> 0.16610116 | AA38: =Z38/$R38 -> 0.63885061 | AC38: =$AD$2*($AD$3+$AD$4*$F38/($N38*'Sem TS MC2020'!P30))*($AD$5*$G38+$AD$6*$B38/$N38)*'Sem TS MC2020'!R30*($J38-$M38)/($J38-$M38-$H38) -> 0.17309835 | AD38: =AC38/$R38 -> 0.66576289 | AE38: =AC38-$R38 -> -0.086901648 | AF38: =1/AD38 -> 1.5020363 | AG38: =AC38*(14.068*'Sem TS MC2020'!$P30^-0.457)/$R38 -> 0.75959219 | AP38: =$AQ$2*($AQ$3+$AQ$4*$F38/($N38*'Sem TS MC2020'!P30))*($AQ$5*$G38+$AQ$6*$B38/$N38)*('Sem TS MC2020'!P30^$AQ$7/200000)*($J38-$M38)/($J38-$M38-$H38)+('Sem TS MC2020'!P30-$C38/$AQ$8)*($AQ$5*$G38+$AQ$6*$B38/$N38)/200000 -> 0.17798601 | AQ38: =AP38/$R38 -> 0.68456158 | AR38: =AP38-$R38 -> -0.082013988
B39: 16 | C39: 571 | D39: 4 | E39: 37 | F39: 4.2588 | G39: 33 | H39: 59 | I39: 125 | J39: 250 | K39: 800 | L39: 19625 | M39: 87.082519 | N39: 0.0408 | O39: 40.8 | P39: 276.47022 | Q39: =(P39-P$354)/P$355 -> 0.26642917 | R39: 0.44 | S39: =P39/200000 -> 0.0013823511 | W39: =$X$2*($X$3*$G39+$X$4*$B39^$X$5*$N39^$X$6)*$S39^$X$7 -> 0.21632211 | X39: =W39/$R39 -> 0.49164115 | Z39: =$AA$2*$B39^$AA$3*$S39^$AA$4*($AA$5*$N39^$AA$6+$AA$7) -> 0.21589522 | AA39: =Z39/$R39 -> 0.49067095 | AC39: =$AD$2*($AD$3+$AD$4*$F39/($N39*'Sem TS MC2020'!P31))*($AD$5*$G39+$AD$6*$B39/$N39)*'Sem TS MC2020'!R31*($J39-$M39)/($J39-$M39-$H39) -> 0.2378686 | AD39: =AC39/$R39 -> 0.54061046 | AE39: =AC39-$R39 -> -0.2021314 | AF39: =1/AD39 -> 1.8497607 | AG39: =AC39*(14.068*'Sem TS MC2020'!$P31^-0.457)/$R39 -> 0.54961394 | AP39: =$AQ$2*($AQ$3+$AQ$4*$F39/($N39*'Sem TS MC2020'!P31))*($AQ$5*$G39+$AQ$6*$B39/$N39)*('Sem TS MC2020'!P31^$AQ$7/200000)*($J39-$M39)/($J39-$M39-$H39)+('Sem TS MC2020'!P31-$C39/$AQ$8)*($AQ$5*$G39+$AQ$6*$B39/$N39)/200000 -> 0.23793605 | AQ39: =AP39/$R39 -> 0.54076376 | AR39: =AP39-$R39 -> -0.20206395
B40: 16 | C40: 571 | D40: 4 | E40: 37 | F40: 4.2588 | G40: 33 | H40: 59 | I40: 125 | J40: 250 | K40: 800 | L40: 19625 | M40: 87.082519 | N40: 0.0408 | O40: 54.1 | P40: 412.87726 | Q40: =(P40-P$354)/P$355 -> 1.4100294 | R40: 0.6 | S40: =P40/200000 -> 0.0020643863 | W40: =$X$2*($X$3*$G40+$X$4*$B40^$X$5*$N40^$X$6)*$S40^$X$7 -> 0.27705463 | X40: =W40/$R40 -> 0.46175771 | Z40: =$AA$2*$B40^$AA$3*$S40^$AA$4*($AA$5*$N40^$AA$6+$AA$7) -> 0.27773041 | AA40: =Z40/$R40 -> 0.46288401 | AC40: =$AD$2*($AD$3+$AD$4*$F40/($N40*'Sem TS MC2020'!P32))*($AD$5*$G40+$AD$6*$B40/$N40)*'Sem TS MC2020'!R32*($J40-$M40)/($J40-$M40-$H40) -> 0.33253282 | AD40: =AC40/$R40 -> 0.55422136 | AE40: =AC40-$R40 -> -0.26746718 | AF40: =1/AD40 -> 1.8043332 | AG40: =AC40*(14.068*'Sem TS MC2020'!$P32^-0.457)/$R40 -> 0.49528719 | AP40: =$AQ$2*($AQ$3+$AQ$4*$F40/($N40*'Sem TS MC2020'!P32))*($AQ$5*$G40+$AQ$6*$B40/$N40)*('Sem TS MC2020'!P32^$AQ$7/200000)*($J40-$M40)/($J40-$M40-$H40)+('Sem TS MC2020'!P32-$C40/$AQ$8)*($AQ$5*$G40+$AQ$6*$B40/$N40)/200000 -> 0.32083232 | AQ40: =AP40/$R40 -> 0.53472053 | AR40: =AP40-$R40 -> -0.27916768
...

Sheet Sem TS MC2020
A1: Autor | B1: Inputs | Q1: Output
B2: Diâmetro da armadura f (mm) | C2: Resistência do aço - fy (MPa) | D2: Número de barras em uma camada | E2: Espaçamento entre as barras (mm) | F2: Resistência à tração do concreto fctm (MPa) | G2: Cobrimento c (mm) | H2: Distância ao centro de gravidade da armadura d' (mm) | I2: Largura da viga - b (mm) | J2: Altura da viga - h (mm) | K2: Área de aço tracionada - As (mm2) | L2: Área de concreto efetiva - Ace (mm2) | M2: Linha neutra no Estádio II - XII (mm) | N2: Taxa de armadura r | O2: Momento fletor - Ms (kNm) | P2: Tensão na armadura (MPa) | Q2: wexp (mm) | R2: Deformação na armadura
A3: Viga S200-1.76-20 - Sokolov et al (2021) | B3: 20 | C3: 500 | D3: 2 | E3: 126 | F3: 4.1203405 | G3: 25 | H3: 39 | I3: 216 | J3: 201 | K3: 628 | L3: 29484 | M3: 57.361777 | N3: 0.021299688 | O3: 20.8 | P3: 231.811 | Q3: 0.16 | R3: =P3/200000 -> 0.001159055
B4: 20 | C4: 500 | D4: 2 | E4: 126 | F4: 4.1203405 | G4: 25 | H4: 39 | I4: 216 | J4: 201 | K4: 628 | L4: 29484 | M4: 57.361777 | N4: 0.021299688 | O4: 27.3 | P4: 304.25194 | Q4: 0.23 | R4: =P4/200000 -> 0.0015212597
B5: 20 | C5: 500 | D5: 2 | E5: 126 | F5: 4.1203405 | G5: 25 | H5: 39 | I5: 216 | J5: 201 | K5: 628 | L5: 29484 | M5: 57.361777 | N5: 0.021299688 | O5: 28.2 | P5: 314.28223 | Q5: 0.24 | R5: =P5/200000 -> 0.0015714111
B6: 20 | C6: 500 | D6: 2 | E6: 126 | F6: 4.1203405 | G6: 25 | H6: 39 | I6: 216 | J6: 201 | K6: 628 | L6: 29484 | M6: 57.361777 | N6: 0.021299688 | O6: 32.6 | P6: 363.31917 | Q6: 0.27 | R6: =P6/200000 -> 0.0018165959
B7: 20 | C7: 500 | D7: 2 | E7: 126 | F7: 4.1203405 | G7: 25 | H7: 39 | I7: 216 | J7: 201 | K7: 628 | L7: 29484 | M7: 57.361777 | N7: 0.021299688 | O7: 41.2 | P7: 459.16411 | Q7: 0.35 | R7: =P7/200000 -> 0.0022958205
B8: 20 | C8: 500 | D8: 2 | E8: 126 | F8: 4.1203405 | G8: 25 | H8: 39 | I8: 216 | J8: 201 | K8: 628 | L8: 29484 | M8: 57.361777 | N8: 0.021299688 | O8: 44.9 | P8: 500 | Q8: 0.4 | R8: =P8/200000 -> 0.0025
A9: Viga S600-0.37-10 - Sokolov et al (2021) | B9: 10 | C9: 500 | D9: 8 | E9: 87.7 | F9: 4.1311268 | G9: 25 | H9: 53 | I9: 308 | J9: 604 | K9: 628 | L9: 43428 | M9: 99.6964 | N9: 0.014460717 | O9: 105 | P9: 322.91972 | Q9: 0.16 | R9: =P9/200000 -> 0.0016145986
B10: 10 | C10: 500 | D10: 8 | E10: 87.7 | F10: 4.1311268 | G10: 25 | H10: 53 | I10: 308 | J10: 604 | K10: 628 | L10: 43428 | M10: 99.6964 | N10: 0.014460717 | O10: 119.6 | P10: 367.82093 | Q10: 0.18 | R10: =P10/200000 -> 0.0018391047
B11: 10 | C11: 500 | D11: 8 | E11: 87.7 | F11: 4.1311268 | G11: 25 | H11: 53 | I11: 308 | J11: 604 | K11: 628 | L11: 43428 | M11: 99.6964 | N11: 0.014460717 | O11: 174.3 | P11: 500 | Q11: 0.26 | R11: =P11/200000 -> 0.0025
A12: Viga V1 - Oliveira (2007) | B12: 10 | C12: 628 | D12: 4 | E12: 32.466667 | F12: 3.262 | G12: 25 | H12: 36 | I12: 200 | J12: 600 | K12: 314 | L12: 17200 | M12: 95.721927 | N12: 0.018255814 | O12: 47.625 | P12: 285.04803 | Q12: 0.16 | R12: =P12/200000 -> 0.0014252402
B13: 10 | C13: 628 | D13: 4 | E13: 32.466667 | F13: 3.262 | G13: 25 | H13: 36 | I13: 200 | J13: 600 | K13: 314 | L13: 17200 | M13: 95.721927 | N13: 0.018255814 | O13: 54.3 | P13: 324.99965 | Q13: 0.2 | R13: =P13/200000 -> 0.0016249982
B14: 10 | C14: 628 | D14: 4 | E14: 32.466667 | F14: 3.262 | G14: 25 | H14: 36 | I14: 200 | J14: 600 | K14: 314 | L14: 17200 | M14: 95.721927 | N14: 0.018255814 | O14: 61.425 | P14: 367.64463 | Q14: 0.2 | R14: =P14/200000 -> 0.0018382231
B15: 10 | C15: 628 | D15: 4 | E15: 32.466667 | F15: 3.262 | G15: 25 | H15: 36 | I15: 200 | J15: 600 | K15: 314 | L15: 17200 | M15: 95.721927 | N15: 0.018255814 | O15: 68.625 | P15: 410.7385 | Q15: 0.24 | R15: =P15/200000 -> 0.0020536925
B16: 10 | C16: 628 | D16: 4 | E16: 32.466667 | F16: 3.262 | G16: 25 | H16: 36 | I16: 200 | J16: 600 | K16: 314 | L16: 17200 | M16: 95.721927 | N16: 0.018255814 | O16: 73.275 | P16: 438.56996 | Q16: 0.3 | R16: =P16/200000 -> 0.0021928498
B17: 10 | C17: 628 | D17: 4 | E17: 32.466667 | F17: 3.262 | G17: 25 | H17: 36 | I17: 200 | J17: 600 | K17: 314 | L17: 17200 | M17: 95.721927 | N17: 0.018255814 | O17: 83.25 | P17: 498.27294 | Q17: 0.32 | R17: =P17/200000 -> 0.0024913647
B18: 10 | C18: 628 | D18: 4 | E18: 32.466667 | F18: 3.262 | G18: 25 | H18: 36 | I18: 200 | J18: 600 | K18: 314 | L18: 17200 | M18: 95.721927 | N18: 0.018255814 | O18: 84 | P18: 502.76188 | Q18: 0.38 | R18: =P18/200000 -> 0.0025138094
B19: 10 | C19: 628 | D19: 4 | E19: 32.466667 | F19: 3.262 | G19: 25 | H19: 36 | I19: 200 | J19: 600 | K19: 314 | L19: 17200 | M19: 95.721927 | N19: 0.018255814 | O19: 90 | P19: 538.67345 | Q19: 0.42 | R19: =P19/200000 -> 0.0026933672
B20: 10 | C20: 628 | D20: 4 | E20: 32.466667 | F20: 3.262 | G20: 25 | H20: 36 | I20: 200 | J20: 600 | K20: 314 | L20: 17200 | M20: 95.721927 | N20: 0.018255814 | O20: 108 | P20: 628 | Q20: 0.44 | R20: =P20/200000 -> 0.00314
B21: 10 | C21: 628 | D21: 4 | E21: 32.466667 | F21: 3.262 | G21: 25 | H21: 36 | I21: 200 | J21: 600 | K21: 314 | L21: 17200 | M21: 95.721927 | N21: 0.018255814 | O21: 120 | P21: 628 | Q21: 0.5 | R21: =P21/200000 -> 0.00314
A22: Viga V2 - Oliveira (2007) | B22: 10 | C22: 628 | D22: 4 | E22: 32.466667 | F22: 3.514 | G22: 25 | H22: 36 | I22: 200 | J22: 600 | K22: 314 | L22: 17200 | M22: 87.120679 | N22: 0.018255814 | O22: 54 | P22: 321.47188 | Q22: 0.24 | R22: =P22/200000 -> 0.0016073594
B23: 10 | C23: 628 | D23: 4 | E23: 32.466667 | F23: 3.514 | G23: 25 | H23: 36 | I23: 200 | J23: 600 | K23: 314 | L23: 17200 | M23: 87.120679 | N23: 0.018255814 | O23: 60 | P23: 357.19097 | Q23: 0.3 | R23: =P23/200000 -> 0.0017859549
B24: 10 | C24: 628 | D24: 4 | E24: 32.466667 | F24: 3.514 | G24: 25 | H24: 36 | I24: 200 | J24: 600 | K24: 314 | L24: 17200 | M24: 87.120679 | N24: 0.018255814 | O24: 62.25 | P24: 370.58564 | Q24: 0.3 | R24: =P24/200000 -> 0.0018529282
B25: 10 | C25: 628 | D25: 4 | E25: 32.466667 | F25: 3.514 | G25: 25 | H25: 36 | I25: 200 | J25: 600 | K25: 314 | L25: 17200 | M25: 87.120679 | N25: 0.018255814 | O25: 66 | P25: 392.91007 | Q25: 0.3 | R25: =P25/200000 -> 0.0019645504
B26: 10 | C26: 628 | D26: 4 | E26: 32.466667 | F26: 3.514 | G26: 25 | H26: 36 | I26: 200 | J26: 600 | K26: 314 | L26: 17200 | M26: 87.120679 | N26: 0.018255814 | O26: 71.25 | P26: 424.16428 | Q26: 0.38 | R26: =P26/200000 -> 0.0021208214
B27: 10 | C27: 628 | D27: 4 | E27: 32.466667 | F27: 3.514 | G27: 25 | H27: 36 | I27: 200 | J27: 600 | K27: 314 | L27: 17200 | M27: 87.120679 | N27: 0.018255814 | O27: 82.5 | P27: 491.13759 | Q27: 0.44 | R27: =P27/200000 -> 0.0024556879
A28: Viga T1F000 - Silva Neto (2017) | B28: 16 | C28: 571 | D28: 4 | E28: 37 | F28: 4.2588 | G28: 33 | H28: 59 | I28: 125 | J28: 250 | K28: 800 | L28: 19625 | M28: 86 | N28: 0.0408 | O28: 18.2 | P28: 140.04197 | Q28: 0.18 | R28: =P28/200000 -> 0.00070020983
B29: 16 | C29: 571 | D29: 4 | E29: 37 | F29: 4.2588 | G29: 33 | H29: 59 | I29: 125 | J29: 250 | K29: 800 | L29: 19625 | M29: 86 | N29: 0.0408 | O29: 26.2 | P29: 201.59887 | Q29: 0.2 | R29: =P29/200000 -> 0.0010079944
