Workbook

Sheet Com TS variável MC2010
P1: Opção 3 de equação | S1: Opção 4 de equação
P2: A1 | Q2: 1.728 | S2: A1 | T2: 0.392
P3: A2 | Q3: 0.011 | S3: A2 | T3: 1.148
P4: A3 | Q4: 0.339 | S4: A3 | T4: 0.854
P5: A4 | Q5: 1.102 | S5: A4 | T5: 0.555
P6: A5 | Q6: -0.495 | S6: A5 | T6: -0.686
P7: A6 | Q7: 0.838 | S7: A6 | T7: 1.952
A9: Autor | B9: Inputs | K9: Output
B10: Diâmetro da armadura (mm) | C10: Resistência do aço - fy (MPa) | D10: Número de barras em uma camada | E10: Espaçamento entre as barras (mm) | F10: Resistência à tração do concreto (MPa) | G10: Cobrimento (mm) | H10: Distância ao centro de gravidade da armadura (mm) | I10: Taxa de armadura | J10: Tensão na armadura menos tension stiffening (MPa) | K10: w (mm) | L10: Deformação na armadura menos tension stiffening (MPa)
A11: Viga S200-1.76-20 - Sokolov et al (2021) | B11: 20 | C11: 500 | D11: 2 | E11: 126 | F11: 4.1203405 | G11: 25 | H11: 39 | I11: 0.060723546 | J11: 185.31436 | K11: 0.16 | L11: =J11/200000 -> 0.00092657181 | P11: =$Q$2*($Q$3*$G11+$Q$4*$B11^$Q$5*$I11^$Q$6)*$L11^$Q$7 -> 0.18415873 | Q11: =P11/$K11 -> 1.1509921 | S11: =$T$2*$B11^$T$3*$L11^$T$4*($T$5*$I11^$T$6+$T$7) -> 0.18022921 | T11: =S11/$K11 -> 1.1264326
B12: 20 | C12: 500 | D12: 2 | E12: 126 | F12: 4.1203405 | G12: 25 | H12: 39 | I12: 0.060723546 | J12: 270.65736 | K12: 0.23 | L12: =J12/200000 -> 0.0013532868 | P12: =$Q$2*($Q$3*$G12+$Q$4*$B12^$Q$5*$I12^$Q$6)*$L12^$Q$7 -> 0.25296029 | Q12: =P12/$K12 -> 1.0998273 | S12: =$T$2*$B12^$T$3*$L12^$T$4*($T$5*$I12^$T$6+$T$7) -> 0.24906768 | T12: =S12/$K12 -> 1.082903
B13: 20 | C13: 500 | D13: 2 | E13: 126 | F13: 4.1203405 | G13: 25 | H13: 39 | I13: 0.060723546 | J13: 284.1029 | K13: 0.24 | L13: =J13/200000 -> 0.0014205145 | P13: =$Q$2*($Q$3*$G13+$Q$4*$B13^$Q$5*$I13^$Q$6)*$L13^$Q$7 -> 0.26344934 | Q13: =P13/$K13 -> 1.0977056 | S13: =$T$2*$B13^$T$3*$L13^$T$4*($T$5*$I13^$T$6+$T$7) -> 0.25959663 | T13: =S13/$K13 -> 1.0816526
B14: 20 | C14: 500 | D14: 2 | E14: 126 | F14: 4.1203405 | G14: 25 | H14: 39 | I14: 0.060723546 | J14: 347.37006 | K14: 0.27 | L14: =J14/200000 -> 0.0017368503 | P14: =$Q$2*($Q$3*$G14+$Q$4*$B14^$Q$5*$I14^$Q$6)*$L14^$Q$7 -> 0.31179456 | Q14: =P14/$K14 -> 1.1547947 | S14: =$T$2*$B14^$T$3*$L14^$T$4*($T$5*$I14^$T$6+$T$7) -> 0.30822476 | T14: =S14/$K14 -> 1.1415732
B15: 20 | C15: 500 | D15: 2 | E15: 126 | F15: 4.1203405 | G15: 25 | H15: 39 | I15: 0.060723546 | J15: 454.40943 | K15: 0.35 | L15: =J15/200000 -> 0.0022720472 | P15: =$Q$2*($Q$3*$G15+$Q$4*$B15^$Q$5*$I15^$Q$6)*$L15^$Q$7 -> 0.3905039 | Q15: =P15/$K15 -> 1.1157254 | S15: =$T$2*$B15^$T$3*$L15^$T$4*($T$5*$I15^$T$6+$T$7) -> 0.38769558 | T15: =S15/$K15 -> 1.1077017
B16: 20 | C16: 500 | D16: 2 | E16: 126 | F16: 4.1203405 | G16: 25 | H16: 39 | I16: 0.060723546 | J16: 500 | K16: 0.4 | L16: =J16/200000 -> 0.0025 | P16: =$Q$2*($Q$3*$G16+$Q$4*$B16^$Q$5*$I16^$Q$6)*$L16^$Q$7 -> 0.42307891 | Q16: =P16/$K16 -> 1.0576973 | S16: =$T$2*$B16^$T$3*$L16^$T$4*($T$5*$I16^$T$6+$T$7) -> 0.42067936 | T16: =S16/$K16 -> 1.0516984
A17: Viga S600-0.37-10 - Sokolov et al (2021) | B17: 10 | C17: 500 | D17: 8 | E17: 87.7 | F17: 4.1311268 | G17: 25 | H17: 53 | I17: 0.015388385 | J17: 230.46115 | K17: 0.16 | L17: =J17/200000 -> 0.0011523057 | P17: =$Q$2*($Q$3*$G17+$Q$4*$B17^$Q$5*$I17^$Q$6)*$L17^$Q$7 -> 0.203325 | Q17: =P17/$K17 -> 1.2707812 | S17: =$T$2*$B17^$T$3*$L17^$T$4*($T$5*$I17^$T$6+$T$7) -> 0.19915306 | T17: =S17/$K17 -> 1.2447066
B18: 10 | C18: 500 | D18: 8 | E18: 87.7 | F18: 4.1311268 | G18: 25 | H18: 53 | I18: 0.015388385 | J18: 305.35368 | K18: 0.18 | L18: =J18/200000 -> 0.0015267684 | P18: =$Q$2*($Q$3*$G18+$Q$4*$B18^$Q$5*$I18^$Q$6)*$L18^$Q$7 -> 0.25739431 | Q18: =P18/$K18 -> 1.4299684 | S18: =$T$2*$B18^$T$3*$L18^$T$4*($T$5*$I18^$T$6+$T$7) -> 0.25325056 | T18: =S18/$K18 -> 1.4069476
B19: 10 | C19: 500 | D19: 8 | E19: 87.7 | F19: 4.1311268 | G19: 25 | H19: 53 | I19: 0.015388385 | J19: 497.51538 | K19: 0.26 | L19: =J19/200000 -> 0.0024875769 | P19: =$Q$2*($Q$3*$G19+$Q$4*$B19^$Q$5*$I19^$Q$6)*$L19^$Q$7 -> 0.38748754 | Q19: =P19/$K19 -> 1.4903367 | S19: =$T$2*$B19^$T$3*$L19^$T$4*($T$5*$I19^$T$6+$T$7) -> 0.38423886 | T19: =S19/$K19 -> 1.4778418
A20: Viga V1 - Oliveira (2007) | B20: 10 | C20: 628 | D20: 4 | E20: 32.466667 | F20: 3.262 | G20: 25 | H20: 36 | I20: 0.017444444 | J20: 173.6503 | K20: 0.16 | L20: =J20/200000 -> 0.00086825151 | P20: =$Q$2*($Q$3*$G20+$Q$4*$B20^$Q$5*$I20^$Q$6)*$L20^$Q$7 -> 0.15081563 | Q20: =P20/$K20 -> 0.9425977 | S20: =$T$2*$B20^$T$3*$L20^$T$4*($T$5*$I20^$T$6+$T$7) -> 0.14565419 | T20: =S20/$K20 -> 0.91033866
B21: 10 | C21: 628 | D21: 4 | E21: 32.466667 | F21: 3.262 | G21: 25 | H21: 36 | I21: 0.017444444 | J21: 238.73913 | K21: 0.2 | L21: =J21/200000 -> 0.0011936956 | P21: =$Q$2*($Q$3*$G21+$Q$4*$B21^$Q$5*$I21^$Q$6)*$L21^$Q$7 -> 0.19692381 | Q21: =P21/$K21 -> 0.98461906 | S21: =$T$2*$B21^$T$3*$L21^$T$4*($T$5*$I21^$T$6+$T$7) -> 0.19115551 | T21: =S21/$K21 -> 0.95577754
B22: 10 | C22: 628 | D22: 4 | E22: 32.466667 | F22: 3.262 | G22: 25 | H22: 36 | I22: 0.017444444 | J22: 305.6485 | K22: 0.2 | L22: =J22/200000 -> 0.0015282425 | P22: =$Q$2*($Q$3*$G22+$Q$4*$B22^$Q$5*$I22^$Q$6)*$L22^$Q$7 -> 0.24222252 | Q22: =P22/$K22 -> 1.2111126 | S22: =$T$2*$B22^$T$3*$L22^$T$4*($T$5*$I22^$T$6+$T$7) -> 0.23605863 | T22: =S22/$K22 -> 1.1802931
B23: 10 | C23: 628 | D23: 4 | E23: 32.466667 | F23: 3.262 | G23: 25 | H23: 36 | I23: 0.017444444 | J23: 366.5479 | K23: 0.24 | L23: =J23/200000 -> 0.0018327395 | P23: =$Q$2*($Q$3*$G23+$Q$4*$B23^$Q$5*$I23^$Q$6)*$L23^$Q$7 -> 0.2820589 | Q23: =P23/$K23 -> 1.1752454 | S23: =$T$2*$B23^$T$3*$L23^$T$4*($T$5*$I23^$T$6+$T$7) -> 0.27568155 | T23: =S23/$K23 -> 1.1486731
B24: 10 | C24: 628 | D24: 4 | E24: 32.466667 | F24: 3.262 | G24: 25 | H24: 36 | I24: 0.017444444 | J24: 399.44172 | K24: 0.3 | L24: =J24/200000 -> 0.0019972086 | P24: =$Q$2*($Q$3*$G24+$Q$4*$B24^$Q$5*$I24^$Q$6)*$L24^$Q$7 -> 0.30312114 | Q24: =P24/$K24 -> 1.0104038 | S24: =$T$2*$B24^$T$3*$L24^$T$4*($T$5*$I24^$T$6+$T$7) -> 0.29667522 | T24: =S24/$K24 -> 0.98891741
B25: 10 | C25: 628 | D25: 4 | E25: 32.466667 | F25: 3.262 | G25: 25 | H25: 36 | I25: 0.017444444 | J25: 498.04874 | K25: 0.32 | L25: =J25/200000 -> 0.0024902437 | P25: =$Q$2*($Q$3*$G25+$Q$4*$B25^$Q$5*$I25^$Q$6)*$L25^$Q$7 -> 0.3646801 | Q25: =P25/$K25 -> 1.1396253 | S25: =$T$2*$B25^$T$3*$L25^$T$4*($T$5*$I25^$T$6+$T$7) -> 0.35818733 | T25: =S25/$K25 -> 1.1193354
B26: 10 | C26: 628 | D26: 4 | E26: 32.466667 | F26: 3.262 | G26: 25 | H26: 36 | I26: 0.017444444 | J26: 502.76188 | K26: 0.38 | L26: =J26/200000 -> 0.0025138094 | P26: =$Q$2*($Q$3*$G26+$Q$4*$B26^$Q$5*$I26^$Q$6)*$L26^$Q$7 -> 0.36756986 | Q26: =P26/$K26 -> 0.96728912 | S26: =$T$2*$B26^$T$3*$L26^$T$4*($T$5*$I26^$T$6+$T$7) -> 0.36108005 | T26: =S26/$K26 -> 0.95021067
B27: 10 | C27: 628 | D27: 4 | E27: 32.466667 | F27: 3.262 | G27: 25 | H27: 36 | I27: 0.017444444 | J27: 538.67345 | K27: 0.42 | L27: =J27/200000 -> 0.0026933672 | P27: =$Q$2*($Q$3*$G27+$Q$4*$B27^$Q$5*$I27^$Q$6)*$L27^$Q$7 -> 0.38944764 | Q27: =P27/$K27 -> 0.92725629 | S27: =$T$2*$B27^$T$3*$L27^$T$4*($T$5*$I27^$T$6+$T$7) -> 0.38299411 | T27: =S27/$K27 -> 0.91189073
B28: 10 | C28: 628 | D28: 4 | E28: 32.466667 | F28: 3.262 | G28: 25 | H28: 36 | I28: 0.017444444 | J28: 628 | K28: 0.44 | L28: =J28/200000 -> 0.00314 | P28: =$Q$2*($Q$3*$G28+$Q$4*$B28^$Q$5*$I28^$Q$6)*$L28^$Q$7 -> 0.44288241 | Q28: =P28/$K28 -> 1.0065509 | S28: =$T$2*$B28^$T$3*$L28^$T$4*($T$5*$I28^$T$6+$T$7) -> 0.43661394 | T28: =S28/$K28 -> 0.9923044
B29: 10 | C29: 628 | D29: 4 | E29: 32.466667 | F29: 3.262 | G29: 25 | H29: 36 | I29: 0.017444444 | J29: 628 | K29: 0.5 | L29: =J29/200000 -> 0.00314 | P29: =$Q$2*($Q$3*$G29+$Q$4*$B29^$Q$5*$I29^$Q$6)*$L29^$Q$7 -> 0.44288241 | Q29: =P29/$K29 -> 0.88576483 | S29: =$T$2*$B29^$T$3*$L29^$T$4*($T$5*$I29^$T$6+$T$7) -> 0.43661394 | T29: =S29/$K29 -> 0.87322787
A30: Viga V2 - Oliveira (2007) | B30: 10 | C30: 628 | D30: 4 | E30: 32.466667 | F30: 3.514 | G30: 25 | H30: 36 | I30: 0.017444444 | J30: 246.62969 | K30: 0.24 | L30: =J30/200000 -> 0.0012331485 | P30: =$Q$2*($Q$3*$G30+$Q$4*$B30^$Q$5*$I30^$Q$6)*$L30^$Q$7 -> 0.20236354 | Q30: =P30/$K30 -> 0.84318141 | S30: =$T$2*$B30^$T$3*$L30^$T$4*($T$5*$I30^$T$6+$T$7) -> 0.19653812 | T30: =S30/$K30 -> 0.81890883
B31: 10 | C31: 628 | D31: 4 | E31: 32.466667 | F31: 3.514 | G31: 25 | H31: 36 | I31: 0.017444444 | J31: 335.69608 | K31: 0.3 | L31: =J31/200000 -> 0.0016784804 | P31: =$Q$2*($Q$3*$G31+$Q$4*$B31^$Q$5*$I31^$Q$6)*$L31^$Q$7 -> 0.26202409 | Q31: =P31/$K31 -> 0.87341364 | S31: =$T$2*$B31^$T$3*$L31^$T$4*($T$5*$I31^$T$6+$T$7) -> 0.25573971 | T31: =S31/$K31 -> 0.8524657
B32: 10 | C32: 628 | D32: 4 | E32: 32.466667 | F32: 3.514 | G32: 25 | H32: 36 | I32: 0.017444444 | J32: 361.50872 | K32: 0.3 | L32: =J32/200000 -> 0.0018075436 | P32: =$Q$2*($Q$3*$G32+$Q$4*$B32^$Q$5*$I32^$Q$6)*$L32^$Q$7 -> 0.27880579 | Q32: =P32/$K32 -> 0.92935263 | S32: =$T$2*$B32^$T$3*$L32^$T$4*($T$5*$I32^$T$6+$T$7) -> 0.27244164 | T32: =S32/$K32 -> 0.90813881
B33: 10 | C33: 628 | D33: 4 | E33: 32.466667 | F33: 3.514 | G33: 25 | H33: 36 | I33: 0.017444444 | J33: 392.91007 | K33: 0.3 | L33: =J33/200000 -> 0.0019645504 | P33: =$Q$2*($Q$3*$G33+$Q$4*$B33^$Q$5*$I33^$Q$6)*$L33^$Q$7 -> 0.29896195 | Q33: =P33/$K33 -> 0.99653985 | S33: =$T$2*$B33^$T$3*$L33^$T$4*($T$5*$I33^$T$6+$T$7) -> 0.29252731 | T33: =S33/$K33 -> 0.97509103
B34: 10 | C34: 628 | D34: 4 | E34: 32.466667 | F34: 3.514 | G34: 25 | H34: 36 | I34: 0.017444444 | J34: 424.16428 | K34: 0.38 | L34: =J34/200000 -> 0.0021208214 | P34: =$Q$2*($Q$3*$G34+$Q$4*$B34^$Q$5*$I34^$Q$6)*$L34^$Q$7 -> 0.31876588 | Q34: =P34/$K34 -> 0.83885757 | S34: =$T$2*$B34^$T$3*$L34^$T$4*($T$5*$I34^$T$6+$T$7) -> 0.31228719 | T34: =S34/$K34 -> 0.8218084
B35: 10 | C35: 628 | D35: 4 | E35: 32.466667 | F35: 3.514 | G35: 25 | H35: 36 | I35: 0.017444444 | J35: 491.13759 | K35: 0.44 | L35: =J35/200000 -> 0.0024556879 | P35: =$Q$2*($Q$3*$G35+$Q$4*$B35^$Q$5*$I35^$Q$6)*$L35^$Q$7 -> 0.36043463 | Q35: =P35/$K35 -> 0.81916962 | S35: =$T$2*$B35^$T$3*$L35^$T$4*($T$5*$I35^$T$6+$T$7) -> 0.35393831 | T35: =S35/$K35 -> 0.80440524
A36: Viga T1F000 - Silva Neto (2017) | B36: 16 | C36: 571 | D36: 4 | E36: 37 | F36: 4.2588 | G36: 33 | H36: 59 | I36: 0.1168 | J36: 104.26922 | K36: 0.18 | L36: =J36/200000 -> 0.00052134608 | P36: =$Q$2*($Q$3*$G36+$Q$4*$B36^$Q$5*$I36^$Q$6)*$L36^$Q$7 -> 0.064976028 | Q36: =P36/$K36 -> 0.36097793 | S36: =$T$2*$B36^$T$3*$L36^$T$4*($T$5*$I36^$T$6+$T$7) -> 0.06498886 | T36: =S36/$K36 -> 0.36104922
B37: 16 | C37: 571 | D37: 4 | E37: 37 | F37: 4.2588 | G37: 33 | H37: 59 | I37: 0.1168 | J37: 166.90492 | K37: 0.2 | L37: =J37/200000 -> 0.00083452461 | P37: =$Q$2*($Q$3*$G37+$Q$4*$B37^$Q$5*$I37^$Q$6)*$L37^$Q$7 -> 0.096375687 | Q37: =P37/$K37 -> 0.48187844 | S37: =$T$2*$B37^$T$3*$L37^$T$4*($T$5*$I37^$T$6+$T$7) -> 0.097123038 | T37: =S37/$K37 -> 0.48561519
B38: 16 | C38: 571 | D38: 4 | E38: 37 | F38: 4.2588 | G38: 33 | H38: 59 | I38: 0.1168 | J38: 214.45813 | K38: 0.26 | L38: =J38/200000 -> 0.0010722906 | P38: =$Q$2*($Q$3*$G38+$Q$4*$B38^$Q$5*$I38^$Q$6)*$L38^$Q$7 -> 0.11890589 | Q38: =P38/$K38 -> 0.45733034 | S38: =$T$2*$B38^$T$3*$L38^$T$4*($T$5*$I38^$T$6+$T$7) -> 0.12030955 | T38: =S38/$K38 -> 0.46272905
B39: 16 | C39: 571 | D39: 4 | E39: 37 | F39: 4.2588 | G39: 33 | H39: 59 | I39: 0.1168 | J39: 293.13707 | K39: 0.44 | L39: =J39/200000 -> 0.0014656853 | P39: =$Q$2*($Q$3*$G39+$Q$4*$B39^$Q$5*$I39^$Q$6)*$L39^$Q$7 -> 0.15450538 | Q39: =P39/$K39 -> 0.3511486 | S39: =$T$2*$B39^$T$3*$L39^$T$4*($T$5*$I39^$T$6+$T$7) -> 0.15711296 | T39: =S39/$K39 -> 0.35707491
B40: 16 | C40: 571 | D40: 4 | E40: 37 | F40: 4.2588 | G40: 33 | H40: 59 | I40: 0.1168 | J40: 408.12936 | K40: 0.6 | L40: =J40/200000 -> 0.0020406468 | P40: =$Q$2*($Q$3*$G40+$Q$4*$B40^$Q$5*$I40^$Q$6)*$L40^$Q$7 -> 0.20388578 | Q40: =P40/$K40 -> 0.33980963 | S40: =$T$2*$B40^$T$3*$L40^$T$4*($T$5*$I40^$T$6+$T$7) -> 0.20842747 | T40: =S40/$K40 -> 0.34737912
A41: Viga 12-20-00 - Caldentey et al (2013) | B41: 12 | C41: 500 | D41: 4 | E41: 79.3 | F41: 2.6933292 | G41: 20 | H41: 38 | I41: 0.013593985 | J41: 220.98185 | K41: 0.36 | L41: =J41/200000 -> 0.0011049092 | P41: =$Q$2*($Q$3*$G41+$Q$4*$B41^$Q$5*$I41^$Q$6)*$L41^$Q$7 -> 0.2543714 | Q41: =P41/$K41 -> 0.70658721 | S41: =$T$2*$B41^$T$3*$L41^$T$4*($T$5*$I41^$T$6+$T$7) -> 0.25438251 | T41: =S41/$K41 -> 0.7066181
...

Sheet Sem TS MC2010
A1: Autor | B1: Inputs | K1: Output
B2: Diâmetro da armadura f (mm) | C2: Resistência do aço - fy (MPa) | D2: Número de barras em uma camada | E2: Espaçamento entre as barras (mm) | F2: Resistência à tração do concreto fctm (MPa) | G2: Cobrimento c (mm) | H2: Distância ao centro de gravidade da armadura d' (mm) | I2: Taxa de armadura r | J2: Tensão na armadura (MPa) | K2: wexp (mm)
A3: Viga S200-1.76-20 - Sokolov et al (2021) | B3: 20 | C3: 500 | D3: 2 | E3: 126 | F3: 4.1203405 | G3: 25 | H3: 39 | I3: 0.060723546 | J3: 231.811 | K3: 0.16
B4: 20 | C4: 500 | D4: 2 | E4: 126 | F4: 4.1203405 | G4: 25 | H4: 39 | I4: 0.060723546 | J4: 304.25194 | K4: 0.23
B5: 20 | C5: 500 | D5: 2 | E5: 126 | F5: 4.1203405 | G5: 25 | H5: 39 | I5: 0.060723546 | J5: 314.28223 | K5: 0.24
B6: 20 | C6: 500 | D6: 2 | E6: 126 | F6: 4.1203405 | G6: 25 | H6: 39 | I6: 0.060723546 | J6: 363.31917 | K6: 0.27
B7: 20 | C7: 500 | D7: 2 | E7: 126 | F7: 4.1203405 | G7: 25 | H7: 39 | I7: 0.060723546 | J7: 459.16411 | K7: 0.35
B8: 20 | C8: 500 | D8: 2 | E8: 126 | F8: 4.1203405 | G8: 25 | H8: 39 | I8: 0.060723546 | J8: 500 | K8: 0.4
A9: Viga S600-0.37-10 - Sokolov et al (2021) | B9: 10 | C9: 500 | D9: 8 | E9: 87.7 | F9: 4.1311268 | G9: 25 | H9: 53 | I9: 0.015388385 | J9: 322.91972 | K9: 0.16
B10: 10 | C10: 500 | D10: 8 | E10: 87.7 | F10: 4.1311268 | G10: 25 | H10: 53 | I10: 0.015388385 | J10: 367.82093 | K10: 0.18
B11: 10 | C11: 500 | D11: 8 | E11: 87.7 | F11: 4.1311268 | G11: 25 | H11: 53 | I11: 0.015388385 | J11: 500 | K11: 0.26
A12: Viga V1 - Oliveira (2007) | B12: 10 | C12: 628 | D12: 4 | E12: 32.466667 | F12: 3.262 | G12: 25 | H12: 36 | I12: 0.017444444 | J12: 285.04803 | K12: 0.16
B13: 10 | C13: 628 | D13: 4 | E13: 32.466667 | F13: 3.262 | G13: 25 | H13: 36 | I13: 0.017444444 | J13: 324.99965 | K13: 0.2
B14: 10 | C14: 628 | D14: 4 | E14: 32.466667 | F14: 3.262 | G14: 25 | H14: 36 | I14: 0.017444444 | J14: 367.64463 | K14: 0.2
B15: 10 | C15: 628 | D15: 4 | E15: 32.466667 | F15: 3.262 | G15: 25 | H15: 36 | I15: 0.017444444 | J15: 410.7385 | K15: 0.24
B16: 10 | C16: 628 | D16: 4 | E16: 32.466667 | F16: 3.262 | G16: 25 | H16: 36 | I16: 0.017444444 | J16: 438.56996 | K16: 0.3
B17: 10 | C17: 628 | D17: 4 | E17: 32.466667 | F17: 3.262 | G17: 25 | H17: 36 | I17: 0.017444444 | J17: 498.27294 | K17: 0.32
B18: 10 | C18: 628 | D18: 4 | E18: 32.466667 | F18: 3.262 | G18: 25 | H18: 36 | I18: 0.017444444 | J18: 502.76188 | K18: 0.38
B19: 10 | C19: 628 | D19: 4 | E19: 32.466667 | F19: 3.262 | G19: 25 | H19: 36 | I19: 0.017444444 | J19: 538.67345 | K19: 0.42
B20: 10 | C20: 628 | D20: 4 | E20: 32.466667 | F20: 3.262 | G20: 25 | H20: 36 | I20: 0.017444444 | J20: 628 | K20: 0.44
B21: 10 | C21: 628 | D21: 4 | E21: 32.466667 | F21: 3.262 | G21: 25 | H21: 36 | I21: 0.017444444 | J21: 628 | K21: 0.5
A22: Viga V2 - Oliveira (2007) | B22: 10 | C22: 628 | D22: 4 | E22: 32.466667 | F22: 3.514 | G22: 25 | H22: 36 | I22: 0.017444444 | J22: 321.47188 | K22: 0.24
B23: 10 | C23: 628 | D23: 4 | E23: 32.466667 | F23: 3.514 | G23: 25 | H23: 36 | I23: 0.017444444 | J23: 357.19097 | K23: 0.3
B24: 10 | C24: 628 | D24: 4 | E24: 32.466667 | F24: 3.514 | G24: 25 | H24: 36 | I24: 0.017444444 | J24: 370.58564 | K24: 0.3
B25: 10 | C25: 628 | D25: 4 | E25: 32.466667 | F25: 3.514 | G25: 25 | H25: 36 | I25: 0.017444444 | J25: 392.91007 | K25: 0.3
B26: 10 | C26: 628 | D26: 4 | E26: 32.466667 | F26: 3.514 | G26: 25 | H26: 36 | I26: 0.017444444 | J26: 424.16428 | K26: 0.38
B27: 10 | C27: 628 | D27: 4 | E27: 32.466667 | F27: 3.514 | G27: 25 | H27: 36 | I27: 0.017444444 | J27: 491.13759 | K27: 0.44
A28: Viga T1F000 - Silva Neto (2017) | B28: 16 | C28: 571 | D28: 4 | E28: 37 | F28: 4.2588 | G28: 33 | H28: 59 | I28: 0.1168 | J28: 140.04197 | K28: 0.18
B29: 16 | C29: 571 | D29: 4 | E29: 37 | F29: 4.2588 | G29: 33 | H29: 59 | I29: 0.1168 | J29: 201.59887 | K29: 0.2
B30: 16 | C30: 571 | D30: 4 | E30: 37 | F30: 4.2588 | G30: 33 | H30: 59 | I30: 0.1168 | J30: 243.91925 | K30: 0.26
B31: 16 | C31: 571 | D31: 4 | E31: 37 | F31: 4.2588 | G31: 33 | H31: 59 | I31: 0.1168 | J31: 313.94023 | K31: 0.44
B32: 16 | C32: 571 | D32: 4 | E32: 37 | F32: 4.2588 | G32: 33 | H32: 59 | I32: 0.1168 | J32: 416.27859 | K32: 0.6
A33: Viga 12-20-00 - Caldentey et al (2013) | B33: 12 | C33: 500 | D33: 4 | E33: 79.3 | F33: 2.6933292 | G33: 20 | H33: 38 | I33: 0.013593985 | J33: 300.43296 | K33: 0.36
B34: 12 | C34: 500 | D34: 4 | E34: 79.3 | F34: 2.6933292 | G34: 20 | H34: 38 | I34: 0.013593985 | J34: 386.27094 | K34: 0.43
B35: 12 | C35: 500 | D35: 4 | E35: 79.3 | F35: 2.6933292 | G35: 20 | H35: 38 | I35: 0.013593985 | J35: 500 | K35: 0.56
B36: 12 | C36: 500 | D36: 4 | E36: 79.3 | F36: 2.6933292 | G36: 20 | H36: 38 | I36: 0.013593985 | J36: 500 | K36: 0.71
B37: 12 | C37: 500 | D37: 4 | E37: 79.3 | F37: 2.6933292 | G37: 20 | H37: 38 | I37: 0.013593985 | J37: 500 | K37: 0.79
A38: Viga 25-20-00 - Caldentey et al (2013) | B38: 25 | C38: 500 | D38: 4 | E38: 62 | F38: 2.6933292 | G38: 20 | H38: 44.5 | I38: 0.054467051 | J38: 106.51266 | K38: 0.2
B39: 25 | C39: 500 | D39: 4 | E39: 62 | F39: 2.6933292 | G39: 20 | H39: 44.5 | I39: 0.054467051 | J39: 191.72278 | K39: 0.25
B40: 25 | C40: 500 | D40: 4 | E40: 62 | F40: 2.6933292 | G40: 20 | H40: 44.5 | I40: 0.054467051 | J40: 276.9329 | K40: 0.36
...

Sheet Com TS variável MC2020
V1: Opção 3 de equação | Y1: Opção 4 de equação | AB1: Equações (13) e (15) do artigo Flexural cracking behavior and parametric analysis of steel-UHPC composite decks without longitudinal ribs (sem Tension stiffening). w=A1*(A2+A3*ft/(ro*Sigmas))*eps*(A4*c+A5*fi/ro)*(h-xii)/(h-xii-dl) | AO1: Equações (13) e (15) do artigo Flexural cracking behavior and parametric analysis of steel-UHPC composite decks without longitudinal ribs (sem Tension stiffening) + proposta de correção por fy. w=A1*(A2+A3*ft/(ro*Sigmas))*(A4*c+A5*fi/ro)*(Sigmas**A6/200000)*(h-xii)/(h-xii-dl)+(Sigmas-fy/A7)*(A4*c+A5*fi/ro)/200000
V2: A1 | W2: 0.515 | Y2: A1 | Z2: 0.391 | AB2: A1 | AC2: 1.22 | AO2: A1 | AP2: 7.37
V3: A2 | W3: -0.00169 | Y3: A2 | Z3: 0.701 | AB3: A2 | AC3: 1.93 | AO3: A2 | AP3: 4.87
V4: A3 | W4: 1 | Y4: A3 | Z4: 0.628 | AB4: A3 | AC4: -1.05 | AO4: A3 | AP4: -2.7
V5: A4 | W5: 0.672 | Y5: A4 | Z5: 0.389 | AB5: A4 | AC5: 0.568 | AO5: A4 | AP5: 0.09
V6: A5 | W6: -0.417 | Y6: A5 | Z6: -0.631 | AB6: A5 | AC6: 0.08 | AO6: A5 | AP6: 0.016
V7: A6 | W7: 0.617 | Y7: A6 | Z7: 2.011 | AO7: A6 | AP7: 0.82
AO8: A7 | AP8: 2
A9: Autor | B9: Inputs | Q9: Output
B10: Diâmetro da armadura (mm) | C10: Resistência do aço - fy (MPa) | D10: Número de barras em uma camada | E10: Espaçamento entre as barras (mm) | F10: Resistência à tração do concreto (MPa) | G10: Cobrimento (mm) | H10: Distância ao centro de gravidade da armadura (mm) | I10: Largura da viga - b (mm) | J10: Altura da viga - h (mm) | K10: Área de aço tracionada - As (mm2) | L10: Área de concreto efetiva - Ace (mm2) | M10: Linha neutra no Estádio II - XII (mm) | N10: Taxa de armadura | O10: Momento fletor - Ms (kNm) | P10: Tensão na armadura menos tension stiffening (MPa) | Q10: w (mm) | R10: Deformação na armadura menos tension stiffening | AD10: resíduo | AE10: Erro | AF10: wpred*Erro/wobs | AQ10: resíduo
A11: Viga S200-1.76-20 - Sokolov et al (2021) | B11: 20 | C11: 500 | D11: 2 | E11: 126 | F11: 4.1203405 | G11: 25 | H11: 39 | I11: 216 | J11: 201 | K11: 628 | L11: 29484 | M11: 57.361777 | N11: 0.021299688 | O11: 20.8 | P11: 120.52775 | Q11: 0.16 | R11: =P11/200000 -> 0.00060263873 | V11: =$W$2*($W$3*$G11+$W$4*$B11^$W$5*$N11^$W$6)*$R11^$W$7 -> 0.19768346 | W11: =V11/$Q11 -> 1.2355216 | Y11: =$Z$2*$B11^$Z$3*$R11^$Z$4*($Z$5*$N11^$Z$6+$Z$7) -> 0.1949344 | Z11: =Y11/$Q11 -> 1.21834 | AB11: =$AC$2*($AC$3+$AC$4*$F11/($N11*'Sem TS MC2020'!P3))*($AC$5*$G11+$AC$6*$B11/$N11)*'Sem TS MC2020'!R3*($J11-$M11)/($J11-$M11-$H11) -> 0.18269773 | AC11: =AB11/$Q11 -> 1.1418608 | AD11: =AB11-$Q11 -> 0.022697733 | AE11: =1/AC11 -> 0.87576347 | AF11: =AB11*(14.068*'Sem TS MC2020'!$P3^-0.457)/$Q11 -> 1.3334578 | AO11: =$AP$2*($AP$3+$AP$4*$F11/($N11*'Sem TS MC2020'!P3))*($AP$5*$G11+$AP$6*$B11/$N11)*('Sem TS MC2020'!P3^$AP$7/200000)*($J11-$M11)/($J11-$M11-$H11)+('Sem TS MC2020'!P3-$C11/$AP$8)*($AP$5*$G11+$AP$6*$B11/$N11)/200000 -> 0.19730926 | AP11: =AO11/$Q11 -> 1.2331829 | AQ11: =AO11-$Q11 -> 0.037309263
B12: 20 | C12: 500 | D12: 2 | E12: 126 | F12: 4.1203405 | G12: 25 | H12: 39 | I12: 216 | J12: 201 | K12: 628 | L12: 29484 | M12: 57.361777 | N12: 0.021299688 | O12: 27.3 | P12: 223.84798 | Q12: 0.23 | R12: =P12/200000 -> 0.0011192399 | V12: =$W$2*($W$3*$G12+$W$4*$B12^$W$5*$N12^$W$6)*$R12^$W$7 -> 0.28964147 | W12: =V12/$Q12 -> 1.2593108 | Y12: =$Z$2*$B12^$Z$3*$R12^$Z$4*($Z$5*$N12^$Z$6+$Z$7) -> 0.28756527 | Z12: =Y12/$Q12 -> 1.2502838 | AB12: =$AC$2*($AC$3+$AC$4*$F12/($N12*'Sem TS MC2020'!P4))*($AC$5*$G12+$AC$6*$B12/$N12)*'Sem TS MC2020'!R4*($J12-$M12)/($J12-$M12-$H12) -> 0.28726414 | AC12: =AB12/$Q12 -> 1.2489745 | AD12: =AB12-$Q12 -> 0.057264135 | AE12: =1/AC12 -> 0.80065686 | AF12: =AB12*(14.068*'Sem TS MC2020'!$P4^-0.457)/$Q12 -> 1.2880962 | AO12: =$AP$2*($AP$3+$AP$4*$F12/($N12*'Sem TS MC2020'!P4))*($AP$5*$G12+$AP$6*$B12/$N12)*('Sem TS MC2020'!P4^$AP$7/200000)*($J12-$M12)/($J12-$M12-$H12)+('Sem TS MC2020'!P4-$C12/$AP$8)*($AP$5*$G12+$AP$6*$B12/$N12)/200000 -> 0.30420253 | AP12: =AO12/$Q12 -> 1.3226197 | AQ12: =AO12-$Q12 -> 0.074202527
B13: 20 | C13: 500 | D13: 2 | E13: 126 | F13: 4.1203405 | G13: 25 | H13: 39 | I13: 216 | J13: 201 | K13: 628 | L13: 29484 | M13: 57.361777 | N13: 0.021299688 | O13: 28.2 | P13: 242.0522 | Q13: 0.24 | R13: =P13/200000 -> 0.001210261 | V13: =$W$2*($W$3*$G13+$W$4*$B13^$W$5*$N13^$W$6)*$R13^$W$7 -> 0.30395655 | W13: =V13/$Q13 -> 1.2664856 | Y13: =$Z$2*$B13^$Z$3*$R13^$Z$4*($Z$5*$N13^$Z$6+$Z$7) -> 0.30203739 | Z13: =Y13/$Q13 -> 1.2584891 | AB13: =$AC$2*($AC$3+$AC$4*$F13/($N13*'Sem TS MC2020'!P5))*($AC$5*$G13+$AC$6*$B13/$N13)*'Sem TS MC2020'!R5*($J13-$M13)/($J13-$M13-$H13) -> 0.30174256 | AC13: =AB13/$Q13 -> 1.2572607 | AD13: =AB13-$Q13 -> 0.06174256 | AE13: =1/AC13 -> 0.79538001 | AF13: =AB13*(14.068*'Sem TS MC2020'!$P5^-0.457)/$Q13 -> 1.2775636 | AO13: =$AP$2*($AP$3+$AP$4*$F13/($N13*'Sem TS MC2020'!P5))*($AP$5*$G13+$AP$6*$B13/$N13)*('Sem TS MC2020'!P5^$AP$7/200000)*($J13-$M13)/($J13-$M13-$H13)+('Sem TS MC2020'!P5-$C13/$AP$8)*($AP$5*$G13+$AP$6*$B13/$N13)/200000 -> 0.31848621 | AP13: =AO13/$Q13 -> 1.3270259 | AQ13: =AO13-$Q13 -> 0.078486208
B14: 20 | C14: 500 | D14: 2 | E14: 126 | F14: 4.1203405 | G14: 25 | H14: 39 | I14: 216 | J14: 201 | K14: 628 | L14: 29484 | M14: 57.361777 | N14: 0.021299688 | O14: 32.6 | P14: 325.14719 | Q14: 0.27 | R14: =P14/200000 -> 0.001625736 | V14: =$W$2*($W$3*$G14+$W$4*$B14^$W$5*$N14^$W$6)*$R14^$W$7 -> 0.36466409 | W14: =V14/$Q14 -> 1.3506077 | Y14: =$Z$2*$B14^$Z$3*$R14^$Z$4*($Z$5*$N14^$Z$6+$Z$7) -> 0.36353989 | Z14: =Y14/$Q14 -> 1.346444 | AB14: =$AC$2*($AC$3+$AC$4*$F14/($N14*'Sem TS MC2020'!P6))*($AC$5*$G14+$AC$6*$B14/$N14)*'Sem TS MC2020'!R6*($J14-$M14)/($J14-$M14-$H14) -> 0.37252597 | AC14: =AB14/$Q14 -> 1.3797258 | AD14: =AB14-$Q14 -> 0.10252597 | AE14: =1/AC14 -> 0.72478168 | AF14: =AB14*(14.068*'Sem TS MC2020'!$P6^-0.457)/$Q14 -> 1.3121195 | AO14: =$AP$2*($AP$3+$AP$4*$F14/($N14*'Sem TS MC2020'!P6))*($AP$5*$G14+$AP$6*$B14/$N14)*('Sem TS MC2020'!P6^$AP$7/200000)*($J14-$M14)/($J14-$M14-$H14)+('Sem TS MC2020'!P6-$C14/$AP$8)*($AP$5*$G14+$AP$6*$B14/$N14)/200000 -> 0.38687098 | AP14: =AO14/$Q14 -> 1.4328555 | AQ14: =AO14-$Q14 -> 0.11687098
B15: 20 | C15: 500 | D15: 2 | E15: 126 | F15: 4.1203405 | G15: 25 | H15: 39 | I15: 216 | J15: 201 | K15: 628 | L15: 29484 | M15: 57.361777 | N15: 0.021299688 | O15: 41.2 | P15: 447.78446 | Q15: 0.35 | R15: =P15/200000 -> 0.0022389223 | V15: =$W$2*($W$3*$G15+$W$4*$B15^$W$5*$N15^$W$6)*$R15^$W$7 -> 0.44427228 | W15: =V15/$Q15 -> 1.2693494 | Y15: =$Z$2*$B15^$Z$3*$R15^$Z$4*($Z$5*$N15^$Z$6+$Z$7) -> 0.4444646 | Z15: =Y15/$Q15 -> 1.2698988 | AB15: =$AC$2*($AC$3+$AC$4*$F15/($N15*'Sem TS MC2020'!P7))*($AC$5*$G15+$AC$6*$B15/$N15)*'Sem TS MC2020'!R7*($J15-$M15)/($J15-$M15-$H15) -> 0.51087536 | AC15: =AB15/$Q15 -> 1.4596439 | AD15: =AB15-$Q15 -> 0.16087536 | AE15: =1/AC15 -> 0.68509861 | AF15: =AB15*(14.068*'Sem TS MC2020'!$P7^-0.457)/$Q15 -> 1.2472684 | AO15: =$AP$2*($AP$3+$AP$4*$F15/($N15*'Sem TS MC2020'!P7))*($AP$5*$G15+$AP$6*$B15/$N15)*('Sem TS MC2020'!P7^$AP$7/200000)*($J15-$M15)/($J15-$M15-$H15)+('Sem TS MC2020'!P7-$C15/$AP$8)*($AP$5*$G15+$AP$6*$B15/$N15)/200000 -> 0.51490295 | AP15: =AO15/$Q15 -> 1.4711513 | AQ15: =AO15-$Q15 -> 0.16490295
B16: 20 | C16: 500 | D16: 2 | E16: 126 | F16: 4.1203405 | G16: 25 | H16: 39 | I16: 216 | J16: 201 | K16: 628 | L16: 29484 | M16: 57.361777 | N16: 0.021299688 | O16: 44.9 | P16: 500 | Q16: 0.4 | R16: =P16/200000 -> 0.0025 | V16: =$W$2*($W$3*$G16+$W$4*$B16^$W$5*$N16^$W$6)*$R16^$W$7 -> 0.4755587 | W16: =V16/$Q16 -> 1.1888967 | Y16: =$Z$2*$B16^$Z$3*$R16^$Z$4*($Z$5*$N16^$Z$6+$Z$7) -> 0.47634213 | Z16: =Y16/$Q16 -> 1.1908553 | AB16: =$AC$2*($AC$3+$AC$4*$F16/($N16*'Sem TS MC2020'!P8))*($AC$5*$G16+$AC$6*$B16/$N16)*'Sem TS MC2020'!R8*($J16-$M16)/($J16-$M16-$H16) -> 0.5698208 | AC16: =AB16/$Q16 -> 1.424552 | AD16: =AB16-$Q16 -> 0.1698208 | AE16: =1/AC16 -> 0.70197508 | AF16: =AB16*(14.068*'Sem TS MC2020'!$P8^-0.457)/$Q16 -> 1.1707964 | AO16: =$AP$2*($AP$3+$AP$4*$F16/($N16*'Sem TS MC2020'!P8))*($AP$5*$G16+$AP$6*$B16/$N16)*('Sem TS MC2020'!P8^$AP$7/200000)*($J16-$M16)/($J16-$M16-$H16)+('Sem TS MC2020'!P8-$C16/$AP$8)*($AP$5*$G16+$AP$6*$B16/$N16)/200000 -> 0.56764369 | AP16: =AO16/$Q16 -> 1.4191092 | AQ16: =AO16-$Q16 -> 0.16764369
A17: Viga S600-0.37-10 - Sokolov et al (2021) | B17: 10 | C17: 500 | D17: 8 | E17: 87.7 | F17: 4.1311268 | G17: 25 | H17: 53 | I17: 308 | J17: 604 | K17: 628 | L17: 43428 | M17: 99.6964 | N17: 0.014460717 | O17: 105 | P17: 224.98496 | Q17: 0.16 | R17: =P17/200000 -> 0.0011249248 | V17: =$W$2*($W$3*$G17+$W$4*$B17^$W$5*$N17^$W$6)*$R17^$W$7 -> 0.2142315 | W17: =V17/$Q17 -> 1.3389469 | Y17: =$Z$2*$B17^$Z$3*$R17^$Z$4*($Z$5*$N17^$Z$6+$Z$7) -> 0.2112024 | Z17: =Y17/$Q17 -> 1.320015 | AB17: =$AC$2*($AC$3+$AC$4*$F17/($N17*'Sem TS MC2020'!P9))*($AC$5*$G17+$AC$6*$B17/$N17)*'Sem TS MC2020'!R9*($J17-$M17)/($J17-$M17-$H17) -> 0.15319516 | AC17: =AB17/$Q17 -> 0.95746978 | AD17: =AB17-$Q17 -> -0.0068048354 | AE17: =1/AC17 -> 1.0444194 | AF17: =AB17*(14.068*'Sem TS MC2020'!$P9^-0.457)/$Q17 -> 0.96095095 | AO17: =$AP$2*($AP$3+$AP$4*$F17/($N17*'Sem TS MC2020'!P9))*($AP$5*$G17+$AP$6*$B17/$N17)*('Sem TS MC2020'!P9^$AP$7/200000)*($J17-$M17)/($J17-$M17-$H17)+('Sem TS MC2020'!P9-$C17/$AP$8)*($AP$5*$G17+$AP$6*$B17/$N17)/200000 -> 0.16014114 | AP17: =AO17/$Q17 -> 1.0008821 | AQ17: =AO17-$Q17 -> 0.00014113896
B18: 10 | C18: 500 | D18: 8 | E18: 87.7 | F18: 4.1311268 | G18: 25 | H18: 53 | I18: 308 | J18: 604 | K18: 628 | L18: 43428 | M18: 99.6964 | N18: 0.014460717 | O18: 119.6 | P18: 301.65384 | Q18: 0.18 | R18: =P18/200000 -> 0.0015082692 | V18: =$W$2*($W$3*$G18+$W$4*$B18^$W$5*$N18^$W$6)*$R18^$W$7 -> 0.25672111 | W18: =V18/$Q18 -> 1.4262284 | Y18: =$Z$2*$B18^$Z$3*$R18^$Z$4*($Z$5*$N18^$Z$6+$Z$7) -> 0.25390896 | Z18: =Y18/$Q18 -> 1.4106053 | AB18: =$AC$2*($AC$3+$AC$4*$F18/($N18*'Sem TS MC2020'!P10))*($AC$5*$G18+$AC$6*$B18/$N18)*'Sem TS MC2020'!R10*($J18-$M18)/($J18-$M18-$H18) -> 0.19426213 | AC18: =AB18/$Q18 -> 1.0792341 | AD18: =AB18-$Q18 -> 0.014262131 | AE18: =1/AC18 -> 0.92658306 | AF18: =AB18*(14.068*'Sem TS MC2020'!$P10^-0.457)/$Q18 -> 1.020592 | AO18: =$AP$2*($AP$3+$AP$4*$F18/($N18*'Sem TS MC2020'!P10))*($AP$5*$G18+$AP$6*$B18/$N18)*('Sem TS MC2020'!P10^$AP$7/200000)*($J18-$M18)/($J18-$M18-$H18)+('Sem TS MC2020'!P10-$C18/$AP$8)*($AP$5*$G18+$AP$6*$B18/$N18)/200000 -> 0.20092938 | AP18: =AO18/$Q18 -> 1.1162744 | AQ18: =AO18-$Q18 -> 0.020929385
B19: 10 | C19: 500 | D19: 8 | E19: 87.7 | F19: 4.1311268 | G19: 25 | H19: 53 | I19: 308 | J19: 604 | K19: 628 | L19: 43428 | M19: 99.6964 | N19: 0.014460717 | O19: 174.3 | P19: 497.36822 | Q19: 0.26 | R19: =P19/200000 -> 0.0024868411 | V19: =$W$2*($W$3*$G19+$W$4*$B19^$W$5*$N19^$W$6)*$R19^$W$7 -> 0.34950627 | W19: =V19/$Q19 -> 1.3442549 | Y19: =$Z$2*$B19^$Z$3*$R19^$Z$4*($Z$5*$N19^$Z$6+$Z$7) -> 0.34758439 | Z19: =Y19/$Q19 -> 1.336863 | AB19: =$AC$2*($AC$3+$AC$4*$F19/($N19*'Sem TS MC2020'!P11))*($AC$5*$G19+$AC$6*$B19/$N19)*'Sem TS MC2020'!R11*($J19-$M19)/($J19-$M19-$H19) -> 0.31515403 | AC19: =AB19/$Q19 -> 1.2121309 | AD19: =AB19-$Q19 -> 0.055154025 | AE19: =1/AC19 -> 0.82499343 | AF19: =AB19*(14.068*'Sem TS MC2020'!$P11^-0.457)/$Q19 -> 0.99621386 | AO19: =$AP$2*($AP$3+$AP$4*$F19/($N19*'Sem TS MC2020'!P11))*($AP$5*$G19+$AP$6*$B19/$N19)*('Sem TS MC2020'!P11^$AP$7/200000)*($J19-$M19)/($J19-$M19-$H19)+('Sem TS MC2020'!P11-$C19/$AP$8)*($AP$5*$G19+$AP$6*$B19/$N19)/200000 -> 0.31465649 | AP19: =AO19/$Q19 -> 1.2102173 | AQ19: =AO19-$Q19 -> 0.05465649
A20: Viga V1 - Oliveira (2007) | B20: 10 | C20: 628 | D20: 4 | E20: 32.466667 | F20: 3.262 | G20: 25 | H20: 36 | I20: 200 | J20: 600 | K20: 314 | L20: 17200 | M20: 95.721927 | N20: 0.018255814 | O20: 47.625 | P20: 178.11588 | Q20: 0.16 | R20: =P20/200000 -> 0.00089057942 | V20: =$W$2*($W$3*$G20+$W$4*$B20^$W$5*$N20^$W$6)*$R20^$W$7 -> 0.16827313 | W20: =V20/$Q20 -> 1.0517071 | Y20: =$Z$2*$B20^$Z$3*$R20^$Z$4*($Z$5*$N20^$Z$6+$Z$7) -> 0.16400319 | Z20: =Y20/$Q20 -> 1.0250199 | AB20: =$AC$2*($AC$3+$AC$4*$F20/($N20*'Sem TS MC2020'!P12))*($AC$5*$G20+$AC$6*$B20/$N20)*'Sem TS MC2020'!R12*($J20-$M20)/($J20-$M20-$H20) -> 0.1381736 | AC20: =AB20/$Q20 -> 0.86358503 | AD20: =AB20-$Q20 -> -0.021826395 | AE20: =1/AC20 -> 1.1579636 | AF20: =AB20*(14.068*'Sem TS MC2020'!$P12^-0.457)/$Q20 -> 0.9175715 | AO20: =$AP$2*($AP$3+$AP$4*$F20/($N20*'Sem TS MC2020'!P12))*($AP$5*$G20+$AP$6*$B20/$N20)*('Sem TS MC2020'!P12^$AP$7/200000)*($J20-$M20)/($J20-$M20-$H20)+('Sem TS MC2020'!P12-$C20/$AP$8)*($AP$5*$G20+$AP$6*$B20/$N20)/200000 -> 0.14151898 | AP20: =AO20/$Q20 -> 0.88449366 | AQ20: =AO20-$Q20 -> -0.018481015
B21: 10 | C21: 628 | D21: 4 | E21: 32.466667 | F21: 3.262 | G21: 25 | H21: 36 | I21: 200 | J21: 600 | K21: 314 | L21: 17200 | M21: 95.721927 | N21: 0.018255814 | O21: 54.3 | P21: 242.19704 | Q21: 0.2 | R21: =P21/200000 -> 0.0012109852 | V21: =$W$2*($W$3*$G21+$W$4*$B21^$W$5*$N21^$W$6)*$R21^$W$7 -> 0.20340584 | W21: =V21/$Q21 -> 1.0170292 | Y21: =$Z$2*$B21^$Z$3*$R21^$Z$4*($Z$5*$N21^$Z$6+$Z$7) -> 0.19891569 | Z21: =Y21/$Q21 -> 0.99457847 | AB21: =$AC$2*($AC$3+$AC$4*$F21/($N21*'Sem TS MC2020'!P13))*($AC$5*$G21+$AC$6*$B21/$N21)*'Sem TS MC2020'!R13*($J21-$M21)/($J21-$M21-$H21) -> 0.16756213 | AC21: =AB21/$Q21 -> 0.83781067 | AD21: =AB21-$Q21 -> -0.032437866 | AE21: =1/AC21 -> 1.1935871 | AF21: =AB21*(14.068*'Sem TS MC2020'!$P13^-0.457)/$Q21 -> 0.83839324 | AO21: =$AP$2*($AP$3+$AP$4*$F21/($N21*'Sem TS MC2020'!P13))*($AP$5*$G21+$AP$6*$B21/$N21)*('Sem TS MC2020'!P13^$AP$7/200000)*($J21-$M21)/($J21-$M21-$H21)+('Sem TS MC2020'!P13-$C21/$AP$8)*($AP$5*$G21+$AP$6*$B21/$N21)/200000 -> 0.17040509 | AP21: =AO21/$Q21 -> 0.85202543 | AQ21: =AO21-$Q21 -> -0.029594915
B22: 10 | C22: 628 | D22: 4 | E22: 32.466667 | F22: 3.262 | G22: 25 | H22: 36 | I22: 200 | J22: 600 | K22: 314 | L22: 17200 | M22: 95.721927 | N22: 0.018255814 | O22: 61.425 | P22: 308.13373 | Q22: 0.2 | R22: =P22/200000 -> 0.0015406687 | V22: =$W$2*($W$3*$G22+$W$4*$B22^$W$5*$N22^$W$6)*$R22^$W$7 -> 0.23598443 | W22: =V22/$Q22 -> 1.1799222 | Y22: =$Z$2*$B22^$Z$3*$R22^$Z$4*($Z$5*$N22^$Z$6+$Z$7) -> 0.23138717 | Z22: =Y22/$Q22 -> 1.1569358 | AB22: =$AC$2*($AC$3+$AC$4*$F22/($N22*'Sem TS MC2020'!P14))*($AC$5*$G22+$AC$6*$B22/$N22)*'Sem TS MC2020'!R14*($J22-$M22)/($J22-$M22-$H22) -> 0.19893191 | AC22: =AB22/$Q22 -> 0.99465956 | AD22: =AB22-$Q22 -> -0.0010680871 | AE22: =1/AC22 -> 1.0053691 | AF22: =AB22*(14.068*'Sem TS MC2020'!$P14^-0.457)/$Q22 -> 0.9408191 | AO22: =$AP$2*($AP$3+$AP$4*$F22/($N22*'Sem TS MC2020'!P14))*($AP$5*$G22+$AP$6*$B22/$N22)*('Sem TS MC2020'!P14^$AP$7/200000)*($J22-$M22)/($J22-$M22-$H22)+('Sem TS MC2020'!P14-$C22/$AP$8)*($AP$5*$G22+$AP$6*$B22/$N22)/200000 -> 0.20037279 | AP22: =AO22/$Q22 -> 1.0018639 | AQ22: =AO22-$Q22 -> 0.0003727879
B23: 10 | C23: 628 | D23: 4 | E23: 32.466667 | F23: 3.262 | G23: 25 | H23: 36 | I23: 200 | J23: 600 | K23: 314 | L23: 17200 | M23: 95.721927 | N23: 0.018255814 | O23: 68.625 | P23: 368.31936 | Q23: 0.24 | R23: =P23/200000 -> 0.0018415968 | V23: =$W$2*($W$3*$G23+$W$4*$B23^$W$5*$N23^$W$6)*$R23^$W$7 -> 0.26344611 | W23: =V23/$Q23 -> 1.0976921 | Y23: =$Z$2*$B23^$Z$3*$R23^$Z$4*($Z$5*$N23^$Z$6+$Z$7) -> 0.25882132 | Z23: =Y23/$Q23 -> 1.0784222 | AB23: =$AC$2*($AC$3+$AC$4*$F23/($N23*'Sem TS MC2020'!P15))*($AC$5*$G23+$AC$6*$B23/$N23)*'Sem TS MC2020'!R15*($J23-$M23)/($J23-$M23-$H23) -> 0.2306319 | AC23: =AB23/$Q23 -> 0.96096625 | AD23: =AB23-$Q23 -> -0.0093681003 | AE23: =1/AC23 -> 1.0406193 | AF23: =AB23*(14.068*'Sem TS MC2020'!$P15^-0.457)/$Q23 -> 0.86405443 | AO23: =$AP$2*($AP$3+$AP$4*$F23/($N23*'Sem TS MC2020'!P15))*($AP$5*$G23+$AP$6*$B23/$N23)*('Sem TS MC2020'!P15^$AP$7/200000)*($J23-$M23)/($J23-$M23-$H23)+('Sem TS MC2020'!P15-$C23/$AP$8)*($AP$5*$G23+$AP$6*$B23/$N23)/200000 -> 0.22989655 | AP23: =AO23/$Q23 -> 0.9579023 | AQ23: =AO23-$Q23 -> -0.010103449
B24: 10 | C24: 628 | D24: 4 | E24: 32.466667 | F24: 3.262 | G24: 25 | H24: 36 | I24: 200 | J24: 600 | K24: 314 | L24: 17200 | M24: 95.721927 | N24: 0.018255814 | O24: 73.275 | P24: 401.01025 | Q24: 0.3 | R24: =P24/200000 -> 0.0020050512 | V24: =$W$2*($W$3*$G24+$W$4*$B24^$W$5*$N24^$W$6)*$R24^$W$7 -> 0.27763753 | W24: =V24/$Q24 -> 0.92545842 | Y24: =$Z$2*$B24^$Z$3*$R24^$Z$4*($Z$5*$N24^$Z$6+$Z$7) -> 0.27301887 | Z24: =Y24/$Q24 -> 0.91006289 | AB24: =$AC$2*($AC$3+$AC$4*$F24/($N24*'Sem TS MC2020'!P16))*($AC$5*$G24+$AC$6*$B24/$N24)*'Sem TS MC2020'!R16*($J24-$M24)/($J24-$M24-$H24) -> 0.25110481 | AC24: =AB24/$Q24 -> 0.83701603 | AD24: =AB24-$Q24 -> -0.048895192 | AE24: =1/AC24 -> 1.1947203 | AF24: =AB24*(14.068*'Sem TS MC2020'!$P16^-0.457)/$Q24 -> 0.73038923 | AO24: =$AP$2*($AP$3+$AP$4*$F24/($N24*'Sem TS MC2020'!P16))*($AP$5*$G24+$AP$6*$B24/$N24)*('Sem TS MC2020'!P16^$AP$7/200000)*($J24-$M24)/($J24-$M24-$H24)+('Sem TS MC2020'!P16-$C24/$AP$8)*($AP$5*$G24+$AP$6*$B24/$N24)/200000 -> 0.24861266 | AP24: =AO24/$Q24 -> 0.82870885 | AQ24: =AO24-$Q24 -> -0.051387344
B25: 10 | C25: 628 | D25: 4 | E25: 32.466667 | F25: 3.262 | G25: 25 | H25: 36 | I25: 200 | J25: 600 | K25: 314 | L25: 17200 | M25: 95.721927 | N25: 0.018255814 | O25: 83.25 | P25: 498.05773 | Q25: 0.32 | R25: =P25/200000 -> 0.0024902886 | V25: =$W$2*($W$3*$G25+$W$4*$B25^$W$5*$N25^$W$6)*$R25^$W$7 -> 0.31736045 | W25: =V25/$Q25 -> 0.99175142 | Y25: =$Z$2*$B25^$Z$3*$R25^$Z$4*($Z$5*$N25^$Z$6+$Z$7) -> 0.31282587 | Z25: =Y25/$Q25 -> 0.97758086 | AB25: =$AC$2*($AC$3+$AC$4*$F25/($N25*'Sem TS MC2020'!P17))*($AC$5*$G25+$AC$6*$B25/$N25)*'Sem TS MC2020'!R17*($J25-$M25)/($J25-$M25-$H25) -> 0.2950225 | AC25: =AB25/$Q25 -> 0.92194531 | AD25: =AB25-$Q25 -> -0.024977502 | AE25: =1/AC25 -> 1.084663 | AF25: =AB25*(14.068*'Sem TS MC2020'!$P17^-0.457)/$Q25 -> 0.75891819 | AO25: =$AP$2*($AP$3+$AP$4*$F25/($N25*'Sem TS MC2020'!P17))*($AP$5*$G25+$AP$6*$B25/$N25)*('Sem TS MC2020'!P17^$AP$7/200000)*($J25-$M25)/($J25-$M25-$H25)+('Sem TS MC2020'!P17-$C25/$AP$8)*($AP$5*$G25+$AP$6*$B25/$N25)/200000 -> 0.28795738 | AP25: =AO25/$Q25 -> 0.89986681 | AQ25: =AO25-$Q25 -> -0.03204262
B26: 10 | C26: 628 | D26: 4 | E26: 32.466667 | F26: 3.262 | G26: 25 | H26: 36 | I26: 200 | J26: 600 | K26: 314 | L26: 17200 | M26: 95.721927 | N26: 0.018255814 | O26: 84 | P26: 502.76188 | Q26: 0.38 | R26: =P26/200000 -> 0.0025138094 | V26: =$W$2*($W$3*$G26+$W$4*$B26^$W$5*$N26^$W$6)*$R26^$W$7 -> 0.31920656 | W26: =V26/$Q26 -> 0.84001726 | Y26: =$Z$2*$B26^$Z$3*$R26^$Z$4*($Z$5*$N26^$Z$6+$Z$7) -> 0.31467814 | Z26: =Y26/$Q26 -> 0.82810038 | AB26: =$AC$2*($AC$3+$AC$4*$F26/($N26*'Sem TS MC2020'!P18))*($AC$5*$G26+$AC$6*$B26/$N26)*'Sem TS MC2020'!R18*($J26-$M26)/($J26-$M26-$H26) -> 0.29832458 | AC26: =AB26/$Q26 -> 0.78506468 | AD26: =AB26-$Q26 -> -0.08167542 | AE26: =1/AC26 -> 1.2737804 | AF26: =AB26*(14.068*'Sem TS MC2020'!$P18^-0.457)/$Q26 -> 0.64359878 | AO26: =$AP$2*($AP$3+$AP$4*$F26/($N26*'Sem TS MC2020'!P18))*($AP$5*$G26+$AP$6*$B26/$N26)*('Sem TS MC2020'!P18^$AP$7/200000)*($J26-$M26)/($J26-$M26-$H26)+('Sem TS MC2020'!P18-$C26/$AP$8)*($AP$5*$G26+$AP$6*$B26/$N26)/200000 -> 0.29087529 | AP26: =AO26/$Q26 -> 0.76546129 | AQ26: =AO26-$Q26 -> -0.089124711
B27: 10 | C27: 628 | D27: 4 | E27: 32.466667 | F27: 3.262 | G27: 25 | H27: 36 | I27: 200 | J27: 600 | K27: 314 | L27: 17200 | M27: 95.721927 | N27: 0.018255814 | O27: 90 | P27: 538.67345 | Q27: 0.42 | R27: =P27/200000 -> 0.0026933672 | V27: =$W$2*($W$3*$G27+$W$4*$B27^$W$5*$N27^$W$6)*$R27^$W$7 -> 0.3330881 | W27: =V27/$Q27 -> 0.79306691 | Y27: =$Z$2*$B27^$Z$3*$R27^$Z$4*($Z$5*$N27^$Z$6+$Z$7) -> 0.32861205 | Z27: =Y27/$Q27 -> 0.78240964 | AB27: =$AC$2*($AC$3+$AC$4*$F27/($N27*'Sem TS MC2020'!P19))*($AC$5*$G27+$AC$6*$B27/$N27)*'Sem TS MC2020'!R19*($J27-$M27)/($J27-$M27-$H27) -> 0.32474124 | AC27: =AB27/$Q27 -> 0.77319342 | AD27: =AB27-$Q27 -> -0.095258764 | AE27: =1/AC27 -> 1.2933374 | AF27: =AB27*(14.068*'Sem TS MC2020'!$P19^-0.457)/$Q27 -> 0.6141928 | AO27: =$AP$2*($AP$3+$AP$4*$F27/($N27*'Sem TS MC2020'!P19))*($AP$5*$G27+$AP$6*$B27/$N27)*('Sem TS MC2020'!P19^$AP$7/200000)*($J27-$M27)/($J27-$M27-$H27)+('Sem TS MC2020'!P19-$C27/$AP$8)*($AP$5*$G27+$AP$6*$B27/$N27)/200000 -> 0.31403394 | AP27: =AO27/$Q27 -> 0.74769985 | AQ27: =AO27-$Q27 -> -0.10596606
B28: 10 | C28: 628 | D28: 4 | E28: 32.466667 | F28: 3.262 | G28: 25 | H28: 36 | I28: 200 | J28: 600 | K28: 314 | L28: 17200 | M28: 95.721927 | N28: 0.018255814 | O28: 108 | P28: 628 | Q28: 0.44 | R28: =P28/200000 -> 0.00314 | V28: =$W$2*($W$3*$G28+$W$4*$B28^$W$5*$N28^$W$6)*$R28^$W$7 -> 0.36616122 | W28: =V28/$Q28 -> 0.83218458 | Y28: =$Z$2*$B28^$Z$3*$R28^$Z$4*($Z$5*$N28^$Z$6+$Z$7) -> 0.36185092 | Z28: =Y28/$Q28 -> 0.82238846 | AB28: =$AC$2*($AC$3+$AC$4*$F28/($N28*'Sem TS MC2020'!P20))*($AC$5*$G28+$AC$6*$B28/$N28)*'Sem TS MC2020'!R20*($J28-$M28)/($J28-$M28-$H28) -> 0.39045012 | AC28: =AB28/$Q28 -> 0.88738664 | AD28: =AB28-$Q28 -> -0.049549879 | AE28: =1/AC28 -> 1.1269045 | AF28: =AB28*(14.068*'Sem TS MC2020'!$P20^-0.457)/$Q28 -> 0.65716994 | AO28: =$AP$2*($AP$3+$AP$4*$F28/($N28*'Sem TS MC2020'!P20))*($AP$5*$G28+$AP$6*$B28/$N28)*('Sem TS MC2020'!P20^$AP$7/200000)*($J28-$M28)/($J28-$M28-$H28)+('Sem TS MC2020'!P20-$C28/$AP$8)*($AP$5*$G28+$AP$6*$B28/$N28)/200000 -> 0.37036258 | AP28: =AO28/$Q28 -> 0.84173314 | AQ28: =AO28-$Q28 -> -0.069637417
B29: 10 | C29: 628 | D29: 4 | E29: 32.466667 | F29: 3.262 | G29: 25 | H29: 36 | I29: 200 | J29: 600 | K29: 314 | L29: 17200 | M29: 95.721927 | N29: 0.018255814 | O29: 120 | P29: 628 | Q29: 0.5 | R29: =P29/200000 -> 0.00314 | V29: =$W$2*($W$3*$G29+$W$4*$B29^$W$5*$N29^$W$6)*$R29^$W$7 -> 0.36616122 | W29: =V29/$Q29 -> 0.73232243 | Y29: =$Z$2*$B29^$Z$3*$R29^$Z$4*($Z$5*$N29^$Z$6+$Z$7) -> 0.36185092 | Z29: =Y29/$Q29 -> 0.72370184 | AB29: =$AC$2*($AC$3+$AC$4*$F29/($N29*'Sem TS MC2020'!P21))*($AC$5*$G29+$AC$6*$B29/$N29)*'Sem TS MC2020'!R21*($J29-$M29)/($J29-$M29-$H29) -> 0.39045012 | AC29: =AB29/$Q29 -> 0.78090024 | AD29: =AB29-$Q29 -> -0.10954988 | AE29: =1/AC29 -> 1.2805733 | AF29: =AB29*(14.068*'Sem TS MC2020'!$P21^-0.457)/$Q29 -> 0.57830954 | AO29: =$AP$2*($AP$3+$AP$4*$F29/($N29*'Sem TS MC2020'!P21))*($AP$5*$G29+$AP$6*$B29/$N29)*('Sem TS MC2020'!P21^$AP$7/200000)*($J29-$M29)/($J29-$M29-$H29)+('Sem TS MC2020'!P21-$C29/$AP$8)*($AP$5*$G29+$AP$6*$B29/$N29)/200000 -> 0.37036258 | AP29: =AO29/$Q29 -> 0.74072517 | AQ29: =AO29-$Q29 -> -0.12963742
A30: Viga V2 - Oliveira (2007) | B30: 10 | C30: 628 | D30: 4 | E30: 32.466667 | F30: 3.514 | G30: 25 | H30: 36 | I30: 200 | J30: 600 | K30: 314 | L30: 17200 | M30: 87.120679 | N30: 0.018255814 | O30: 54 | P30: 249.68578 | Q30: 0.24 | R30: =P30/200000 -> 0.0012484289 | V30: =$W$2*($W$3*$G30+$W$4*$B30^$W$5*$N30^$W$6)*$R30^$W$7 -> 0.20726369 | W30: =V30/$Q30 -> 0.86359871 | Y30: =$Z$2*$B30^$Z$3*$R30^$Z$4*($Z$5*$N30^$Z$6+$Z$7) -> 0.20275629 | Z30: =Y30/$Q30 -> 0.84481789 | AB30: =$AC$2*($AC$3+$AC$4*$F30/($N30*'Sem TS MC2020'!P22))*($AC$5*$G30+$AC$6*$B30/$N30)*'Sem TS MC2020'!R22*($J30-$M30)/($J30-$M30-$H30) -> 0.15923753 | AC30: =AB30/$Q30 -> 0.66348969 | AD30: =AB30-$Q30 -> -0.080762474 | AE30: =1/AC30 -> 1.5071824 | AF30: =AB30*(14.068*'Sem TS MC2020'!$P22^-0.457)/$Q30 -> 0.66727091 | AO30: =$AP$2*($AP$3+$AP$4*$F30/($N30*'Sem TS MC2020'!P22))*($AP$5*$G30+$AP$6*$B30/$N30)*('Sem TS MC2020'!P22^$AP$7/200000)*($J30-$M30)/($J30-$M30-$H30)+('Sem TS MC2020'!P22-$C30/$AP$8)*($AP$5*$G30+$AP$6*$B30/$N30)/200000 -> 0.16191714 | AP30: =AO30/$Q30 -> 0.67465473 | AQ30: =AO30-$Q30 -> -0.078082865
B31: 10 | C31: 628 | D31: 4 | E31: 32.466667 | F31: 3.514 | G31: 25 | H31: 36 | I31: 200 | J31: 600 | K31: 314 | L31: 17200 | M31: 87.120679 | N31: 0.018255814 | O31: 60 | P31: 336.5738 | Q31: 0.3 | R31: =P31/200000 -> 0.001682869 | V31: =$W$2*($W$3*$G31+$W$4*$B31^$W$5*$N31^$W$6)*$R31^$W$7 -> 0.24919527 | W31: =V31/$Q31 -> 0.83065089 | Y31: =$Z$2*$B31^$Z$3*$R31^$Z$4*($Z$5*$N31^$Z$6+$Z$7) -> 0.24457804 | Z31: =Y31/$Q31 -> 0.81526012 | AB31: =$AC$2*($AC$3+$AC$4*$F31/($N31*'Sem TS MC2020'!P23))*($AC$5*$G31+$AC$6*$B31/$N31)*'Sem TS MC2020'!R23*($J31-$M31)/($J31-$M31-$H31) -> 0.18547877 | AC31: =AB31/$Q31 -> 0.61826257 | AD31: =AB31-$Q31 -> -0.11452123 | AE31: =1/AC31 -> 1.6174358 | AF31: =AB31*(14.068*'Sem TS MC2020'!$P23^-0.457)/$Q31 -> 0.59255654 | AO31: =$AP$2*($AP$3+$AP$4*$F31/($N31*'Sem TS MC2020'!P23))*($AP$5*$G31+$AP$6*$B31/$N31)*('Sem TS MC2020'!P23^$AP$7/200000)*($J31-$M31)/($J31-$M31-$H31)+('Sem TS MC2020'!P23-$C31/$AP$8)*($AP$5*$G31+$AP$6*$B31/$N31)/200000 -> 0.187208 | AP31: =AO31/$Q31 -> 0.62402667 | AQ31: =AO31-$Q31 -> -0.112792
B32: 10 | C32: 628 | D32: 4 | E32: 32.466667 | F32: 3.514 | G32: 25 | H32: 36 | I32: 200 | J32: 600 | K32: 314 | L32: 17200 | M32: 87.120679 | N32: 0.018255814 | O32: 62.25 | P32: 361.87936 | Q32: 0.3 | R32: =P32/200000 -> 0.0018093968 | V32: =$W$2*($W$3*$G32+$W$4*$B32^$W$5*$N32^$W$6)*$R32^$W$7 -> 0.26059442 | W32: =V32/$Q32 -> 0.86864808 | Y32: =$Z$2*$B32^$Z$3*$R32^$Z$4*($Z$5*$N32^$Z$6+$Z$7) -> 0.25597002 | Z32: =Y32/$Q32 -> 0.8532334 | AB32: =$AC$2*($AC$3+$AC$4*$F32/($N32*'Sem TS MC2020'!P24))*($AC$5*$G32+$AC$6*$B32/$N32)*'Sem TS MC2020'!R24*($J32-$M32)/($J32-$M32-$H32) -> 0.19531924 | AC32: =AB32/$Q32 -> 0.65106413 | AD32: =AB32-$Q32 -> -0.10468076 | AE32: =1/AC32 -> 1.535947 | AF32: =AB32*(14.068*'Sem TS MC2020'!$P24^-0.457)/$Q32 -> 0.61358403 | AO32: =$AP$2*($AP$3+$AP$4*$F32/($N32*'Sem TS MC2020'!P24))*($AP$5*$G32+$AP$6*$B32/$N32)*('Sem TS MC2020'!P24^$AP$7/200000)*($J32-$M32)/($J32-$M32-$H32)+('Sem TS MC2020'!P24-$C32/$AP$8)*($AP$5*$G32+$AP$6*$B32/$N32)/200000 -> 0.19654385 | AP32: =AO32/$Q32 -> 0.65514615 | AQ32: =AO32-$Q32 -> -0.10345615
B33: 10 | C33: 628 | D33: 4 | E33: 32.466667 | F33: 3.514 | G33: 25 | H33: 36 | I33: 200 | J33: 600 | K33: 314 | L33: 17200 | M33: 87.120679 | N33: 0.018255814 | O33: 66 | P33: 392.91007 | Q33: 0.3 | R33: =P33/200000 -> 0.0019645504 | V33: =$W$2*($W$3*$G33+$W$4*$B33^$W$5*$N33^$W$6)*$R33^$W$7 -> 0.27416381 | W33: =V33/$Q33 -> 0.91387936 | Y33: =$Z$2*$B33^$Z$3*$R33^$Z$4*($Z$5*$N33^$Z$6+$Z$7) -> 0.26954242 | Z33: =Y33/$Q33 -> 0.89847475 | AB33: =$AC$2*($AC$3+$AC$4*$F33/($N33*'Sem TS MC2020'!P25))*($AC$5*$G33+$AC$6*$B33/$N33)*'Sem TS MC2020'!R25*($J33-$M33)/($J33-$M33-$H33) -> 0.21172002 | AC33: =AB33/$Q33 -> 0.70573339 | AD33: =AB33-$Q33 -> -0.088279984 | AE33: =1/AC33 -> 1.4169657 | AF33: =AB33*(14.068*'Sem TS MC2020'!$P25^-0.457)/$Q33 -> 0.64756154 | AO33: =$AP$2*($AP$3+$AP$4*$F33/($N33*'Sem TS MC2020'!P25))*($AP$5*$G33+$AP$6*$B33/$N33)*('Sem TS MC2020'!P25^$AP$7/200000)*($J33-$M33)/($J33-$M33-$H33)+('Sem TS MC2020'!P25-$C33/$AP$8)*($AP$5*$G33+$AP$6*$B33/$N33)/200000 -> 0.21194075 | AP33: =AO33/$Q33 -> 0.70646917 | AQ33: =AO33-$Q33 -> -0.08805925
B34: 10 | C34: 628 | D34: 4 | E34: 32.466667 | F34: 3.514 | G34: 25 | H34: 36 | I34: 200 | J34: 600 | K34: 314 | L34: 17200 | M34: 87.120679 | N34: 0.018255814 | O34: 71.25 | P34: 424.16428 | Q34: 0.38 | R34: =P34/200000 -> 0.0021208214 | V34: =$W$2*($W$3*$G34+$W$4*$B34^$W$5*$N34^$W$6)*$R34^$W$7 -> 0.28742185 | W34: =V34/$Q34 -> 0.75637329 | Y34: =$Z$2*$B34^$Z$3*$R34^$Z$4*($Z$5*$N34^$Z$6+$Z$7) -> 0.282815 | Z34: =Y34/$Q34 -> 0.74424999 | AB34: =$AC$2*($AC$3+$AC$4*$F34/($N34*'Sem TS MC2020'!P26))*($AC$5*$G34+$AC$6*$B34/$N34)*'Sem TS MC2020'!R26*($J34-$M34)/($J34-$M34-$H34) -> 0.23468111 | AC34: =AB34/$Q34 -> 0.61758186 | AD34: =AB34-$Q34 -> -0.14531889 | AE34: =1/AC34 -> 1.6192186 | AF34: =AB34*(14.068*'Sem TS MC2020'!$P26^-0.457)/$Q34 -> 0.54719713 | AO34: =$AP$2*($AP$3+$AP$4*$F34/($N34*'Sem TS MC2020'!P26))*($AP$5*$G34+$AP$6*$B34/$N34)*('Sem TS MC2020'!P26^$AP$7/200000)*($J34-$M34)/($J34-$M34-$H34)+('Sem TS MC2020'!P26-$C34/$AP$8)*($AP$5*$G34+$AP$6*$B34/$N34)/200000 -> 0.23318211 | AP34: =AO34/$Q34 -> 0.61363714 | AQ34: =AO34-$Q34 -> -0.14681789
B35: 10 | C35: 628 | D35: 4 | E35: 32.466667 | F35: 3.514 | G35: 25 | H35: 36 | I35: 200 | J35: 600 | K35: 314 | L35: 17200 | M35: 87.120679 | N35: 0.018255814 | O35: 82.5 | P35: 491.13759 | Q35: 0.44 | R35: =P35/200000 -> 0.0024556879 | V35: =$W$2*($W$3*$G35+$W$4*$B35^$W$5*$N35^$W$6)*$R35^$W$7 -> 0.31463251 | W35: =V35/$Q35 -> 0.7150739 | Y35: =$Z$2*$B35^$Z$3*$R35^$Z$4*($Z$5*$N35^$Z$6+$Z$7) -> 0.31008918 | Z35: =Y35/$Q35 -> 0.70474815 | AB35: =$AC$2*($AC$3+$AC$4*$F35/($N35*'Sem TS MC2020'!P27))*($AC$5*$G35+$AC$6*$B35/$N35)*'Sem TS MC2020'!R27*($J35-$M35)/($J35-$M35-$H35) -> 0.28388344 | AC35: =AB35/$Q35 -> 0.64518964 | AD35: =AB35-$Q35 -> -0.15611656 | AE35: =1/AC35 -> 1.5499319 | AF35: =AB35*(14.068*'Sem TS MC2020'!$P27^-0.457)/$Q35 -> 0.53461346 | AO35: =$AP$2*($AP$3+$AP$4*$F35/($N35*'Sem TS MC2020'!P27))*($AP$5*$G35+$AP$6*$B35/$N35)*('Sem TS MC2020'!P27^$AP$7/200000)*($J35-$M35)/($J35-$M35-$H35)+('Sem TS MC2020'!P27-$C35/$AP$8)*($AP$5*$G35+$AP$6*$B35/$N35)/200000 -> 0.27762328 | AP35: =AO35/$Q35 -> 0.630962 | AQ35: =AO35-$Q35 -> -0.16237672
A36: Viga T1F000 - Silva Neto (2017) | B36: 16 | C36: 571 | D36: 4 | E36: 37 | F36: 4.2588 | G36: 33 | H36: 59 | I36: 125 | J36: 250 | K36: 800 | L36: 19625 | M36: 87.082519 | N36: 0.0408 | O36: 18.2 | P36: 63.458454 | Q36: 0.18 | R36: =P36/200000 -> 0.00031729227 | V36: =$W$2*($W$3*$G36+$W$4*$B36^$W$5*$N36^$W$6)*$R36^$W$7 -> 0.087244867 | W36: =V36/$Q36 -> 0.48469371 | Y36: =$Z$2*$B36^$Z$3*$R36^$Z$4*($Z$5*$N36^$Z$6+$Z$7) -> 0.085674437 | Z36: =Y36/$Q36 -> 0.4759691 | AB36: =$AC$2*($AC$3+$AC$4*$F36/($N36*'Sem TS MC2020'!P28))*($AC$5*$G36+$AC$6*$B36/$N36)*'Sem TS MC2020'!R28*($J36-$M36)/($J36-$M36-$H36) -> 0.077010617 | AC36: =AB36/$Q36 -> 0.42783676 | AD36: =AB36-$Q36 -> -0.10298938 | AE36: =1/AC36 -> 2.3373401 | AF36: =AB36*(14.068*'Sem TS MC2020'!$P28^-0.457)/$Q36 -> 0.6290287 | AO36: =$AP$2*($AP$3+$AP$4*$F36/($N36*'Sem TS MC2020'!P28))*($AP$5*$G36+$AP$6*$B36/$N36)*('Sem TS MC2020'!P28^$AP$7/200000)*($J36-$M36)/($J36-$M36-$H36)+('Sem TS MC2020'!P28-$C36/$AP$8)*($AP$5*$G36+$AP$6*$B36/$N36)/200000 -> 0.081081852 | AP36: =AO36/$Q36 -> 0.45045473 | AQ36: =AO36-$Q36 -> -0.098918148
B37: 16 | C37: 571 | D37: 4 | E37: 37 | F37: 4.2588 | G37: 33 | H37: 59 | I37: 125 | J37: 250 | K37: 800 | L37: 19625 | M37: 87.082519 | N37: 0.0408 | O37: 26.2 | P37: 132.58577 | Q37: 0.2 | R37: =P37/200000 -> 0.00066292885 | V37: =$W$2*($W$3*$G37+$W$4*$B37^$W$5*$N37^$W$6)*$R37^$W$7 -> 0.13746257 | W37: =V37/$Q37 -> 0.68731286 | Y37: =$Z$2*$B37^$Z$3*$R37^$Z$4*($Z$5*$N37^$Z$6+$Z$7) -> 0.13608678 | Z37: =Y37/$Q37 -> 0.68043388 | AB37: =$AC$2*($AC$3+$AC$4*$F37/($N37*'Sem TS MC2020'!P29))*($AC$5*$G37+$AC$6*$B37/$N37)*'Sem TS MC2020'!R29*($J37-$M37)/($J37-$M37-$H37) -> 0.1339515 | AC37: =AB37/$Q37 -> 0.66975748 | AD37: =AB37-$Q37 -> -0.066048503 | AE37: =1/AC37 -> 1.4930778 | AF37: =AB37*(14.068*'Sem TS MC2020'!$P29^-0.457)/$Q37 -> 0.83367902 | AO37: =$AP$2*($AP$3+$AP$4*$F37/($N37*'Sem TS MC2020'!P29))*($AP$5*$G37+$AP$6*$B37/$N37)*('Sem TS MC2020'!P29^$AP$7/200000)*($J37-$M37)/($J37-$M37-$H37)+('Sem TS MC2020'!P29-$C37/$AP$8)*($AP$5*$G37+$AP$6*$B37/$N37)/200000 -> 0.13995609 | AP37: =AO37/$Q37 -> 0.69978044 | AQ37: =AO37-$Q37 -> -0.060043913
B38: 16 | C38: 571 | D38: 4 | E38: 37 | F38: 4.2588 | G38: 33 | H38: 59 | I38: 125 | J38: 250 | K38: 800 | L38: 19625 | M38: 87.082519 | N38: 0.0408 | O38: 31.7 | P38: 182.10678 | Q38: 0.26 | R38: =P38/200000 -> 0.00091053391 | V38: =$W$2*($W$3*$G38+$W$4*$B38^$W$5*$N38^$W$6)*$R38^$W$7 -> 0.16719569 | W38: =V38/$Q38 -> 0.64306036 | Y38: =$Z$2*$B38^$Z$3*$R38^$Z$4*($Z$5*$N38^$Z$6+$Z$7) -> 0.16610116 | Z38: =Y38/$Q38 -> 0.63885061 | AB38: =$AC$2*($AC$3+$AC$4*$F38/($N38*'Sem TS MC2020'!P30))*($AC$5*$G38+$AC$6*$B38/$N38)*'Sem TS MC2020'!R30*($J38-$M38)/($J38-$M38-$H38) -> 0.17309835 | AC38: =AB38/$Q38 -> 0.66576289 | AD38: =AB38-$Q38 -> -0.086901648 | AE38: =1/AC38 -> 1.5020363 | AF38: =AB38*(14.068*'Sem TS MC2020'!$P30^-0.457)/$Q38 -> 0.75959219 | AO38: =$AP$2*($AP$3+$AP$4*$F38/($N38*'Sem TS MC2020'!P30))*($AP$5*$G38+$AP$6*$B38/$N38)*('Sem TS MC2020'!P30^$AP$7/200000)*($J38-$M38)/($J38-$M38-$H38)+('Sem TS MC2020'!P30-$C38/$AP$8)*($AP$5*$G38+$AP$6*$B38/$N38)/200000 -> 0.17798601 | AP38: =AO38/$Q38 -> 0.68456158 | AQ38: =AO38-$Q38 -> -0.082013988
B39: 16 | C39: 571 | D39: 4 | E39: 37 | F39: 4.2588 | G39: 33 | H39: 59 | I39: 125 | J39: 250 | K39: 800 | L39: 19625 | M39: 87.082519 | N39: 0.0408 | O39: 40.8 | P39: 276.47022 | Q39: 0.44 | R39: =P39/200000 -> 0.0013823511 | V39: =$W$2*($W$3*$G39+$W$4*$B39^$W$5*$N39^$W$6)*$R39^$W$7 -> 0.21632211 | W39: =V39/$Q39 -> 0.49164115 | Y39: =$Z$2*$B39^$Z$3*$R39^$Z$4*($Z$5*$N39^$Z$6+$Z$7) -> 0.21589522 | Z39: =Y39/$Q39 -> 0.49067095 | AB39: =$AC$2*($AC$3+$AC$4*$F39/($N39*'Sem TS MC2020'!P31))*($AC$5*$G39+$AC$6*$B39/$N39)*'Sem TS MC2020'!R31*($J39-$M39)/($J39-$M39-$H39) -> 0.2378686 | AC39: =AB39/$Q39 -> 0.54061046 | AD39: =AB39-$Q39 -> -0.2021314 | AE39: =1/AC39 -> 1.8497607 | AF39: =AB39*(14.068*'Sem TS MC2020'!$P31^-0.457)/$Q39 -> 0.54961394 | AO39: =$AP$2*($AP$3+$AP$4*$F39/($N39*'Sem TS MC2020'!P31))*($AP$5*$G39+$AP$6*$B39/$N39)*('Sem TS MC2020'!P31^$AP$7/200000)*($J39-$M39)/($J39-$M39-$H39)+('Sem TS MC2020'!P31-$C39/$AP$8)*($AP$5*$G39+$AP$6*$B39/$N39)/200000 -> 0.23793605 | AP39: =AO39/$Q39 -> 0.54076376 | AQ39: =AO39-$Q39 -> -0.20206395
B40: 16 | C40: 571 | D40: 4 | E40: 37 | F40: 4.2588 | G40: 33 | H40: 59 | I40: 125 | J40: 250 | K40: 800 | L40: 19625 | M40: 87.082519 | N40: 0.0408 | O40: 54.1 | P40: 412.87726 | Q40: 0.6 | R40: =P40/200000 -> 0.0020643863 | V40: =$W$2*($W$3*$G40+$W$4*$B40^$W$5*$N40^$W$6)*$R40^$W$7 -> 0.27705463 | W40: =V40/$Q40 -> 0.46175771 | Y40: =$Z$2*$B40^$Z$3*$R40^$Z$4*($Z$5*$N40^$Z$6+$Z$7) -> 0.27773041 | Z40: =Y40/$Q40 -> 0.46288401 | AB40: =$AC$2*($AC$3+$AC$4*$F40/($N40*'Sem TS MC2020'!P32))*($AC$5*$G40+$AC$6*$B40/$N40)*'Sem TS MC2020'!R32*($J40-$M40)/($J40-$M40-$H40) -> 0.33253282 | AC40: =AB40/$Q40 -> 0.55422136 | AD40: =AB40-$Q40 -> -0.26746718 | AE40: =1/AC40 -> 1.8043332 | AF40: =AB40*(14.068*'Sem TS MC2020'!$P32^-0.457)/$Q40 -> 0.49528719 | AO40: =$AP$2*($AP$3+$AP$4*$F40/($N40*'Sem TS MC2020'!P32))*($AP$5*$G40+$AP$6*$B40/$N40)*('Sem TS MC2020'!P32^$AP$7/200000)*($J40-$M40)/($J40-$M40-$H40)+('Sem TS MC2020'!P32-$C40/$AP$8)*($AP$5*$G40+$AP$6*$B40/$N40)/200000 -> 0.32083232 | AP40: =AO40/$Q40 -> 0.53472053 | AQ40: =AO40-$Q40 -> -0.27916768
...

Sheet Sem TS MC2020
A1: Autor | B1: Inputs | Q1: Output
B2: Diâmetro da armadura f (mm) | C2: Resistência do aço - fy (MPa) | D2: Número de barras em uma camada | E2: Espaçamento entre as barras (mm) | F2: Resistência à tração do concreto fctm (MPa) | G2: Cobrimento c (mm) | H2: Distância ao centro de gravidade da armadura d' (mm) | I2: Largura da viga - b (mm) | J2: Altura da viga - h (mm) | K2: Área de aço tracionada - As (mm2) | L2: Área de concreto efetiva - Ace (mm2) | M2: Linha neutra no Estádio II - XII (mm) | N2: Taxa de armadura r | O2: Momento fletor - Ms (kNm) | P2: Tensão na armadura (MPa) | Q2: wexp (mm) | R2: Deformação na armadura
A3: Viga S200-1.76-20 - Sokolov et al (2021) | B3: 20 | C3: 500 | D3: 2 | E3: 126 | F3: 4.1203405 | G3: 25 | H3: 39 | I3: 216 | J3: 201 | K3: 628 | L3: 29484 | M3: 57.361777 | N3: 0.021299688 | O3: 20.8 | P3: 231.811 | Q3: 0.16 | R3: =P3/200000 -> 0.001159055
B4: 20 | C4: 500 | D4: 2 | E4: 126 | F4: 4.1203405 | G4: 25 | H4: 39 | I4: 216 | J4: 201 | K4: 628 | L4: 29484 | M4: 57.361777 | N4: 0.021299688 | O4: 27.3 | P4: 304.25194 | Q4: 0.23 | R4: =P4/200000 -> 0.0015212597
B5: 20 | C5: 500 | D5: 2 | E5: 126 | F5: 4.1203405 | G5: 25 | H5: 39 | I5: 216 | J5: 201 | K5: 628 | L5: 29484 | M5: 57.361777 | N5: 0.021299688 | O5: 28.2 | P5: 314.28223 | Q5: 0.24 | R5: =P5/200000 -> 0.0015714111
B6: 20 | C6: 500 | D6: 2 | E6: 126 | F6: 4.1203405 | G6: 25 | H6: 39 | I6: 216 | J6: 201 | K6: 628 | L6: 29484 | M6: 57.361777 | N6: 0.021299688 | O6: 32.6 | P6: 363.31917 | Q6: 0.27 | R6: =P6/200000 -> 0.0018165959
B7: 20 | C7: 500 | D7: 2 | E7: 126 | F7: 4.1203405 | G7: 25 | H7: 39 | I7: 216 | J7: 201 | K7: 628 | L7: 29484 | M7: 57.361777 | N7: 0.021299688 | O7: 41.2 | P7: 459.16411 | Q7: 0.35 | R7: =P7/200000 -> 0.0022958205
B8: 20 | C8: 500 | D8: 2 | E8: 126 | F8: 4.1203405 | G8: 25 | H8: 39 | I8: 216 | J8: 201 | K8: 628 | L8: 29484 | M8: 57.361777 | N8: 0.021299688 | O8: 44.9 | P8: 500 | Q8: 0.4 | R8: =P8/200000 -> 0.0025
A9: Viga S600-0.37-10 - Sokolov et al (2021) | B9: 10 | C9: 500 | D9: 8 | E9: 87.7 | F9: 4.1311268 | G9: 25 | H9: 53 | I9: 308 | J9: 604 | K9: 628 | L9: 43428 | M9: 99.6964 | N9: 0.014460717 | O9: 105 | P9: 322.91972 | Q9: 0.16 | R9: =P9/200000 -> 0.0016145986
B10: 10 | C10: 500 | D10: 8 | E10: 87.7 | F10: 4.1311268 | G10: 25 | H10: 53 | I10: 308 | J10: 604 | K10: 628 | L10: 43428 | M10: 99.6964 | N10: 0.014460717 | O10: 119.6 | P10: 367.82093 | Q10: 0.18 | R10: =P10/200000 -> 0.0018391047
B11: 10 | C11: 500 | D11: 8 | E11: 87.7 | F11: 4.1311268 | G11: 25 | H11: 53 | I11: 308 | J11: 604 | K11: 628 | L11: 43428 | M11: 99.6964 | N11: 0.014460717 | O11: 174.3 | P11: 500 | Q11: 0.26 | R11: =P11/200000 -> 0.0025
A12: Viga V1 - Oliveira (2007) | B12: 10 | C12: 628 | D12: 4 | E12: 32.466667 | F12: 3.262 | G12: 25 | H12: 36 | I12: 200 | J12: 600 | K12: 314 | L12: 17200 | M12: 95.721927 | N12: 0.018255814 | O12: 47.625 | P12: 285.04803 | Q12: 0.16 | R12: =P12/200000 -> 0.0014252402
B13: 10 | C13: 628 | D13: 4 | E13: 32.466667 | F13: 3.262 | G13: 25 | H13: 36 | I13: 200 | J13: 600 | K13: 314 | L13: 17200 | M13: 95.721927 | N13: 0.018255814 | O13: 54.3 | P13: 324.99965 | Q13: 0.2 | R13: =P13/200000 -> 0.0016249982
B14: 10 | C14: 628 | D14: 4 | E14: 32.466667 | F14: 3.262 | G14: 25 | H14: 36 | I14: 200 | J14: 600 | K14: 314 | L14: 17200 | M14: 95.721927 | N14: 0.018255814 | O14: 61.425 | P14: 367.64463 | Q14: 0.2 | R14: =P14/200000 -> 0.0018382231
B15: 10 | C15: 628 | D15: 4 | E15: 32.466667 | F15: 3.262 | G15: 25 | H15: 36 | I15: 200 | J15: 600 | K15: 314 | L15: 17200 | M15: 95.721927 | N15: 0.018255814 | O15: 68.625 | P15: 410.7385 | Q15: 0.24 | R15: =P15/200000 -> 0.0020536925
B16: 10 | C16: 628 | D16: 4 | E16: 32.466667 | F16: 3.262 | G16: 25 | H16: 36 | I16: 200 | J16: 600 | K16: 314 | L16: 17200 | M16: 95.721927 | N16: 0.018255814 | O16: 73.275 | P16: 438.56996 | Q16: 0.3 | R16: =P16/200000 -> 0.0021928498
B17: 10 | C17: 628 | D17: 4 | E17: 32.466667 | F17: 3.262 | G17: 25 | H17: 36 | I17: 200 | J17: 600 | K17: 314 | L17: 17200 | M17: 95.721927 | N17: 0.018255814 | O17: 83.25 | P17: 498.27294 | Q17: 0.32 | R17: =P17/200000 -> 0.0024913647
B18: 10 | C18: 628 | D18: 4 | E18: 32.466667 | F18: 3.262 | G18: 25 | H18: 36 | I18: 200 | J18: 600 | K18: 314 | L18: 17200 | M18: 95.721927 | N18: 0.018255814 | O18: 84 | P18: 502.76188 | Q18: 0.38 | R18: =P18/200000 -> 0.0025138094
B19: 10 | C19: 628 | D19: 4 | E19: 32.466667 | F19: 3.262 | G19: 25 | H19: 36 | I19: 200 | J19: 600 | K19: 314 | L19: 17200 | M19: 95.721927 | N19: 0.018255814 | O19: 90 | P19: 538.67345 | Q19: 0.42 | R19: =P19/200000 -> 0.0026933672
B20: 10 | C20: 628 | D20: 4 | E20: 32.466667 | F20: 3.262 | G20: 25 | H20: 36 | I20: 200 | J20: 600 | K20: 314 | L20: 17200 | M20: 95.721927 | N20: 0.018255814 | O20: 108 | P20: 628 | Q20: 0.44 | R20: =P20/200000 -> 0.00314
B21: 10 | C21: 628 | D21: 4 | E21: 32.466667 | F21: 3.262 | G21: 25 | H21: 36 | I21: 200 | J21: 600 | K21: 314 | L21: 17200 | M21: 95.721927 | N21: 0.018255814 | O21: 120 | P21: 628 | Q21: 0.5 | R21: =P21/200000 -> 0.00314
A22: Viga V2 - Oliveira (2007) | B22: 10 | C22: 628 | D22: 4 | E22: 32.466667 | F22: 3.514 | G22: 25 | H22: 36 | I22: 200 | J22: 600 | K22: 314 | L22: 17200 | M22: 87.120679 | N22: 0.018255814 | O22: 54 | P22: 321.47188 | Q22: 0.24 | R22: =P22/200000 -> 0.0016073594
B23: 10 | C23: 628 | D23: 4 | E23: 32.466667 | F23: 3.514 | G23: 25 | H23: 36 | I23: 200 | J23: 600 | K23: 314 | L23: 17200 | M23: 87.120679 | N23: 0.018255814 | O23: 60 | P23: 357.19097 | Q23: 0.3 | R23: =P23/200000 -> 0.0017859549
B24: 10 | C24: 628 | D24: 4 | E24: 32.466667 | F24: 3.514 | G24: 25 | H24: 36 | I24: 200 | J24: 600 | K24: 314 | L24: 17200 | M24: 87.120679 | N24: 0.018255814 | O24: 62.25 | P24: 370.58564 | Q24: 0.3 | R24: =P24/200000 -> 0.0018529282
B25: 10 | C25: 628 | D25: 4 | E25: 32.466667 | F25: 3.514 | G25: 25 | H25: 36 | I25: 200 | J25: 600 | K25: 314 | L25: 17200 | M25: 87.120679 | N25: 0.018255814 | O25: 66 | P25: 392.91007 | Q25: 0.3 | R25: =P25/200000 -> 0.0019645504
B26: 10 | C26: 628 | D26: 4 | E26: 32.466667 | F26: 3.514 | G26: 25 | H26: 36 | I26: 200 | J26: 600 | K26: 314 | L26: 17200 | M26: 87.120679 | N26: 0.018255814 | O26: 71.25 | P26: 424.16428 | Q26: 0.38 | R26: =P26/200000 -> 0.0021208214
B27: 10 | C27: 628 | D27: 4 | E27: 32.466667 | F27: 3.514 | G27: 25 | H27: 36 | I27: 200 | J27: 600 | K27: 314 | L27: 17200 | M27: 87.120679 | N27: 0.018255814 | O27: 82.5 | P27: 491.13759 | Q27: 0.44 | R27: =P27/200000 -> 0.0024556879
A28: Viga T1F000 - Silva Neto (2017) | B28: 16 | C28: 571 | D28: 4 | E28: 37 | F28: 4.2588 | G28: 33 | H28: 59 | I28: 125 | J28: 250 | K28: 800 | L28: 19625 | M28: 86 | N28: 0.0408 | O28: 18.2 | P28: 140.04197 | Q28: 0.18 | R28: =P28/200000 -> 0.00070020983
B29: 16 | C29: 571 | D29: 4 | E29: 37 | F29: 4.2588 | G29: 33 | H29: 59 | I29: 125 | J29: 250 | K29: 800 | L29: 19625 | M29: 86 | N29: 0.0408 | O29: 26.2 | P29: 201.59887 | Q29: 0.2 | R29: =P29/200000 -> 0.0010079944
B30: 16 | C30: 571 | D30: 4 | E30: 37 | F30: 4.2588 | G30: 33 | H30: 59 | I30: 125 | J30: 250 | K30: 800 | L30: 19625 | M30: 86 | N30: 0.0408 | O30: 31.7 | P30: 243.91925 | Q30: 0.26 | R30: =P30/200000 -> 0.0012195962
B31: 16 | C31: 571 | D31: 4 | E31: 37 | F31: 4.2588 | G31: 33 | H31: 59 | I31: 125 | J31: 250 | K31: 800 | L31: 19625 | M31: 86 | N31: 0.0408 | O31: 40.8 | P31: 313.94023 | Q31: 0.44 | R31: =P31/200000 -> 0.0015697012
B32: 16 | C32: 571 | D32: 4 | E32: 37 | F32: 4.2588 | G32: 33 | H32: 59 | I32: 125 | J32: 250 | K32: 800 | L32: 19625 | M32: 86 | N32: 0.0408 | O32: 54.1 | P32: 416.27859 | Q32: 0.6 | R32: =P32/200000 -> 0.002081393
A33: Viga 12-20-00 - Caldentey et al (2013) | B33: 12 | C33: 500 | D33: 4 | E33: 79.3 | F33: 2.6933292 | G33: 20 | H33: 38 | I33: 350 | J33: 450 | K33: 452 | L33: 34300 | M33: 76.169428 | N33: 0.013177843 | O33: 52.5 | P33: 300.43296 | Q33: 0.36 | R33: =P33/200000 -> 0.0015021648
B34: 12 | C34: 500 | D34: 4 | E34: 79.3 | F34: 2.6933292 | G34: 20 | H34: 38 | I34: 350 | J34: 450 | K34: 452 | L34: 34300 | M34: 76.169428 | N34: 0.013177843 | O34: 67.5 | P34: 386.27094 | Q34: 0.43 | R34: =P34/200000 -> 0.0019313547
B35: 12 | C35: 500 | D35: 4 | E35: 79.3 | F35: 2.6933292 | G35: 20 | H35: 38 | I35: 350 | J35: 450 | K35: 452 | L35: 34300 | M35: 76.169428 | N35: 0.013177843 | O35: 90 | P35: 500 | Q35: 0.56 | R35: =P35/200000 -> 0.0025
B36: 12 | C36: 500 | D36: 4 | E36: 79.3 | F36: 2.6933292 | G36: 20 | H36: 38 | I36: 350 | J36: 450 | K36: 452 | L36: 34300 | M36: 76.169428 | N36: 0.013177843 | O36: 112.5 | P36: 500 | Q36: 0.71 | R36: =P36/200000 -> 0.0025
